Workbook

Sheet 渠道充值成功率-统整
B1: Date | C1: jiliarena | D1: GCash | E1: QRPH | F1: GCashQR | G1: Maya | H1: GRABPAY | I1: Online Banking | J1: USDT | K1: GOTYME | L1: GCASHPAY
A2: =B2 -> 46082 | B2: 46082 | C2: 申请笔数 | D2: =SUMIFS('渠道充值成功率_底稿'!$C:$C,'渠道充值成功率_底稿'!$A:$A,$A2,'渠道充值成功率_底稿'!$B:$B,D$1) -> 1458 | E2: =SUMIFS('渠道充值成功率_底稿'!$C:$C,'渠道充值成功率_底稿'!$A:$A,$A2,'渠道充值成功率_底稿'!$B:$B,E$1) -> 32 | F2: =SUMIFS('渠道充值成功率_底稿'!$C:$C,'渠道充值成功率_底稿'!$A:$A,$A2,'渠道充值成功率_底稿'!$B:$B,F$1) -> 61 | G2: =SUMIFS('渠道充值成功率_底稿'!$C:$C,'渠道充值成功率_底稿'!$A:$A,$A2,'渠道充值成功率_底稿'!$B:$B,G$1) -> 146 | H2: =SUMIFS('渠道充值成功率_底稿'!$C:$C,'渠道充值成功率_底稿'!$A:$A,$A2,'渠道充值成功率_底稿'!$B:$B,H$1) -> 0 | I2: =SUMIFS('渠道充值成功率_底稿'!$C:$C,'渠道充值成功率_底稿'!$A:$A,$A2,'渠道充值成功率_底稿'!$B:$B,I$1) -> 0 | J2: =SUMIFS('渠道充值成功率_底稿'!$C:$C,'渠道充值成功率_底稿'!$A:$A,$A2,'渠道充值成功率_底稿'!$B:$B,J$1) -> 0 | K2: =SUMIFS('渠道充值成功率_底稿'!$C:$C,'渠道充值成功率_底稿'!$A:$A,$A2,'渠道充值成功率_底稿'!$B:$B,K$1) -> 6 | L2: =SUMIFS('渠道充值成功率_底稿'!$C:$C,'渠道充值成功率_底稿'!$A:$A,$A2,'渠道充值成功率_底稿'!$B:$B,L$1) -> 0
A3: =B2 -> 46082 | C3: 到账笔数 | D3: =SUMIFS('渠道充值成功率_底稿'!$F:$F,'渠道充值成功率_底稿'!$A:$A,$A3,'渠道充值成功率_底稿'!$B:$B,D$1) -> 1065 | E3: =SUMIFS('渠道充值成功率_底稿'!$F:$F,'渠道充值成功率_底稿'!$A:$A,$A3,'渠道充值成功率_底稿'!$B:$B,E$1) -> 24 | F3: =SUMIFS('渠道充值成功率_底稿'!$F:$F,'渠道充值成功率_底稿'!$A:$A,$A3,'渠道充值成功率_底稿'!$B:$B,F$1) -> 41 | G3: =SUMIFS('渠道充值成功率_底稿'!$F:$F,'渠道充值成功率_底稿'!$A:$A,$A3,'渠道充值成功率_底稿'!$B:$B,G$1) -> 117 | H3: =SUMIFS('渠道充值成功率_底稿'!$F:$F,'渠道充值成功率_底稿'!$A:$A,$A3,'渠道充值成功率_底稿'!$B:$B,H$1) -> 0 | I3: =SUMIFS('渠道充值成功率_底稿'!$F:$F,'渠道充值成功率_底稿'!$A:$A,$A3,'渠道充值成功率_底稿'!$B:$B,I$1) -> 0 | J3: =SUMIFS('渠道充值成功率_底稿'!$F:$F,'渠道充值成功率_底稿'!$A:$A,$A3,'渠道充值成功率_底稿'!$B:$B,J$1) -> 0 | K3: =SUMIFS('渠道充值成功率_底稿'!$F:$F,'渠道充值成功率_底稿'!$A:$A,$A3,'渠道充值成功率_底稿'!$B:$B,K$1) -> 4 | L3: =SUMIFS('渠道充值成功率_底稿'!$F:$F,'渠道充值成功率_底稿'!$A:$A,$A3,'渠道充值成功率_底稿'!$B:$B,L$1) -> 0
A4: =B2 -> 46082 | C4: 笔数成功率 | D4: =IFERROR(ROUND(D3/D2,6),"0") -> 0.730453 | E4: =IFERROR(ROUND(E3/E2,6),"0") -> 0.75 | F4: =IFERROR(ROUND(F3/F2,6),"0") -> 0.672131 | G4: =IFERROR(ROUND(G3/G2,6),"0") -> 0.80137 | H4: =IFERROR(ROUND(H3/H2,6),"0") -> 0 | I4: =IFERROR(ROUND(I3/I2,6),"0") -> 0 | J4: =IFERROR(ROUND(J3/J2,6),"0") -> 0 | K4: =IFERROR(ROUND(K3/K2,6),"0") -> 0.666667 | L4: =IFERROR(ROUND(L3/L2,6),"0") -> 0
A5: =B2 -> 46082 | C5: 申请金额 | D5: =SUMIFS('渠道充值成功率_底稿'!$D:$D,'渠道充值成功率_底稿'!$A:$A,$A6,'渠道充值成功率_底稿'!$B:$B,D$1) -> 201674 | E5: =SUMIFS('渠道充值成功率_底稿'!$D:$D,'渠道充值成功率_底稿'!$A:$A,$A5,'渠道充值成功率_底稿'!$B:$B,E$1) -> 5860 | F5: =SUMIFS('渠道充值成功率_底稿'!$D:$D,'渠道充值成功率_底稿'!$A:$A,$A5,'渠道充值成功率_底稿'!$B:$B,F$1) -> 8630 | G5: =SUMIFS('渠道充值成功率_底稿'!$D:$D,'渠道充值成功率_底稿'!$A:$A,$A5,'渠道充值成功率_底稿'!$B:$B,G$1) -> 18592 | H5: =SUMIFS('渠道充值成功率_底稿'!$D:$D,'渠道充值成功率_底稿'!$A:$A,$A5,'渠道充值成功率_底稿'!$B:$B,H$1) -> 0 | I5: =SUMIFS('渠道充值成功率_底稿'!$D:$D,'渠道充值成功率_底稿'!$A:$A,$A5,'渠道充值成功率_底稿'!$B:$B,I$1) -> 0 | J5: =SUMIFS('渠道充值成功率_底稿'!$D:$D,'渠道充值成功率_底稿'!$A:$A,$A5,'渠道充值成功率_底稿'!$B:$B,J$1) -> 0 | K5: =SUMIFS('渠道充值成功率_底稿'!$D:$D,'渠道充值成功率_底稿'!$A:$A,$A5,'渠道充值成功率_底稿'!$B:$B,K$1) -> 900 | L5: =SUMIFS('渠道充值成功率_底稿'!$D:$D,'渠道充值成功率_底稿'!$A:$A,$A5,'渠道充值成功率_底稿'!$B:$B,L$1) -> 0
A6: =B2 -> 46082 | C6: 到账金额 | D6: =SUMIFS('渠道充值成功率_底稿'!$G:$G,'渠道充值成功率_底稿'!$A:$A,$A7,'渠道充值成功率_底稿'!$B:$B,D$1) -> 162179 | E6: =SUMIFS('渠道充值成功率_底稿'!$G:$G,'渠道充值成功率_底稿'!$A:$A,$A6,'渠道充值成功率_底稿'!$B:$B,E$1) -> 4610 | F6: =SUMIFS('渠道充值成功率_底稿'!$G:$G,'渠道充值成功率_底稿'!$A:$A,$A6,'渠道充值成功率_底稿'!$B:$B,F$1) -> 5980 | G6: =SUMIFS('渠道充值成功率_底稿'!$G:$G,'渠道充值成功率_底稿'!$A:$A,$A6,'渠道充值成功率_底稿'!$B:$B,G$1) -> 13472 | H6: =SUMIFS('渠道充值成功率_底稿'!$G:$G,'渠道充值成功率_底稿'!$A:$A,$A6,'渠道充值成功率_底稿'!$B:$B,H$1) -> 0 | I6: =SUMIFS('渠道充值成功率_底稿'!$G:$G,'渠道充值成功率_底稿'!$A:$A,$A6,'渠道充值成功率_底稿'!$B:$B,I$1) -> 0 | J6: =SUMIFS('渠道充值成功率_底稿'!$G:$G,'渠道充值成功率_底稿'!$A:$A,$A6,'渠道充值成功率_底稿'!$B:$B,J$1) -> 0 | K6: =SUMIFS('渠道充值成功率_底稿'!$G:$G,'渠道充值成功率_底稿'!$A:$A,$A6,'渠道充值成功率_底稿'!$B:$B,K$1) -> 700 | L6: =SUMIFS('渠道充值成功率_底稿'!$G:$G,'渠道充值成功率_底稿'!$A:$A,$A6,'渠道充值成功率_底稿'!$B:$B,L$1) -> 0
A7: =B2 -> 46082 | C7: 金额成功率 | D7: =IFERROR(ROUND(D6/D5,6),"0") -> 0.804164 | E7: =IFERROR(ROUND(E6/E5,6),"0") -> 0.786689 | F7: =IFERROR(ROUND(F6/F5,6),"0") -> 0.692932 | G7: =IFERROR(ROUND(G6/G5,6),"0") -> 0.724613 | H7: =IFERROR(ROUND(H6/H5,6),"0") -> 0 | I7: =IFERROR(ROUND(I6/I5,6),"0") -> 0 | J7: =IFERROR(ROUND(J6/J5,6),"0") -> 0 | K7: =IFERROR(ROUND(K6/K5,6),"0") -> 0.777778 | L7: =IFERROR(ROUND(L6/L5,6),"0") -> 0
A8: =B8 -> 46083 | B8: =B2+1 -> 46083 | C8: 申请笔数 | D8: =SUMIFS('渠道充值成功率_底稿'!$C:$C,'渠道充值成功率_底稿'!$A:$A,$A8,'渠道充值成功率_底稿'!$B:$B,D$1) -> 611 | E8: =SUMIFS('渠道充值成功率_底稿'!$C:$C,'渠道充值成功率_底稿'!$A:$A,$A8,'渠道充值成功率_底稿'!$B:$B,E$1) -> 14 | F8: =SUMIFS('渠道充值成功率_底稿'!$C:$C,'渠道充值成功率_底稿'!$A:$A,$A8,'渠道充值成功率_底稿'!$B:$B,F$1) -> 30 | G8: =SUMIFS('渠道充值成功率_底稿'!$C:$C,'渠道充值成功率_底稿'!$A:$A,$A8,'渠道充值成功率_底稿'!$B:$B,G$1) -> 81 | H8: =SUMIFS('渠道充值成功率_底稿'!$C:$C,'渠道充值成功率_底稿'!$A:$A,$A8,'渠道充值成功率_底稿'!$B:$B,H$1) -> 0 | I8: =SUMIFS('渠道充值成功率_底稿'!$C:$C,'渠道充值成功率_底稿'!$A:$A,$A8,'渠道充值成功率_底稿'!$B:$B,I$1) -> 0 | J8: =SUMIFS('渠道充值成功率_底稿'!$C:$C,'渠道充值成功率_底稿'!$A:$A,$A8,'渠道充值成功率_底稿'!$B:$B,J$1) -> 0 | K8: =SUMIFS('渠道充值成功率_底稿'!$C:$C,'渠道充值成功率_底稿'!$A:$A,$A8,'渠道充值成功率_底稿'!$B:$B,K$1) -> 14 | L8: =SUMIFS('渠道充值成功率_底稿'!$C:$C,'渠道充值成功率_底稿'!$A:$A,$A8,'渠道充值成功率_底稿'!$B:$B,L$1) -> 0
A9: =B8 -> 46083 | C9: 到账笔数 | D9: =SUMIFS('渠道充值成功率_底稿'!$F:$F,'渠道充值成功率_底稿'!$A:$A,$A9,'渠道充值成功率_底稿'!$B:$B,D$1) -> 492 | E9: =SUMIFS('渠道充值成功率_底稿'!$F:$F,'渠道充值成功率_底稿'!$A:$A,$A9,'渠道充值成功率_底稿'!$B:$B,E$1) -> 13 | F9: =SUMIFS('渠道充值成功率_底稿'!$F:$F,'渠道充值成功率_底稿'!$A:$A,$A9,'渠道充值成功率_底稿'!$B:$B,F$1) -> 24 | G9: =SUMIFS('渠道充值成功率_底稿'!$F:$F,'渠道充值成功率_底稿'!$A:$A,$A9,'渠道充值成功率_底稿'!$B:$B,G$1) -> 57 | H9: =SUMIFS('渠道充值成功率_底稿'!$F:$F,'渠道充值成功率_底稿'!$A:$A,$A9,'渠道充值成功率_底稿'!$B:$B,H$1) -> 0 | I9: =SUMIFS('渠道充值成功率_底稿'!$F:$F,'渠道充值成功率_底稿'!$A:$A,$A9,'渠道充值成功率_底稿'!$B:$B,I$1) -> 0 | J9: =SUMIFS('渠道充值成功率_底稿'!$F:$F,'渠道充值成功率_底稿'!$A:$A,$A9,'渠道充值成功率_底稿'!$B:$B,J$1) -> 0 | K9: =SUMIFS('渠道充值成功率_底稿'!$F:$F,'渠道充值成功率_底稿'!$A:$A,$A9,'渠道充值成功率_底稿'!$B:$B,K$1) -> 13 | L9: =SUMIFS('渠道充值成功率_底稿'!$F:$F,'渠道充值成功率_底稿'!$A:$A,$A9,'渠道充值成功率_底稿'!$B:$B,L$1) -> 0
A10: =B8 -> 46083 | C10: 笔数成功率 | D10: =IFERROR(ROUND(D9/D8,6),"0") -> 0.805237 | E10: =IFERROR(ROUND(E9/E8,6),"0") -> 0.928571 | F10: =IFERROR(ROUND(F9/F8,6),"0") -> 0.8 | G10: =IFERROR(ROUND(G9/G8,6),"0") -> 0.703704 | H10: =IFERROR(ROUND(H9/H8,6),"0") -> 0 | I10: =IFERROR(ROUND(I9/I8,6),"0") -> 0 | J10: =IFERROR(ROUND(J9/J8,6),"0") -> 0 | K10: =IFERROR(ROUND(K9/K8,6),"0") -> 0.928571 | L10: =IFERROR(ROUND(L9/L8,6),"0") -> 0
A11: =B8 -> 46083 | C11: 申请金额 | D11: =SUMIFS('渠道充值成功率_底稿'!$D:$D,'渠道充值成功率_底稿'!$A:$A,$A12,'渠道充值成功率_底稿'!$B:$B,D$1) -> 97556 | E11: =SUMIFS('渠道充值成功率_底稿'!$D:$D,'渠道充值成功率_底稿'!$A:$A,$A11,'渠道充值成功率_底稿'!$B:$B,E$1) -> 2325 | F11: =SUMIFS('渠道充值成功率_底稿'!$D:$D,'渠道充值成功率_底稿'!$A:$A,$A11,'渠道充值成功率_底稿'!$B:$B,F$1) -> 4167 | G11: =SUMIFS('渠道充值成功率_底稿'!$D:$D,'渠道充值成功率_底稿'!$A:$A,$A11,'渠道充值成功率_底稿'!$B:$B,G$1) -> 9777 | H11: =SUMIFS('渠道充值成功率_底稿'!$D:$D,'渠道充值成功率_底稿'!$A:$A,$A11,'渠道充值成功率_底稿'!$B:$B,H$1) -> 0 | I11: =SUMIFS('渠道充值成功率_底稿'!$D:$D,'渠道充值成功率_底稿'!$A:$A,$A11,'渠道充值成功率_底稿'!$B:$B,I$1) -> 0 | J11: =SUMIFS('渠道充值成功率_底稿'!$D:$D,'渠道充值成功率_底稿'!$A:$A,$A11,'渠道充值成功率_底稿'!$B:$B,J$1) -> 0 | K11: =SUMIFS('渠道充值成功率_底稿'!$D:$D,'渠道充值成功率_底稿'!$A:$A,$A11,'渠道充值成功率_底稿'!$B:$B,K$1) -> 3110 | L11: =SUMIFS('渠道充值成功率_底稿'!$D:$D,'渠道充值成功率_底稿'!$A:$A,$A11,'渠道充值成功率_底稿'!$B:$B,L$1) -> 0
A12: =B8 -> 46083 | C12: 到账金额 | D12: =SUMIFS('渠道充值成功率_底稿'!$G:$G,'渠道充值成功率_底稿'!$A:$A,$A13,'渠道充值成功率_底稿'!$B:$B,D$1) -> 76391 | E12: =SUMIFS('渠道充值成功率_底稿'!$G:$G,'渠道充值成功率_底稿'!$A:$A,$A12,'渠道充值成功率_底稿'!$B:$B,E$1) -> 2225 | F12: =SUMIFS('渠道充值成功率_底稿'!$G:$G,'渠道充值成功率_底稿'!$A:$A,$A12,'渠道充值成功率_底稿'!$B:$B,F$1) -> 3467 | G12: =SUMIFS('渠道充值成功率_底稿'!$G:$G,'渠道充值成功率_底稿'!$A:$A,$A12,'渠道充值成功率_底稿'!$B:$B,G$1) -> 5458 | H12: =SUMIFS('渠道充值成功率_底稿'!$G:$G,'渠道充值成功率_底稿'!$A:$A,$A12,'渠道充值成功率_底稿'!$B:$B,H$1) -> 0 | I12: =SUMIFS('渠道充值成功率_底稿'!$G:$G,'渠道充值成功率_底稿'!$A:$A,$A12,'渠道充值成功率_底稿'!$B:$B,I$1) -> 0 | J12: =SUMIFS('渠道充值成功率_底稿'!$G:$G,'渠道充值成功率_底稿'!$A:$A,$A12,'渠道充值成功率_底稿'!$B:$B,J$1) -> 0 | K12: =SUMIFS('渠道充值成功率_底稿'!$G:$G,'渠道充值成功率_底稿'!$A:$A,$A12,'渠道充值成功率_底稿'!$B:$B,K$1) -> 2910 | L12: =SUMIFS('渠道充值成功率_底稿'!$G:$G,'渠道充值成功率_底稿'!$A:$A,$A12,'渠道充值成功率_底稿'!$B:$B,L$1) -> 0
A13: =B8 -> 46083 | C13: 金额成功率 | D13: =IFERROR(ROUND(D12/D11,6),"0") -> 0.783048 | E13: =IFERROR(ROUND(E12/E11,6),"0") -> 0.956989 | F13: =IFERROR(ROUND(F12/F11,6),"0") -> 0.832013 | G13: =IFERROR(ROUND(G12/G11,6),"0") -> 0.558249 | H13: =IFERROR(ROUND(H12/H11,6),"0") -> 0 | I13: =IFERROR(ROUND(I12/I11,6),"0") -> 0 | J13: =IFERROR(ROUND(J12/J11,6),"0") -> 0 | K13: =IFERROR(ROUND(K12/K11,6),"0") -> 0.935691 | L13: =IFERROR(ROUND(L12/L11,6),"0") -> 0
A14: =B14 -> 46084 | B14: =B8+1 -> 46084 | C14: 申请笔数 | D14: =SUMIFS('渠道充值成功率_底稿'!$C:$C,'渠道充值成功率_底稿'!$A:$A,$A14,'渠道充值成功率_底稿'!$B:$B,D$1) -> 563 | E14: =SUMIFS('渠道充值成功率_底稿'!$C:$C,'渠道充值成功率_底稿'!$A:$A,$A14,'渠道充值成功率_底稿'!$B:$B,E$1) -> 22 | F14: =SUMIFS('渠道充值成功率_底稿'!$C:$C,'渠道充值成功率_底稿'!$A:$A,$A14,'渠道充值成功率_底稿'!$B:$B,F$1) -> 26 | G14: =SUMIFS('渠道充值成功率_底稿'!$C:$C,'渠道充值成功率_底稿'!$A:$A,$A14,'渠道充值成功率_底稿'!$B:$B,G$1) -> 59 | H14: =SUMIFS('渠道充值成功率_底稿'!$C:$C,'渠道充值成功率_底稿'!$A:$A,$A14,'渠道充值成功率_底稿'!$B:$B,H$1) -> 0 | I14: =SUMIFS('渠道充值成功率_底稿'!$C:$C,'渠道充值成功率_底稿'!$A:$A,$A14,'渠道充值成功率_底稿'!$B:$B,I$1) -> 0 | J14: =SUMIFS('渠道充值成功率_底稿'!$C:$C,'渠道充值成功率_底稿'!$A:$A,$A14,'渠道充值成功率_底稿'!$B:$B,J$1) -> 0 | K14: =SUMIFS('渠道充值成功率_底稿'!$C:$C,'渠道充值成功率_底稿'!$A:$A,$A14,'渠道充值成功率_底稿'!$B:$B,K$1) -> 11 | L14: =SUMIFS('渠道充值成功率_底稿'!$C:$C,'渠道充值成功率_底稿'!$A:$A,$A14,'渠道充值成功率_底稿'!$B:$B,L$1) -> 0
A15: =B14 -> 46084 | C15: 到账笔数 | D15: =SUMIFS('渠道充值成功率_底稿'!$F:$F,'渠道充值成功率_底稿'!$A:$A,$A15,'渠道充值成功率_底稿'!$B:$B,D$1) -> 435 | E15: =SUMIFS('渠道充值成功率_底稿'!$F:$F,'渠道充值成功率_底稿'!$A:$A,$A15,'渠道充值成功率_底稿'!$B:$B,E$1) -> 21 | F15: =SUMIFS('渠道充值成功率_底稿'!$F:$F,'渠道充值成功率_底稿'!$A:$A,$A15,'渠道充值成功率_底稿'!$B:$B,F$1) -> 18 | G15: =SUMIFS('渠道充值成功率_底稿'!$F:$F,'渠道充值成功率_底稿'!$A:$A,$A15,'渠道充值成功率_底稿'!$B:$B,G$1) -> 48 | H15: =SUMIFS('渠道充值成功率_底稿'!$F:$F,'渠道充值成功率_底稿'!$A:$A,$A15,'渠道充值成功率_底稿'!$B:$B,H$1) -> 0 | I15: =SUMIFS('渠道充值成功率_底稿'!$F:$F,'渠道充值成功率_底稿'!$A:$A,$A15,'渠道充值成功率_底稿'!$B:$B,I$1) -> 0 | J15: =SUMIFS('渠道充值成功率_底稿'!$F:$F,'渠道充值成功率_底稿'!$A:$A,$A15,'渠道充值成功率_底稿'!$B:$B,J$1) -> 0 | K15: =SUMIFS('渠道充值成功率_底稿'!$F:$F,'渠道充值成功率_底稿'!$A:$A,$A15,'渠道充值成功率_底稿'!$B:$B,K$1) -> 6 | L15: =SUMIFS('渠道充值成功率_底稿'!$F:$F,'渠道充值成功率_底稿'!$A:$A,$A15,'渠道充值成功率_底稿'!$B:$B,L$1) -> 0
A16: =B14 -> 46084 | C16: 笔数成功率 | D16: =IFERROR(ROUND(D15/D14,6),"0") -> 0.772647 | E16: =IFERROR(ROUND(E15/E14,6),"0") -> 0.954545 | F16: =IFERROR(ROUND(F15/F14,6),"0") -> 0.692308 | G16: =IFERROR(ROUND(G15/G14,6),"0") -> 0.813559 | H16: =IFERROR(ROUND(H15/H14,6),"0") -> 0 | I16: =IFERROR(ROUND(I15/I14,6),"0") -> 0 | J16: =IFERROR(ROUND(J15/J14,6),"0") -> 0 | K16: =IFERROR(ROUND(K15/K14,6),"0") -> 0.545455 | L16: =IFERROR(ROUND(L15/L14,6),"0") -> 0
A17: =B14 -> 46084 | C17: 申请金额 | D17: =SUMIFS('渠道充值成功率_底稿'!$D:$D,'渠道充值成功率_底稿'!$A:$A,$A18,'渠道充值成功率_底稿'!$B:$B,D$1) -> 89488 | E17: =SUMIFS('渠道充值成功率_底稿'!$D:$D,'渠道充值成功率_底稿'!$A:$A,$A17,'渠道充值成功率_底稿'!$B:$B,E$1) -> 3250 | F17: =SUMIFS('渠道充值成功率_底稿'!$D:$D,'渠道充值成功率_底稿'!$A:$A,$A17,'渠道充值成功率_底稿'!$B:$B,F$1) -> 3975 | G17: =SUMIFS('渠道充值成功率_底稿'!$D:$D,'渠道充值成功率_底稿'!$A:$A,$A17,'渠道充值成功率_底稿'!$B:$B,G$1) -> 10480 | H17: =SUMIFS('渠道充值成功率_底稿'!$D:$D,'渠道充值成功率_底稿'!$A:$A,$A17,'渠道充值成功率_底稿'!$B:$B,H$1) -> 0 | I17: =SUMIFS('渠道充值成功率_底稿'!$D:$D,'渠道充值成功率_底稿'!$A:$A,$A17,'渠道充值成功率_底稿'!$B:$B,I$1) -> 0 | J17: =SUMIFS('渠道充值成功率_底稿'!$D:$D,'渠道充值成功率_底稿'!$A:$A,$A17,'渠道充值成功率_底稿'!$B:$B,J$1) -> 0 | K17: =SUMIFS('渠道充值成功率_底稿'!$D:$D,'渠道充值成功率_底稿'!$A:$A,$A17,'渠道充值成功率_底稿'!$B:$B,K$1) -> 2100 | L17: =SUMIFS('渠道充值成功率_底稿'!$D:$D,'渠道充值成功率_底稿'!$A:$A,$A17,'渠道充值成功率_底稿'!$B:$B,L$1) -> 0
A18: =B14 -> 46084 | C18: 到账金额 | D18: =SUMIFS('渠道充值成功率_底稿'!$G:$G,'渠道充值成功率_底稿'!$A:$A,$A19,'渠道充值成功率_底稿'!$B:$B,D$1) -> 71452 | E18: =SUMIFS('渠道充值成功率_底稿'!$G:$G,'渠道充值成功率_底稿'!$A:$A,$A18,'渠道充值成功率_底稿'!$B:$B,E$1) -> 3050 | F18: =SUMIFS('渠道充值成功率_底稿'!$G:$G,'渠道充值成功率_底稿'!$A:$A,$A18,'渠道充值成功率_底稿'!$B:$B,F$1) -> 2925 | G18: =SUMIFS('渠道充值成功率_底稿'!$G:$G,'渠道充值成功率_底稿'!$A:$A,$A18,'渠道充值成功率_底稿'!$B:$B,G$1) -> 8681 | H18: =SUMIFS('渠道充值成功率_底稿'!$G:$G,'渠道充值成功率_底稿'!$A:$A,$A18,'渠道充值成功率_底稿'!$B:$B,H$1) -> 0 | I18: =SUMIFS('渠道充值成功率_底稿'!$G:$G,'渠道充值成功率_底稿'!$A:$A,$A18,'渠道充值成功率_底稿'!$B:$B,I$1) -> 0 | J18: =SUMIFS('渠道充值成功率_底稿'!$G:$G,'渠道充值成功率_底稿'!$A:$A,$A18,'渠道充值成功率_底稿'!$B:$B,J$1) -> 0 | K18: =SUMIFS('渠道充值成功率_底稿'!$G:$G,'渠道充值成功率_底稿'!$A:$A,$A18,'渠道充值成功率_底稿'!$B:$B,K$1) -> 1200 | L18: =SUMIFS('渠道充值成功率_底稿'!$G:$G,'渠道充值成功率_底稿'!$A:$A,$A18,'渠道充值成功率_底稿'!$B:$B,L$1) -> 0
A19: =B14 -> 46084 | C19: 金额成功率 | D19: =IFERROR(ROUND(D18/D17,6),"0") -> 0.798453 | E19: =IFERROR(ROUND(E18/E17,6),"0") -> 0.938462 | F19: =IFERROR(ROUND(F18/F17,6),"0") -> 0.735849 | G19: =IFERROR(ROUND(G18/G17,6),"0") -> 0.82834 | H19: =IFERROR(ROUND(H18/H17,6),"0") -> 0 | I19: =IFERROR(ROUND(I18/I17,6),"0") -> 0 | J19: =IFERROR(ROUND(J18/J17,6),"0") -> 0 | K19: =IFERROR(ROUND(K18/K17,6),"0") -> 0.571429 | L19: =IFERROR(ROUND(L18/L17,6),"0") -> 0
A20: =B20 -> 46085 | B20: =B14+1 -> 46085 | C20: 申请笔数 | D20: =SUMIFS('渠道充值成功率_底稿'!$C:$C,'渠道充值成功率_底稿'!$A:$A,$A20,'渠道充值成功率_底稿'!$B:$B,D$1) -> 495 | E20: =SUMIFS('渠道充值成功率_底稿'!$C:$C,'渠道充值成功率_底稿'!$A:$A,$A20,'渠道充值成功率_底稿'!$B:$B,E$1) -> 15 | F20: =SUMIFS('渠道充值成功率_底稿'!$C:$C,'渠道充值成功率_底稿'!$A:$A,$A20,'渠道充值成功率_底稿'!$B:$B,F$1) -> 28 | G20: =SUMIFS('渠道充值成功率_底稿'!$C:$C,'渠道充值成功率_底稿'!$A:$A,$A20,'渠道充值成功率_底稿'!$B:$B,G$1) -> 54 | H20: =SUMIFS('渠道充值成功率_底稿'!$C:$C,'渠道充值成功率_底稿'!$A:$A,$A20,'渠道充值成功率_底稿'!$B:$B,H$1) -> 0 | I20: =SUMIFS('渠道充值成功率_底稿'!$C:$C,'渠道充值成功率_底稿'!$A:$A,$A20,'渠道充值成功率_底稿'!$B:$B,I$1) -> 0 | J20: =SUMIFS('渠道充值成功率_底稿'!$C:$C,'渠道充值成功率_底稿'!$A:$A,$A20,'渠道充值成功率_底稿'!$B:$B,J$1) -> 0 | K20: =SUMIFS('渠道充值成功率_底稿'!$C:$C,'渠道充值成功率_底稿'!$A:$A,$A20,'渠道充值成功率_底稿'!$B:$B,K$1) -> 2 | L20: =SUMIFS('渠道充值成功率_底稿'!$C:$C,'渠道充值成功率_底稿'!$A:$A,$A20,'渠道充值成功率_底稿'!$B:$B,L$1) -> 0
A21: =B20 -> 46085 | C21: 到账笔数 | D21: =SUMIFS('渠道充值成功率_底稿'!$F:$F,'渠道充值成功率_底稿'!$A:$A,$A21,'渠道充值成功率_底稿'!$B:$B,D$1) -> 427 | E21: =SUMIFS('渠道充值成功率_底稿'!$F:$F,'渠道充值成功率_底稿'!$A:$A,$A21,'渠道充值成功率_底稿'!$B:$B,E$1) -> 7 | F21: =SUMIFS('渠道充值成功率_底稿'!$F:$F,'渠道充值成功率_底稿'!$A:$A,$A21,'渠道充值成功率_底稿'!$B:$B,F$1) -> 19 | G21: =SUMIFS('渠道充值成功率_底稿'!$F:$F,'渠道充值成功率_底稿'!$A:$A,$A21,'渠道充值成功率_底稿'!$B:$B,G$1) -> 49 | H21: =SUMIFS('渠道充值成功率_底稿'!$F:$F,'渠道充值成功率_底稿'!$A:$A,$A21,'渠道充值成功率_底稿'!$B:$B,H$1) -> 0 | I21: =SUMIFS('渠道充值成功率_底稿'!$F:$F,'渠道充值成功率_底稿'!$A:$A,$A21,'渠道充值成功率_底稿'!$B:$B,I$1) -> 0 | J21: =SUMIFS('渠道充值成功率_底稿'!$F:$F,'渠道充值成功率_底稿'!$A:$A,$A21,'渠道充值成功率_底稿'!$B:$B,J$1) -> 0 | K21: =SUMIFS('渠道充值成功率_底稿'!$F:$F,'渠道充值成功率_底稿'!$A:$A,$A21,'渠道充值成功率_底稿'!$B:$B,K$1) -> 2 | L21: =SUMIFS('渠道充值成功率_底稿'!$F:$F,'渠道充值成功率_底稿'!$A:$A,$A21,'渠道充值成功率_底稿'!$B:$B,L$1) -> 0
A22: =B20 -> 46085 | C22: 笔数成功率 | D22: =IFERROR(ROUND(D21/D20,6),"0") -> 0.862626 | E22: =IFERROR(ROUND(E21/E20,6),"0") -> 0.466667 | F22: =IFERROR(ROUND(F21/F20,6),"0") -> 0.678571 | G22: =IFERROR(ROUND(G21/G20,6),"0") -> 0.907407 | H22: =IFERROR(ROUND(H21/H20,6),"0") -> 0 | I22: =IFERROR(ROUND(I21/I20,6),"0") -> 0 | J22: =IFERROR(ROUND(J21/J20,6),"0") -> 0 | K22: =IFERROR(ROUND(K21/K20,6),"0") -> 1 | L22: =IFERROR(ROUND(L21/L20,6),"0") -> 0
A23: =B20 -> 46085 | C23: 申请金额 | D23: =SUMIFS('渠道充值成功率_底稿'!$D:$D,'渠道充值成功率_底稿'!$A:$A,$A24,'渠道充值成功率_底稿'!$B:$B,D$1) -> 75867 | E23: =SUMIFS('渠道充值成功率_底稿'!$D:$D,'渠道充值成功率_底稿'!$A:$A,$A23,'渠道充值成功率_底稿'!$B:$B,E$1) -> 3270 | F23: =SUMIFS('渠道充值成功率_底稿'!$D:$D,'渠道充值成功率_底稿'!$A:$A,$A23,'渠道充值成功率_底稿'!$B:$B,F$1) -> 4140 | G23: =SUMIFS('渠道充值成功率_底稿'!$D:$D,'渠道充值成功率_底稿'!$A:$A,$A23,'渠道充值成功率_底稿'!$B:$B,G$1) -> 12150 | H23: =SUMIFS('渠道充值成功率_底稿'!$D:$D,'渠道充值成功率_底稿'!$A:$A,$A23,'渠道充值成功率_底稿'!$B:$B,H$1) -> 0 | I23: =SUMIFS('渠道充值成功率_底稿'!$D:$D,'渠道充值成功率_底稿'!$A:$A,$A23,'渠道充值成功率_底稿'!$B:$B,I$1) -> 0 | J23: =SUMIFS('渠道充值成功率_底稿'!$D:$D,'渠道充值成功率_底稿'!$A:$A,$A23,'渠道充值成功率_底稿'!$B:$B,J$1) -> 0 | K23: =SUMIFS('渠道充值成功率_底稿'!$D:$D,'渠道充值成功率_底稿'!$A:$A,$A23,'渠道充值成功率_底稿'!$B:$B,K$1) -> 330 | L23: =SUMIFS('渠道充值成功率_底稿'!$D:$D,'渠道充值成功率_底稿'!$A:$A,$A23,'渠道充值成功率_底稿'!$B:$B,L$1) -> 0
A24: =B20 -> 46085 | C24: 到账金额 | D24: =SUMIFS('渠道充值成功率_底稿'!$G:$G,'渠道充值成功率_底稿'!$A:$A,$A25,'渠道充值成功率_底稿'!$B:$B,D$1) -> 68188 | E24: =SUMIFS('渠道充值成功率_底稿'!$G:$G,'渠道充值成功率_底稿'!$A:$A,$A24,'渠道充值成功率_底稿'!$B:$B,E$1) -> 1570 | F24: =SUMIFS('渠道充值成功率_底稿'!$G:$G,'渠道充值成功率_底稿'!$A:$A,$A24,'渠道充值成功率_底稿'!$B:$B,F$1) -> 2440 | G24: =SUMIFS('渠道充值成功率_底稿'!$G:$G,'渠道充值成功率_底稿'!$A:$A,$A24,'渠道充值成功率_底稿'!$B:$B,G$1) -> 10700 | H24: =SUMIFS('渠道充值成功率_底稿'!$G:$G,'渠道充值成功率_底稿'!$A:$A,$A24,'渠道充值成功率_底稿'!$B:$B,H$1) -> 0 | I24: =SUMIFS('渠道充值成功率_底稿'!$G:$G,'渠道充值成功率_底稿'!$A:$A,$A24,'渠道充值成功率_底稿'!$B:$B,I$1) -> 0 | J24: =SUMIFS('渠道充值成功率_底稿'!$G:$G,'渠道充值成功率_底稿'!$A:$A,$A24,'渠道充值成功率_底稿'!$B:$B,J$1) -> 0 | K24: =SUMIFS('渠道充值成功率_底稿'!$G:$G,'渠道充值成功率_底稿'!$A:$A,$A24,'渠道充值成功率_底稿'!$B:$B,K$1) -> 330 | L24: =SUMIFS('渠道充值成功率_底稿'!$G:$G,'渠道充值成功率_底稿'!$A:$A,$A24,'渠道充值成功率_底稿'!$B:$B,L$1) -> 0
A25: =B20 -> 46085 | C25: 金额成功率 | D25: =IFERROR(ROUND(D24/D23,6),"0") -> 0.898783 | E25: =IFERROR(ROUND(E24/E23,6),"0") -> 0.480122 | F25: =IFERROR(ROUND(F24/F23,6),"0") -> 0.589372 | G25: =IFERROR(ROUND(G24/G23,6),"0") -> 0.880658 | H25: =IFERROR(ROUND(H24/H23,6),"0") -> 0 | I25: =IFERROR(ROUND(I24/I23,6),"0") -> 0 | J25: =IFERROR(ROUND(J24/J23,6),"0") -> 0 | K25: =IFERROR(ROUND(K24/K23,6),"0") -> 1 | L25: =IFERROR(ROUND(L24/L23,6),"0") -> 0
A26: =B26 -> 46086 | B26: =B20+1 -> 46086 | C26: 申请笔数 | D26: =SUMIFS('渠道充值成功率_底稿'!$C:$C,'渠道充值成功率_底稿'!$A:$A,$A26,'渠道充值成功率_底稿'!$B:$B,D$1) -> 746 | E26: =SUMIFS('渠道充值成功率_底稿'!$C:$C,'渠道充值成功率_底稿'!$A:$A,$A26,'渠道充值成功率_底稿'!$B:$B,E$1) -> 25 | F26: =SUMIFS('渠道充值成功率_底稿'!$C:$C,'渠道充值成功率_底稿'!$A:$A,$A26,'渠道充值成功率_底稿'!$B:$B,F$1) -> 66 | G26: =SUMIFS('渠道充值成功率_底稿'!$C:$C,'渠道充值成功率_底稿'!$A:$A,$A26,'渠道充值成功率_底稿'!$B:$B,G$1) -> 80 | H26: =SUMIFS('渠道充值成功率_底稿'!$C:$C,'渠道充值成功率_底稿'!$A:$A,$A26,'渠道充值成功率_底稿'!$B:$B,H$1) -> 0 | I26: =SUMIFS('渠道充值成功率_底稿'!$C:$C,'渠道充值成功率_底稿'!$A:$A,$A26,'渠道充值成功率_底稿'!$B:$B,I$1) -> 0 | J26: =SUMIFS('渠道充值成功率_底稿'!$C:$C,'渠道充值成功率_底稿'!$A:$A,$A26,'渠道充值成功率_底稿'!$B:$B,J$1) -> 0 | K26: =SUMIFS('渠道充值成功率_底稿'!$C:$C,'渠道充值成功率_底稿'!$A:$A,$A26,'渠道充值成功率_底稿'!$B:$B,K$1) -> 21 | L26: =SUMIFS('渠道充值成功率_底稿'!$C:$C,'渠道充值成功率_底稿'!$A:$A,$A26,'渠道充值成功率_底稿'!$B:$B,L$1) -> 0
A27: =B26 -> 46086 | C27: 到账笔数 | D27: =SUMIFS('渠道充值成功率_底稿'!$F:$F,'渠道充值成功率_底稿'!$A:$A,$A27,'渠道充值成功率_底稿'!$B:$B,D$1) -> 494 | E27: =SUMIFS('渠道充值成功率_底稿'!$F:$F,'渠道充值成功率_底稿'!$A:$A,$A27,'渠道充值成功率_底稿'!$B:$B,E$1) -> 24 | F27: =SUMIFS('渠道充值成功率_底稿'!$F:$F,'渠道充值成功率_底稿'!$A:$A,$A27,'渠道充值成功率_底稿'!$B:$B,F$1) -> 30 | G27: =SUMIFS('渠道充值成功率_底稿'!$F:$F,'渠道充值成功率_底稿'!$A:$A,$A27,'渠道充值成功率_底稿'!$B:$B,G$1) -> 66 | H27: =SUMIFS('渠道充值成功率_底稿'!$F:$F,'渠道充值成功率_底稿'!$A:$A,$A27,'渠道充值成功率_底稿'!$B:$B,H$1) -> 0 | I27: =SUMIFS('渠道充值成功率_底稿'!$F:$F,'渠道充值成功率_底稿'!$A:$A,$A27,'渠道充值成功率_底稿'!$B:$B,I$1) -> 0 | J27: =SUMIFS('渠道充值成功率_底稿'!$F:$F,'渠道充值成功率_底稿'!$A:$A,$A27,'渠道充值成功率_底稿'!$B:$B,J$1) -> 0 | K27: =SUMIFS('渠道充值成功率_底稿'!$F:$F,'渠道充值成功率_底稿'!$A:$A,$A27,'渠道充值成功率_底稿'!$B:$B,K$1) -> 15 | L27: =SUMIFS('渠道充值成功率_底稿'!$F:$F,'渠道充值成功率_底稿'!$A:$A,$A27,'渠道充值成功率_底稿'!$B:$B,L$1) -> 0
A28: =B26 -> 46086 | C28: 笔数成功率 | D28: =IFERROR(ROUND(D27/D26,6),"0") -> 0.662198 | E28: =IFERROR(ROUND(E27/E26,6),"0") -> 0.96 | F28: =IFERROR(ROUND(F27/F26,6),"0") -> 0.454545 | G28: =IFERROR(ROUND(G27/G26,6),"0") -> 0.825 | H28: =IFERROR(ROUND(H27/H26,6),"0") -> 0 | I28: =IFERROR(ROUND(I27/I26,6),"0") -> 0 | J28: =IFERROR(ROUND(J27/J26,6),"0") -> 0 | K28: =IFERROR(ROUND(K27/K26,6),"0") -> 0.714286 | L28: =IFERROR(ROUND(L27/L26,6),"0") -> 0
A29: =B26 -> 46086 | C29: 申请金额 | D29: =SUMIFS('渠道充值成功率_底稿'!$D:$D,'渠道充值成功率_底稿'!$A:$A,$A30,'渠道充值成功率_底稿'!$B:$B,D$1) -> 129434 | E29: =SUMIFS('渠道充值成功率_底稿'!$D:$D,'渠道充值成功率_底稿'!$A:$A,$A29,'渠道充值成功率_底稿'!$B:$B,E$1) -> 4680 | F29: =SUMIFS('渠道充值成功率_底稿'!$D:$D,'渠道充值成功率_底稿'!$A:$A,$A29,'渠道充值成功率_底稿'!$B:$B,F$1) -> 10670 | G29: =SUMIFS('渠道充值成功率_底稿'!$D:$D,'渠道充值成功率_底稿'!$A:$A,$A29,'渠道充值成功率_底稿'!$B:$B,G$1) -> 28649 | H29: =SUMIFS('渠道充值成功率_底稿'!$D:$D,'渠道充值成功率_底稿'!$A:$A,$A29,'渠道充值成功率_底稿'!$B:$B,H$1) -> 0 | I29: =SUMIFS('渠道充值成功率_底稿'!$D:$D,'渠道充值成功率_底稿'!$A:$A,$A29,'渠道充值成功率_底稿'!$B:$B,I$1) -> 0 | J29: =SUMIFS('渠道充值成功率_底稿'!$D:$D,'渠道充值成功率_底稿'!$A:$A,$A29,'渠道充值成功率_底稿'!$B:$B,J$1) -> 0 | K29: =SUMIFS('渠道充值成功率_底稿'!$D:$D,'渠道充值成功率_底稿'!$A:$A,$A29,'渠道充值成功率_底稿'!$B:$B,K$1) -> 4550 | L29: =SUMIFS('渠道充值成功率_底稿'!$D:$D,'渠道充值成功率_底稿'!$A:$A,$A29,'渠道充值成功率_底稿'!$B:$B,L$1) -> 0
A30: =B26 -> 46086 | C30: 到账金额 | D30: =SUMIFS('渠道充值成功率_底稿'!$G:$G,'渠道充值成功率_底稿'!$A:$A,$A31,'渠道充值成功率_底稿'!$B:$B,D$1) -> 89429 | E30: =SUMIFS('渠道充值成功率_底稿'!$G:$G,'渠道充值成功率_底稿'!$A:$A,$A30,'渠道充值成功率_底稿'!$B:$B,E$1) -> 4480 | F30: =SUMIFS('渠道充值成功率_底稿'!$G:$G,'渠道充值成功率_底稿'!$A:$A,$A30,'渠道充值成功率_底稿'!$B:$B,F$1) -> 4183 | G30: =SUMIFS('渠道充值成功率_底稿'!$G:$G,'渠道充值成功率_底稿'!$A:$A,$A30,'渠道充值成功率_底稿'!$B:$B,G$1) -> 22356 | H30: =SUMIFS('渠道充值成功率_底稿'!$G:$G,'渠道充值成功率_底稿'!$A:$A,$A30,'渠道充值成功率_底稿'!$B:$B,H$1) -> 0 | I30: =SUMIFS('渠道充值成功率_底稿'!$G:$G,'渠道充值成功率_底稿'!$A:$A,$A30,'渠道充值成功率_底稿'!$B:$B,I$1) -> 0 | J30: =SUMIFS('渠道充值成功率_底稿'!$G:$G,'渠道充值成功率_底稿'!$A:$A,$A30,'渠道充值成功率_底稿'!$B:$B,J$1) -> 0 | K30: =SUMIFS('渠道充值成功率_底稿'!$G:$G,'渠道充值成功率_底稿'!$A:$A,$A30,'渠道充值成功率_底稿'!$B:$B,K$1) -> 2250 | L30: =SUMIFS('渠道充值成功率_底稿'!$G:$G,'渠道充值成功率_底稿'!$A:$A,$A30,'渠道充值成功率_底稿'!$B:$B,L$1) -> 0
A31: =B26 -> 46086 | C31: 金额成功率 | D31: =IFERROR(ROUND(D30/D29,6),"0") -> 0.690924 | E31: =IFERROR(ROUND(E30/E29,6),"0") -> 0.957265 | F31: =IFERROR(ROUND(F30/F29,6),"0") -> 0.392034 | G31: =IFERROR(ROUND(G30/G29,6),"0") -> 0.780341 | H31: =IFERROR(ROUND(H30/H29,6),"0") -> 0 | I31: =IFERROR(ROUND(I30/I29,6),"0") -> 0 | J31: =IFERROR(ROUND(J30/J29,6),"0") -> 0 | K31: =IFERROR(ROUND(K30/K29,6),"0") -> 0.494505 | L31: =IFERROR(ROUND(L30/L29,6),"0") -> 0
A32: =B32 -> 46087 | B32: =B26+1 -> 46087 | C32: 申请笔数 | D32: =SUMIFS('渠道充值成功率_底稿'!$C:$C,'渠道充值成功率_底稿'!$A:$A,$A32,'渠道充值成功率_底稿'!$B:$B,D$1) -> 731 | E32: =SUMIFS('渠道充值成功率_底稿'!$C:$C,'渠道充值成功率_底稿'!$A:$A,$A32,'渠道充值成功率_底稿'!$B:$B,E$1) -> 36 | F32: =SUMIFS('渠道充值成功率_底稿'!$C:$C,'渠道充值成功率_底稿'!$A:$A,$A32,'渠道充值成功率_底稿'!$B:$B,F$1) -> 60 | G32: =SUMIFS('渠道充值成功率_底稿'!$C:$C,'渠道充值成功率_底稿'!$A:$A,$A32,'渠道充值成功率_底稿'!$B:$B,G$1) -> 90 | H32: =SUMIFS('渠道充值成功率_底稿'!$C:$C,'渠道充值成功率_底稿'!$A:$A,$A32,'渠道充值成功率_底稿'!$B:$B,H$1) -> 0 | I32: =SUMIFS('渠道充值成功率_底稿'!$C:$C,'渠道充值成功率_底稿'!$A:$A,$A32,'渠道充值成功率_底稿'!$B:$B,I$1) -> 0 | J32: =SUMIFS('渠道充值成功率_底稿'!$C:$C,'渠道充值成功率_底稿'!$A:$A,$A32,'渠道充值成功率_底稿'!$B:$B,J$1) -> 0 | K32: =SUMIFS('渠道充值成功率_底稿'!$C:$C,'渠道充值成功率_底稿'!$A:$A,$A32,'渠道充值成功率_底稿'!$B:$B,K$1) -> 8 | L32: =SUMIFS('渠道充值成功率_底稿'!$C:$C,'渠道充值成功率_底稿'!$A:$A,$A32,'渠道充值成功率_底稿'!$B:$B,L$1) -> 0
A33: =B32 -> 46087 | C33: 到账笔数 | D33: =SUMIFS('渠道充值成功率_底稿'!$F:$F,'渠道充值成功率_底稿'!$A:$A,$A33,'渠道充值成功率_底稿'!$B:$B,D$1) -> 400 | E33: =SUMIFS('渠道充值成功率_底稿'!$F:$F,'渠道充值成功率_底稿'!$A:$A,$A33,'渠道充值成功率_底稿'!$B:$B,E$1) -> 29 | F33: =SUMIFS('渠道充值成功率_底稿'!$F:$F,'渠道充值成功率_底稿'!$A:$A,$A33,'渠道充值成功率_底稿'!$B:$B,F$1) -> 26 | G33: =SUMIFS('渠道充值成功率_底稿'!$F:$F,'渠道充值成功率_底稿'!$A:$A,$A33,'渠道充值成功率_底稿'!$B:$B,G$1) -> 69 | H33: =SUMIFS('渠道充值成功率_底稿'!$F:$F,'渠道充值成功率_底稿'!$A:$A,$A33,'渠道充值成功率_底稿'!$B:$B,H$1) -> 0 | I33: =SUMIFS('渠道充值成功率_底稿'!$F:$F,'渠道充值成功率_底稿'!$A:$A,$A33,'渠道充值成功率_底稿'!$B:$B,I$1) -> 0 | J33: =SUMIFS('渠道充值成功率_底稿'!$F:$F,'渠道充值成功率_底稿'!$A:$A,$A33,'渠道充值成功率_底稿'!$B:$B,J$1) -> 0 | K33: =SUMIFS('渠道充值成功率_底稿'!$F:$F,'渠道充值成功率_底稿'!$A:$A,$A33,'渠道充值成功率_底稿'!$B:$B,K$1) -> 7 | L33: =SUMIFS('渠道充值成功率_底稿'!$F:$F,'渠道充值成功率_底稿'!$A:$A,$A33,'渠道充值成功率_底稿'!$B:$B,L$1) -> 0
A34: =B32 -> 46087 | C34: 笔数成功率 | D34: =IFERROR(ROUND(D33/D32,6),"0") -> 0.547196 | E34: =IFERROR(ROUND(E33/E32,6),"0") -> 0.805556 | F34: =IFERROR(ROUND(F33/F32,6),"0") -> 0.433333 | G34: =IFERROR(ROUND(G33/G32,6),"0") -> 0.766667 | H34: =IFERROR(ROUND(H33/H32,6),"0") -> 0 | I34: =IFERROR(ROUND(I33/I32,6),"0") -> 0 | J34: =IFERROR(ROUND(J33/J32,6),"0") -> 0 | K34: =IFERROR(ROUND(K33/K32,6),"0") -> 0.875 | L34: =IFERROR(ROUND(L33/L32,6),"0") -> 0
A35: =B32 -> 46087 | C35: 申请金额 | D35: =SUMIFS('渠道充值成功率_底稿'!$D:$D,'渠道充值成功率_底稿'!$A:$A,$A36,'渠道充值成功率_底稿'!$B:$B,D$1) -> 123829 | E35: =SUMIFS('渠道充值成功率_底稿'!$D:$D,'渠道充值成功率_底稿'!$A:$A,$A35,'渠道充值成功率_底稿'!$B:$B,E$1) -> 9587 | F35: =SUMIFS('渠道充值成功率_底稿'!$D:$D,'渠道充值成功率_底稿'!$A:$A,$A35,'渠道充值成功率_底稿'!$B:$B,F$1) -> 13060 | G35: =SUMIFS('渠道充值成功率_底稿'!$D:$D,'渠道充值成功率_底稿'!$A:$A,$A35,'渠道充值成功率_底稿'!$B:$B,G$1) -> 9860 | H35: =SUMIFS('渠道充值成功率_底稿'!$D:$D,'渠道充值成功率_底稿'!$A:$A,$A35,'渠道充值成功率_底稿'!$B:$B,H$1) -> 0 | I35: =SUMIFS('渠道充值成功率_底稿'!$D:$D,'渠道充值成功率_底稿'!$A:$A,$A35,'渠道充值成功率_底稿'!$B:$B,I$1) -> 0 | J35: =SUMIFS('渠道充值成功率_底稿'!$D:$D,'渠道充值成功率_底稿'!$A:$A,$A35,'渠道充值成功率_底稿'!$B:$B,J$1) -> 0 | K35: =SUMIFS('渠道充值成功率_底稿'!$D:$D,'渠道充值成功率_底稿'!$A:$A,$A35,'渠道充值成功率_底稿'!$B:$B,K$1) -> 2020 | L35: =SUMIFS('渠道充值成功率_底稿'!$D:$D,'渠道充值成功率_底稿'!$A:$A,$A35,'渠道充值成功率_底稿'!$B:$B,L$1) -> 0
A36: =B32 -> 46087 | C36: 到账金额 | D36: =SUMIFS('渠道充值成功率_底稿'!$G:$G,'渠道充值成功率_底稿'!$A:$A,$A37,'渠道充值成功率_底稿'!$B:$B,D$1) -> 62040 | E36: =SUMIFS('渠道充值成功率_底稿'!$G:$G,'渠道充值成功率_底稿'!$A:$A,$A36,'渠道充值成功率_底稿'!$B:$B,E$1) -> 6087 | F36: =SUMIFS('渠道充值成功率_底稿'!$G:$G,'渠道充值成功率_底稿'!$A:$A,$A36,'渠道充值成功率_底稿'!$B:$B,F$1) -> 5460 | G36: =SUMIFS('渠道充值成功率_底稿'!$G:$G,'渠道充值成功率_底稿'!$A:$A,$A36,'渠道充值成功率_底稿'!$B:$B,G$1) -> 7338 | H36: =SUMIFS('渠道充值成功率_底稿'!$G:$G,'渠道充值成功率_底稿'!$A:$A,$A36,'渠道充值成功率_底稿'!$B:$B,H$1) -> 0 | I36: =SUMIFS('渠道充值成功率_底稿'!$G:$G,'渠道充值成功率_底稿'!$A:$A,$A36,'渠道充值成功率_底稿'!$B:$B,I$1) -> 0 | J36: =SUMIFS('渠道充值成功率_底稿'!$G:$G,'渠道充值成功率_底稿'!$A:$A,$A36,'渠道充值成功率_底稿'!$B:$B,J$1) -> 0 | K36: =SUMIFS('渠道充值成功率_底稿'!$G:$G,'渠道充值成功率_底稿'!$A:$A,$A36,'渠道充值成功率_底稿'!$B:$B,K$1) -> 1520 | L36: =SUMIFS('渠道充值成功率_底稿'!$G:$G,'渠道充值成功率_底稿'!$A:$A,$A36,'渠道充值成功率_底稿'!$B:$B,L$1) -> 0
A37: =B32 -> 46087 | C37: 金额成功率 | D37: =IFERROR(ROUND(D36/D35,6),"0") -> 0.501013 | E37: =IFERROR(ROUND(E36/E35,6),"0") -> 0.634922 | F37: =IFERROR(ROUND(F36/F35,6),"0") -> 0.41807 | G37: =IFERROR(ROUND(G36/G35,6),"0") -> 0.744219 | H37: =IFERROR(ROUND(H36/H35,6),"0") -> 0 | I37: =IFERROR(ROUND(I36/I35,6),"0") -> 0 | J37: =IFERROR(ROUND(J36/J35,6),"0") -> 0 | K37: =IFERROR(ROUND(K36/K35,6),"0") -> 0.752475 | L37: =IFERROR(ROUND(L36/L35,6),"0") -> 0
A38: =B38 -> 46088 | B38: =B32+1 -> 46088 | C38: 申请笔数 | D38: =SUMIFS('渠道充值成功率_底稿'!$C:$C,'渠道充值成功率_底稿'!$A:$A,$A38,'渠道充值成功率_底稿'!$B:$B,D$1) -> 465 | E38: =SUMIFS('渠道充值成功率_底稿'!$C:$C,'渠道充值成功率_底稿'!$A:$A,$A38,'渠道充值成功率_底稿'!$B:$B,E$1) -> 11 | F38: =SUMIFS('渠道充值成功率_底稿'!$C:$C,'渠道充值成功率_底稿'!$A:$A,$A38,'渠道充值成功率_底稿'!$B:$B,F$1) -> 34 | G38: =SUMIFS('渠道充值成功率_底稿'!$C:$C,'渠道充值成功率_底稿'!$A:$A,$A38,'渠道充值成功率_底稿'!$B:$B,G$1) -> 43 | H38: =SUMIFS('渠道充值成功率_底稿'!$C:$C,'渠道充值成功率_底稿'!$A:$A,$A38,'渠道充值成功率_底稿'!$B:$B,H$1) -> 0 | I38: =SUMIFS('渠道充值成功率_底稿'!$C:$C,'渠道充值成功率_底稿'!$A:$A,$A38,'渠道充值成功率_底稿'!$B:$B,I$1) -> 0 | J38: =SUMIFS('渠道充值成功率_底稿'!$C:$C,'渠道充值成功率_底稿'!$A:$A,$A38,'渠道充值成功率_底稿'!$B:$B,J$1) -> 0 | K38: =SUMIFS('渠道充值成功率_底稿'!$C:$C,'渠道充值成功率_底稿'!$A:$A,$A38,'渠道充值成功率_底稿'!$B:$B,K$1) -> 5 | L38: =SUMIFS('渠道充值成功率_底稿'!$C:$C,'渠道充值成功率_底稿'!$A:$A,$A38,'渠道充值成功率_底稿'!$B:$B,L$1) -> 0
A39: =B38 -> 46088 | C39: 到账笔数 | D39: =SUMIFS('渠道充值成功率_底稿'!$F:$F,'渠道充值成功率_底稿'!$A:$A,$A39,'渠道充值成功率_底稿'!$B:$B,D$1) -> 388 | E39: =SUMIFS('渠道充值成功率_底稿'!$F:$F,'渠道充值成功率_底稿'!$A:$A,$A39,'渠道充值成功率_底稿'!$B:$B,E$1) -> 10 | F39: =SUMIFS('渠道充值成功率_底稿'!$F:$F,'渠道充值成功率_底稿'!$A:$A,$A39,'渠道充值成功率_底稿'!$B:$B,F$1) -> 21 | G39: =SUMIFS('渠道充值成功率_底稿'!$F:$F,'渠道充值成功率_底稿'!$A:$A,$A39,'渠道充值成功率_底稿'!$B:$B,G$1) -> 38 | H39: =SUMIFS('渠道充值成功率_底稿'!$F:$F,'渠道充值成功率_底稿'!$A:$A,$A39,'渠道充值成功率_底稿'!$B:$B,H$1) -> 0 | I39: =SUMIFS('渠道充值成功率_底稿'!$F:$F,'渠道充值成功率_底稿'!$A:$A,$A39,'渠道充值成功率_底稿'!$B:$B,I$1) -> 0 | J39: =SUMIFS('渠道充值成功率_底稿'!$F:$F,'渠道充值成功率_底稿'!$A:$A,$A39,'渠道充值成功率_底稿'!$B:$B,J$1) -> 0 | K39: =SUMIFS('渠道充值成功率_底稿'!$F:$F,'渠道充值成功率_底稿'!$A:$A,$A39,'渠道充值成功率_底稿'!$B:$B,K$1) -> 3 | L39: =SUMIFS('渠道充值成功率_底稿'!$F:$F,'渠道充值成功率_底稿'!$A:$A,$A39,'渠道充值成功率_底稿'!$B:$B,L$1) -> 0
A40: =B38 -> 46088 | C40: 笔数成功率 | D40: =IFERROR(ROUND(D39/D38,6),"0") -> 0.834409 | E40: =IFERROR(ROUND(E39/E38,6),"0") -> 0.909091 | F40: =IFERROR(ROUND(F39/F38,6),"0") -> 0.617647 | G40: =IFERROR(ROUND(G39/G38,6),"0") -> 0.883721 | H40: =IFERROR(ROUND(H39/H38,6),"0") -> 0 | I40: =IFERROR(ROUND(I39/I38,6),"0") -> 0 | J40: =IFERROR(ROUND(J39/J38,6),"0") -> 0 | K40: =IFERROR(ROUND(K39/K38,6),"0") -> 0.6 | L40: =IFERROR(ROUND(L39/L38,6),"0") -> 0
...

Sheet 渠道充值成功率_底稿
B1: jiliarena
A2: 时间 | B2: 充值方式 | C2: 申请笔数 | D2: 申请金额 | E2: 申请人数 | F2: 到账笔数 | G2: 到账金额 | H2: 到账人数 | I2: 首存人数 | J2: 首存金额 | K2: 成功率 (%) | L2: 到账金额占比 (%) | M2: 平均到账时间
A3: 46082 | B3: GOTYME | C3: 6 | D3: 900 | E3: 5 | F3: 4 | G3: 700 | H3: 4 | I3: 3 | J3: 500 | K3: 66.66 % | L3: 0.37 % | M3: 0.0046064815
A4: 46082 | B4: QRPH | C4: 32 | D4: 5860 | E4: 19 | F4: 24 | G4: 4610 | H4: 17 | I4: 11 | J4: 2050 | K4: 75.00 % | L4: 2.46 % | M4: 0.00081018519
A5: 46082 | B5: GCash | C5: 1458 | D5: 201674 | E5: 854 | F5: 1065 | G5: 162179 | H5: 786 | I5: 530 | J5: 75007 | K5: 73.04 % | L5: 86.75 % | M5: 0.00071759259
A6: 46082 | B6: GCashQR | C6: 61 | D6: 8630 | E6: 46 | F6: 41 | G6: 5980 | H6: 32 | I6: 21 | J6: 3000 | K6: 67.21 % | L6: 3.19 % | M6: 0.00075231481
A7: 46082 | B7: Maya | C7: 146 | D7: 18592 | E7: 120 | F7: 117 | G7: 13472 | H7: 104 | I7: 60 | J7: 6970 | K7: 80.13 % | L7: 7.20 % | M7: 0.000625
A9: 46083 | B9: GOTYME | C9: 14 | D9: 3110 | E9: 4 | F9: 13 | G9: 2910 | H9: 3 | I9: 1 | J9: 200 | K9: 92.85 % | L9: 3.21 % | M9: 0.000625
A10: 46083 | B10: QRPH | C10: 14 | D10: 2325 | E10: 6 | F10: 13 | G10: 2225 | H10: 5 | I10: 0 | J10: 0 | K10: 92.85 % | L10: 2.45 % | M10: 0.00045138889
A11: 46083 | B11: GCash | C11: 611 | D11: 97556 | E11: 382 | F11: 492 | G11: 76391 | H11: 359 | I11: 119 | J11: 17236 | K11: 80.52 % | L11: 84.45 % | M11: 0.00074074074
A12: 46083 | B12: GCashQR | C12: 30 | D12: 4167 | E12: 24 | F12: 24 | G12: 3467 | H12: 19 | I12: 8 | J12: 1235 | K12: 80.00 % | L12: 3.83 % | M12: 0.00056712963
A13: 46083 | B13: Maya | C13: 81 | D13: 9777 | E13: 54 | F13: 57 | G13: 5458 | H13: 46 | I13: 12 | J13: 1024 | K13: 70.37 % | L13: 6.03 % | M13: 0.000625
A15: 46084 | B15: GOTYME | C15: 11 | D15: 2100 | E15: 4 | F15: 6 | G15: 1200 | H15: 2 | I15: 0 | J15: 0 | K15: 54.54 % | L15: 1.37 % | M15: 0.00060185185
A16: 46084 | B16: QRPH | C16: 22 | D16: 3250 | E16: 5 | F16: 21 | G16: 3050 | H16: 4 | I16: 0 | J16: 0 | K16: 95.45 % | L16: 3.49 % | M16: 0.00054398148
... A59: 46091 | B59: Maya | C59: 58 | D59: 6569 | E59: 35 | F59: 42 | G59: 4709 | H59: 31 | I59: 7 | J59: 550 | K59: 72.41 % | L59: 8.76 % | M59: 0.00069444444
A61: 46092 | B61: GOTYME | C61: 5 | D61: 600 | E61: 2 | F61: 5 | G61: 600 | H61: 2 | I61: 1 | J61: 100 | K61: 100 | L61: 1.12 | M61: 0.0017939815
A62: 46092 | B62: QRPH | C62: 18 | D62: 4270 | E62: 8 | F62: 12 | G62: 2770 | H62: 7 | I62: 3 | J62: 300 | K62: 66.66 | L62: 5.2 | M62: 0.00056712963
A63: 46092 | B63: GCash | C63: 479 | D63: 63978 | E63: 301 | F63: 331 | G63: 43743 | H63: 268 | I63: 93 | J63: 11375 | K63: 69.1 | L63: 82.11 | M63: 0.00087962963
A64: 46092 | B64: GCashQR | C64: 26 | D64: 3306 | E64: 20 | F64: 11 | G64: 1151 | H64: 11 | I64: 3 | J64: 300 | K64: 42.3 | L64: 2.16 | M64: 0.0014351852
A65: 46092 | B65: Maya | C65: 70 | D65: 10363 | E65: 51 | F65: 49 | G65: 5004 | H65: 43 | I65: 19 | J65: 2035 | K65: 70 | L65: 9.39 | M65: 0.00065972222

Sheet jiliarena
A1: jiliarena | W1: 净输/投注 | Z1: 净赢/中奖 | BW1: 8月 | BX1: 手续费费率 | BY1: 0.0241 | BZ1: 0.002
B2: 报表管理-平台损益总表 | C2: 报表管理-平台损益总表 | D2: 报表管理-平台损益总表 | E2: 报表管理-留存用户分析 | F2: 报表管理-平台损益总表 | G2: 报表管理-平台损益-充值 | H2: 报表管理-平台损益总表 | J2: 报表管理-平台损益总表 | L2: 报表管理-平台损益总表 | M2: 报表管理-平台损益总表 | W2: 报表管理-游戏玩家分析 | X2: 报表管理-游戏玩家分析 | Y2: 报表管理-游戏玩家分析 | Z2: 报表管理-游戏玩家分析 | AT2: GAME_REBATE | AU2: APP_DOWNLOAD | AV2: DEPOSIT | AW2: LOGIN | AX2: UPGRADE_BONUS | AY2: MANUAL | BA2: PROMO_CODE | BB2: 邀请返佣 | BC2: LOGIN_TASK | BD2: DEPOSIT_BET_BONUS | BE2: SAVIOR | BF2: MISSION | BG2: RANK_SALARY | BH2: SECOND_DEPOSIT | BI2: THIRD_DEPOSIT | BJ2: FIRST_DEPOSIT | BY2: 报表管理-平台损益-手续费 | BZ2: 报表管理-平台损益-手续费 | CF2: 报表管理-平台损益-平台毛利 | CG2: 报表管理-平台损益-平台毛利 | CH2: 报表管理-平台损益-平台毛利
B3: 注册人数 | C3: 首充人数 | D3: 登录人数 | E3: 报表管理-留存用户分析 | F3: 存款人数 | G3: 存款次数 | H3: 提款人数 | I3: 出款笔数 | J3: 投注人数 | K3: 总首存 | L3: 日充值 | M3: 提款金额 | N3: 公式 | O3: 公式 | P3: 公式 | Q3: 公式 | R3: 公式 | S3: 公式 | T3: 公式 | U3: 公式 | V3: 公式 | W3: 投注 | X3: 有效投注 | Y3: 公司输赢 | Z3: 派彩 | AA3: 公式 | AB3: 棋牌输额 | AC3: 棋牌赢额 | AD3: 公式 | AE3: 电子投注 | AF3: 电子中奖 | AG3: 公式 | AH3: 真人投注 | AI3: 真人中奖 | AJ3: 公式 | AK3: 捕鱼投注 | AL3: 捕鱼中奖 | AM3: 公式 | AN3: 体育投注 | AO3: 体育中奖 | AP3: 公式 | AQ3: 盘口彩票投注 | AR3: 盘口彩票中奖 | AS3: 公式 | AT3: 玩家返水 | AU3: APP下载 | AV3: 笔笔存送 | AW3: 签到奖励 | AX3: 升级奖励 | AY3: 手动红利 | AZ3: 红利扣除 | BA3: 优惠码 | BB3: 邀请返佣 | BC3: 登录任务 | BD3: 存款达标奖励 | BE3: 关怀援助金 | BF3: 任务排行榜 | BG3: VIP俸禄 | BH3: 二次存送 | BI3: 三次存送 | BJ3: 首存 | BK3: 新手任务奖励 | BL3: 注册奖励 | BM3: 四次存送 | BN3: 五次存送 | BQ3: 总优惠 | BR3: 返点 | BS3: 代理贡献层级 | BT3: 公式 | BW3: 公式 | BY3: 渠道手续费 | BZ3: 玩家提现手续费 | CA3: 公式 | CB3: 公式 | CD3: 代理佣金（周） | CE3: 代理佣金（月 | CF3: 开分 | CG3: 洗分 | CH3: 结算余额
A4: 时间 Date | B4: 平台新注册人数 Total New Users | C4: 总首充人数 first depositor / no of first time depositors | D4: 总登录人数 Login Head Count | E4: 续存人数 Number of survivors | F4: 总存款人数 no of total depositors | G4: 总存款次数 deposit times / total deposit counts | H4: 总取款人数 no of total withdrawer | I4: 总取款次数 withdrawal times / total withdrawal counts | J4: 总投注人数 no of bettors / No of bet | K4: 首存金额 First deposit amount | L4: 总存款额度 total deposit amount | M4: 总取款额度 total withdrawal amount | N4: 平台转化率 Conversion rate | O4: 人均首存金额 | P4: 首存比例存款 First deposit ratio total deposit | Q4: 人均次数 Per capita times | R4: 人均入款 Per capita deposit | S4: 單次人均入款 | T4: 續存/首存 比 | U4: 人均提款 Withdrawal per capita | V4: 存提差 Deposit/withdrawal difference | W4: 投注 Betting | X4: 有效投注额 Valid bet | Y4: 公司输赢 Win or lose | Z4: 派彩 Payouts | AA4: 杀率 kill rate | AB4: 棋牌投注 PVP Bet | AC4: 棋牌赢额 PVP Win | AD4: 棋牌杀率 PVP kill rate | AE4: 電子投注 RNG Bet | AF4: 電子中獎 RNG Win | AG4: 電子杀率 RNG kill rate | AH4: 真人投注 LIVE Bet | AI4: 真人中獎 LIVE Win | AJ4: 真人杀率 LIVE kill rate | AK4: 捕魚投注 FISH Bet | AL4: 捕魚中獎 FISH Win | AM4: 捕魚杀率 FISH kill rate | AN4: 體育投注 SPORTS Bet | AO4: 體育中獎 SPORTS Win | AP4: 體育杀率 SPORTS kill rate | AQ4: 盘口彩票投注 ELOTT Bet | AR4: 盘口彩票中獎 ELOTT Win | AS4: 盘口彩票 ELOTT kill rate | AT4: 玩家返水 | AU4: APP下载 | AV4: 笔笔存送 | AW4: 签到奖励 | AX4: 升级奖励 | AY4: 手动红利 | AZ4: 红利扣除 | BA4: 优惠码 | BB4: 邀请返佣 | BC4: 登录任务 | BD4: 存款达标奖励 | BE4: 关怀援助金 | BF4: 任务排行榜 | BG4: VIP俸禄 | BH4: 二次存送 | BI4: 三次存送 | BJ4: 首存 | BK4: 新手任务奖励 | BL4: 注册奖励 | BM4: 四次存送 | BN4: 五次存送 | BP4: 其他奖励 Other Bonus | BQ4: 总优惠 （Z+...+AH） Total Bonus | BR4: 返点 Rebates | BS4: 邀请返佣 Referral rebates | BT4: 优惠占比投注 Preferential ratio bet | BU4: 优惠占比充值 Bonus rebates | BV4: 优惠占比游戏亏损 Preferential astio loss | BW4: 公司净利 company net profit | BX4: 優惠/ 淨利 | BY4: 存款手续费 Deposit fees | BZ4: 提款手续费 Withdrawal fees | CA4: 支付手续费 service fees (Payment Channel Fee) | CB4: 预估平台费9% Estimate platform fee | CC4: 支付費用/淨利 | CD4: 代理佣金（周） Affiliate Commission (Weekly) | CE4: 代理佣金（月） Affiliate Commission (Monthly) | CF4: 開分 Credit Adjustment | CG4: 洗分 Debit Adjustment | CH4: 平台余额 Platform balance | CI4: 平台毛利 3 GP3 | CJ4: 月份 | CK4: 日期
A5: 46076 | B5: 623 | C5: 161 | D5: 3493 | E5: 33 | F5: 419 | G5: 578 | H5: 94 | I5: 132 | J5: 2358 | K5: 21559 | L5: 75103 | M5: 67348 | N5: 0.2584 | O5: 134 | P5: 0.2871 | Q5: 1.4 | R5: 179 | S5: 130 | T5: 1 | U5: 716 | V5: 7755 | W5: 799540.59 | X5: 751956.38 | Y5: 23986.09 | Z5: 775554.5 | AA5: 0.03 | AB5: 0 | AC5: 0 | AD5: #DIV/0! | AE5: 767010.59 | AF5: 740575.58 | AG5: 0.0345 | AH5: 3935 | AI5: 4190 | AJ5: -0.0648 | AK5: 27093.9 | AL5: 28727.6 | AM5: -0.0603 | AN5: 1495.1 | AO5: 981.32 | AP5: 0.3436 | AQ5: 6 | AR5: 1080 | AS5: -179 | AT5: 5406.93 | AU5: 0 | AV5: 3121.1 | AW5: 4366 | AX5: 427 | AY5: 0 | AZ5: 0 | BA5: 0 | BB5: 457.68 | BC5: 246 | BD5: 0 | BE5: 0 | BF5: 405 | BG5: 0 | BH5: 0 | BI5: 0 | BJ5: 3777 | BK5: 0 | BL5: 0 | BM5: 0 | BN5: 0 | BO5: 0 | BP5: 0 | BQ5: 18206.71 | BR5: 5406.93 | BS5: 457.68 | BT5: 0.0242 | BU5: 0.2424 | BV5: 0.7591 | BW5: 5779 | BX5: 3.1503 | BY5: 1810 | BZ5: 135 | CA5: 1945 | CB5: 2159 | CC5: 0.3365 | CD5: 0 | CF5: 0 | CG5: 0 | CH5: 88711.73 | CI5: 1676 | CJ5: 2 | CK5: 23
A6: 46077 | B6: 707 | C6: 199 | D6: 3785 | E6: 39 | F6: 498 | G6: 699 | H6: 95 | I6: 125 | J6: 2686 | K6: 29064 | L6: 120843 | M6: 59351 | N6: 0.2815 | O6: 146 | P6: 0.2405 | Q6: 1.4 | R6: 243 | S6: 173 | T6: 1.2 | U6: 625 | V6: 61492 | W6: 1175025.7 | X6: 1108281.9 | Y6: 63427.47 | Z6: 1111598.2 | AA6: 0.054 | AB6: 1 | AC6: 0 | AD6: 1 | AE6: 1086922.3 | AF6: 1029615.4 | AG6: 0.0527 | AH6: 14221.23 | AI6: 10874.82 | AJ6: 0.2353 | AK6: 71861.15 | AL6: 69691.8 | AM6: 0.0302 | AN6: 2018 | AO6: 1416.17 | AP6: 0.2982 | AQ6: 2 | AR6: 0 | AS6: 1 | AT6: 2417.95 | AU6: 0 | AV6: 3828.77 | AW6: 4504 | AX6: 457 | AY6: 0 | AZ6: 0 | BA6: 0 | BB6: 471.85 | BC6: 348 | BD6: 0 | BE6: 0 | BF6: 497 | BG6: 0 | BH6: 0 | BI6: 0 | BJ6: 3603 | BK6: 0 | BL6: 0 | BM6: 0 | BN6: 0 | BO6: 0 | BP6: 0 | BQ6: 16127.57 | BR6: 2417.95 | BS6: 471.85 | BT6: 0.0146 | BU6: 0.1335 | BV6: 0.2543 | BW6: 47300 | BX6: 0.341 | BY6: 2912 | BZ6: 119 | CA6: 3031 | CB6: 5708 | CC6: 0.0641 | CD6: 0 | CF6: 0 | CG6: 0 | CH6: 93016.97 | CI6: 38561 | CJ6: 2 | CK6: 24
A7: 46078 | B7: 826 | C7: 213 | D7: 3611 | E7: 36 | F7: 481 | G7: 657 | H7: 97 | I7: 121 | J7: 2548 | K7: 27687 | L7: 92719 | M7: 75437 | N7: 0.2579 | O7: 130 | P7: 0.2986 | Q7: 1.4 | R7: 193 | S7: 141 | T7: 1.1 | U7: 778 | V7: 17282 | W7: 873983.42 | X7: 822652.93 | Y7: 17252.13 | Z7: 856731.3 | AA7: 0.0197 | AB7: 0 | AC7: 0 | AD7: #DIV/0! | AE7: 840574.91 | AF7: 823468.46 | AG7: 0.0204 | AH7: 15722.08 | AI7: 15147.22 | AJ7: 0.0366 | AK7: 17582.43 | AL7: 18115.62 | AM7: -0.0303 | AN7: 100 | AO7: 0 | AP7: 1 | AQ7: 4 | AR7: 0 | AS7: 1 | AT7: 3906.86 | AU7: 0 | AV7: 2830.51 | AW7: 4518 | AX7: 580 | AY7: 0 | AZ7: 0 | BA7: 0 | BB7: 271.96 | BC7: 318 | BD7: 0 | BE7: 0 | BF7: 291 | BG7: 0 | BH7: 0 | BI7: 0 | BJ7: 4701 | BK7: 0 | BL7: 0 | BM7: 0 | BN7: 0 | BO7: 0 | BP7: 0 | BQ7: 17417.33 | BR7: 3906.86 | BS7: 271.96 | BT7: 0.0212 | BU7: 0.1879 | BV7: 1.0096 | BW7: -165 | BX7: -105.4286 | BY7: 2235 | BZ7: 151 | CA7: 2385 | CB7: 1553 | CC7: -14.439 | CD7: 0 | CF7: 0 | CG7: 0 | CH7: 96459.38 | CI7: -4104 | CJ7: 2 | CK7: 25
A8: 46079 | B8: 594 | C8: 172 | D8: 3223 | E8: 52 | F8: 437 | G8: 634 | H8: 108 | I8: 146 | J8: 2304 | K8: 23238 | L8: 96473 | M8: 89750 | N8: 0.2896 | O8: 135 | P8: 0.2409 | Q8: 1.5 | R8: 221 | S8: 152 | T8: 1.1 | U8: 831 | V8: 6723 | W8: 853298.63 | X8: 804306.43 | Y8: 13146.22 | Z8: 840152.41 | AA8: 0.0154 | AB8: 60 | AC8: 0 | AD8: 1 | AE8: 821477.24 | AF8: 808905.75 | AG8: 0.0153 | AH8: 18235.59 | AI8: 19190 | AJ8: -0.0523 | AK8: 13524.8 | AL8: 12056.66 | AM8: 0.1086 | AN8: 0 | AO8: 0 | AP8: #DIV/0! | AQ8: 1 | AR8: 0 | AS8: 1 | AT8: 3076.5 | AU8: 0 | AV8: 3710.2 | AW8: 3784 | AX8: 528 | AY8: 0 | AZ8: 0 | BA8: 0 | BB8: 104.46 | BC8: 346 | BD8: 0 | BE8: 0 | BF8: 424 | BG8: 0 | BH8: 0 | BI8: 0 | BJ8: 4112.5 | BK8: 0 | BL8: 0 | BM8: 0 | BN8: 0 | BO8: 0 | BP8: 0 | BQ8: 16085.66 | BR8: 3076.5 | BS8: 104.46 | BT8: 0.02 | BU8: 0.1667 | BV8: 1.2236 | BW8: -2939 | BX8: -5.4724 | BY8: 2325 | BZ8: 180 | CA8: 2504 | CB8: 1183 | CC8: -0.852 | CD8: 0 | CF8: 0 | CG8: 0 | CH8: 94316.75 | CI8: -6627 | CJ8: 2 | CK8: 26
A9: 46080 | B9: 268 | C9: 89 | D9: 2890 | E9: 16 | F9: 352 | G9: 519 | H9: 92 | I9: 519 | J9: 2122 | K9: 12300 | L9: 94962 | M9: 93643 | N9: 0.3321 | O9: 138 | P9: 0.1295 | Q9: 1.5 | R9: 270 | S9: 183 | T9: 1.3 | U9: 1018 | V9: 1319 | W9: 742129.38 | X9: 692850.77 | Y9: 11032.04 | Z9: 731097.35 | AA9: 0.0149 | AB9: 0 | AC9: 0 | AD9: #DIV/0! | AE9: 734752.98 | AF9: 724516.45 | AG9: 0.0139 | AH9: 2734.5 | AI9: 1846.5 | AJ9: 0.3247 | AK9: 4639.9 | AL9: 4734.4 | AM9: -0.0204 | AN9: 0 | AO9: 0 | AP9: #DIV/0! | AQ9: 2 | AR9: 0 | AS9: 1 | AT9: 2605.21 | AU9: 0 | AV9: 2664.5 | AW9: 3699 | AX9: 340 | AY9: 0 | AZ9: 0 | BA9: 0 | BB9: 208.11 | BC9: 249 | BD9: 0 | BE9: 0 | BF9: 6 | BG9: 0 | BH9: 0 | BI9: 0 | BJ9: 2075 | BK9: 0 | BL9: 0 | BM9: 0 | BN9: 0 | BO9: 0 | BP9: 0 | BQ9: 11846.82 | BR9: 2605.21 | BS9: 208.11 | BT9: 0.0171 | BU9: 0.1248 | BV9: 1.0739 | BW9: -815 | BX9: -14.5398 | BY9: 2289 | BZ9: 187 | CA9: 2476 | CB9: 993 | CC9: -3.0387 | CD9: 0 | CF9: 0 | CG9: 0 | CH9: 96202.4 | CI9: -4284 | CJ9: 2 | CK9: 27
A10: 46081 | B10: 717 | C10: 231 | D10: 3515 | E10: 91 | F10: 515 | G10: 679 | H10: 98 | I10: 120 | J10: 2404 | K10: 30310 | L10: 103745 | M10: 68336 | N10: 0.3222 | O10: 131 | P10: 0.2922 | Q10: 1.3 | R10: 201 | S10: 153 | T10: 1.2 | U10: 697 | V10: 35409 | W10: 913539.63 | X10: 851449.64 | Y10: 27029.51 | Z10: 886510.11 | AA10: 0.0296 | AB10: 1 | AC10: 0 | AD10: 1 | AE10: 893340.12 | AF10: 864325.06 | AG10: 0.0325 | AH10: 7245.31 | AI10: 8340 | AJ10: -0.1511 | AK10: 12950.2 | AL10: 13845.05 | AM10: -0.0691 | AN10: 0 | AO10: 0 | AP10: #DIV/0! | AQ10: 3 | AR10: 0 | AS10: 1 | AT10: 2251.1 | AU10: 0 | AV10: 2762.09 | AW10: 4033 | AX10: 395 | AY10: 0 | AZ10: 0 | BA10: 0 | BB10: 61.05 | BC10: 299 | BD10: 0 | BE10: 0 | BF10: 0 | BG10: 0 | BH10: 0 | BI10: 0 | BJ10: 5353.5 | BK10: 0 | BL10: 0 | BM10: 0 | BN10: 0 | BO10: 0 | BP10: 0 | BQ10: 15154.74 | BR10: 2251.1 | BS10: 61.05 | BT10: 0.0178 | BU10: 0.1461 | BV10: 0.5607 | BW10: 11875 | BX10: 1.2762 | BY10: 2500 | BZ10: 137 | CA10: 2637 | CB10: 2433 | CC10: 0.2221 | CD10: 0 | CF10: 0 | CG10: 0 | CH10: 113632.87 | CI10: 6805 | CJ10: 2 | CK10: 28
A11: 46082 | B11: {=INDEX('jiliarena_日报_底稿'!$A$3:$N$34,MATCH($A11,'jiliarena_日报_底稿'!$A$3:$A$34,0),MATCH(B$3,'jiliarena_日报_底稿'!$A$3:$N$3,0))} -> 1098 | C11: {=INDEX('jiliarena_日报_底稿'!$A$3:$N$34,MATCH($A11,'jiliarena_日报_底稿'!$A$3:$A$34,0),MATCH(C$3,'jiliarena_日报_底稿'!$A$3:$N$3,0))} -> 625 | D11: {=INDEX('jiliarena_日报_底稿'!$A$3:$N$34,MATCH($A11,'jiliarena_日报_底稿'!$A$3:$A$34,0),MATCH(D$3,'jiliarena_日报_底稿'!$A$3:$N$3,0))} -> 4268 | E11: 178 | F11: {=INDEX('jiliarena_日报_底稿'!$A$3:$N$34,MATCH($A11,'jiliarena_日报_底稿'!$A$3:$A$34,0),MATCH(F$3,'jiliarena_日报_底稿'!$A$3:$N$3,0))} -> 928 | G11: =SUMIFS('渠道充值成功率_底稿'!$F:$F,'渠道充值成功率_底稿'!$A:$A,A11) -> 1251 | H11: {=INDEX('jiliarena_日报_底稿'!$A$3:$N$34,MATCH($A11,'jiliarena_日报_底稿'!$A$3:$A$34,0),MATCH(H$3,'jiliarena_日报_底稿'!$A$3:$N$3,0))} -> 189 | I11: 247 | J11: {=INDEX('jiliarena_日报_底稿'!$A$3:$N$34,MATCH($A11,'jiliarena_日报_底稿'!$A$3:$A$34,0),MATCH(J$3,'jiliarena_日报_底稿'!$A$3:$N$3,0))} -> 3186 | K11: =SUMIFS('渠道充值成功率_底稿'!$J:$J,'渠道充值成功率_底稿'!$A:$A,$A11) -> 87527 | L11: {=INDEX('jiliarena_日报_底稿'!$A$3:$N$34,MATCH($A11,'jiliarena_日报_底稿'!$A$3:$A$34,0),MATCH(L$3,'jiliarena_日报_底稿'!$A$3:$N$3,0))} -> 186941 | M11: {=INDEX('jiliarena_日报_底稿'!$P$2:$DS$34,MATCH($A11,'jiliarena_日报_底稿'!$P$2:$P$34,0),MATCH($M$3,'jiliarena_日报_底稿'!$P$3:$DS$3,0))} -> 131003 | N11: =IF(C11="","",ROUND(C11/B11,4)) -> 0.5692 | O11: =IF(K11="","",ROUND(K11/C11,0)) -> 140 | P11: =IF(L11="","",ROUND(K11/L11,6)) -> 0.468207 | Q11: =IF(G11="","",ROUND(G11/F11,1)) -> 1.3 | R11: =IF(L11="","",ROUND(L11/F11,0)) -> 201 | S11: =IF(L11="","",ROUND(L11/G11,0)) -> 149 | T11: =IF(S11="","",ROUND(S11/O11,1)) -> 1.1 | U11: =IF(M11="","",ROUND(M11/H11,0)) -> 693 | V11: =IF(M11="","",L11-M11) -> 55938 | W11: =AB11+AE11+AH11+AK11+AN11+AQ11 -> 1794608.7 | X11: {=index('jiliarena_日报_底稿'!$P$2:$DS$34,match($A11,'jiliarena_日报_底稿'!$P$2:$P$34,0),match("电子有效投注",'jiliarena_日报_底稿'!$P$3:$DS$3,0))+index('jiliarena_日报_底稿'!$P$2:$DS$34,match($A11,'jiliarena_日报_底稿'!$P$2:$P$34,0),match("真人有效投注",'jiliarena_日报_底稿'!$P$3:$DS$3,0))+index('jiliarena_日报_底稿'!$P$2:$DS$34,match($A11,'jiliarena_日报_底稿'!$P$2:$P$34,0),match("彩票有效投注",'jiliarena_日报_底稿'!$P$3:$DS$3,0))+index('jiliarena_日报_底稿'!$P$2:$DS$34,match($A11,'jiliarena_日报_底稿'!$P$2:$P$34,0),match("棋牌有效投注",'jiliarena_日报_底稿'!$P$3:$DS$3,0))+index('jiliarena_日报_底稿'!$P$2:$DS$34,match($A11,'jiliarena_日报_底稿'!$P$2:$P$34,0),match("捕鱼有效投注",'jiliarena_日报_底稿'!$P$3:$DS$3,0))+index('jiliarena_日报_底稿'!$P$2:$DS$34,match($A11,'jiliarena_日报_底稿'!$P$2:$P$34,0),match("体育有效投注",'jiliarena_日报_底稿'!$P$3:$DS$3,0))+index('jiliarena_日报_底稿'!$P$2:$DS$34,match($A11,'jiliarena_日报_底稿'!$P$2:$P$34,0),match("盘口彩票有效投注",'jiliarena_日报_底稿'!$P$3:$DS$3,0))} -> 1674018.2 | Y11: =AB11+AE11+AH11+AK11+AN11+AQ11-AR11-AO11-AL11-AI11-AF11-AC11 -> 81864.325 | Z11: =AC11+AF11+AI11+AL11+AO11+AR11 -> 1712744.4 | AA11: =IFERROR(ROUND(1-(Z11/W11),6),"") -> 0.045617 | AB11: {=INDEX('jiliarena_日报_底稿'!$P$2:$DS$34,MATCH($A11,'jiliarena_日报_底稿'!$P$2:$P$34,0),MATCH(AB$3,'jiliarena_日报_底稿'!$P$3:$DS$3,0))} -> 450 | AC11: {=INDEX('jiliarena_日报_底稿'!$P$2:$DS$34,MATCH($A11,'jiliarena_日报_底稿'!$P$2:$P$34,0),MATCH(AC$3,'jiliarena_日报_底稿'!$P$3:$DS$3,0))} -> 386.15 | AD11: =IF(AC11="","",ROUND((1-(AC11/AB11)),6)) -> 0.141889 | AE11: {=INDEX('jiliarena_日报_底稿'!$P$2:$DS$34,MATCH($A11,'jiliarena_日报_底稿'!$P$2:$P$34,0),MATCH(AE$3,'jiliarena_日报_底稿'!$P$3:$DS$3,0))} -> 1772693 | AF11: {=INDEX('jiliarena_日报_底稿'!$P$2:$DS$34,MATCH($A11,'jiliarena_日报_底稿'!$P$2:$P$34,0),MATCH(AF$3,'jiliarena_日报_底稿'!$P$3:$DS$3,0))} -> 1694500.6 | AG11: =IF(AF11="","",ROUND((1-(AF11/AE11)),6)) -> 0.044109 | AH11: {=INDEX('jiliarena_日报_底稿'!$P$2:$DS$34,MATCH($A11,'jiliarena_日报_底稿'!$P$2:$P$34,0),MATCH(AH$3,'jiliarena_日报_底稿'!$P$3:$DS$3,0))} -> 8456.8 | AI11: {=INDEX('jiliarena_日报_底稿'!$P$2:$DS$34,MATCH($A11,'jiliarena_日报_底稿'!$P$2:$P$34,0),MATCH(AI$3,'jiliarena_日报_底稿'!$P$3:$DS$3,0))} -> 5555 | AJ11: =IF(AI11="","",ROUND((1-(AI11/AH11)),6)) -> 0.343132 | AK11: {=INDEX('jiliarena_日报_底稿'!$P$2:$DS$34,MATCH($A11,'jiliarena_日报_底稿'!$P$2:$P$34,0),MATCH(AK$3,'jiliarena_日报_底稿'!$P$3:$DS$3,0))} -> 13004.9 | AL11: {=INDEX('jiliarena_日报_底稿'!$P$2:$DS$34,MATCH($A11,'jiliarena_日报_底稿'!$P$2:$P$34,0),MATCH(AL$3,'jiliarena_日报_底稿'!$P$3:$DS$3,0))} -> 12302.7 | AM11: =IF(AL11="","",ROUND((1-(AL11/AK11)),6)) -> 0.053995 | AN11: {=INDEX('jiliarena_日报_底稿'!$P$2:$DS$34,MATCH($A11,'jiliarena_日报_底稿'!$P$2:$P$34,0),MATCH(AN$3,'jiliarena_日报_底稿'!$P$3:$DS$3,0))} -> 0 | AO11: {=INDEX('jiliarena_日报_底稿'!$P$2:$DS$34,MATCH($A11,'jiliarena_日报_底稿'!$P$2:$P$34,0),MATCH(AO$3,'jiliarena_日报_底稿'!$P$3:$DS$3,0))} -> 0 | AP11: =IF(AO11="","",ROUND((1-(AO11/AN11)),6)) -> #DIV/0! | AQ11: {=INDEX('jiliarena_日报_底稿'!$P$2:$DS$34,MATCH($A11,'jiliarena_日报_底稿'!$P$2:$P$34,0),MATCH(AQ$3,'jiliarena_日报_底稿'!$P$3:$DS$3,0))} -> 4 | AR11: {=INDEX('jiliarena_日报_底稿'!$P$2:$DS$34,MATCH($A11,'jiliarena_日报_底稿'!$P$2:$P$34,0),MATCH(AR$3,'jiliarena_日报_底稿'!$P$3:$DS$3,0))} -> 0 | AS11: =IF(AR11="","",ROUND((1-(AR11/AQ11)),6)) -> 1 | AT11: =SUMIFS('jiliarena_活动分析数据_底稿'!$K:$K,'jiliarena_活动分析数据_底稿'!$B:$B,$A11,'jiliarena_活动分析数据_底稿'!$L:$L,AT$3) -> 2895.46 | AU11: =SUMIFS('jiliarena_活动分析数据_底稿'!$K:$K,'jiliarena_活动分析数据_底稿'!$B:$B,$A11,'jiliarena_活动分析数据_底稿'!$L:$L,AU$3) -> 0 | AV11: =SUMIFS('jiliarena_活动分析数据_底稿'!$K:$K,'jiliarena_活动分析数据_底稿'!$B:$B,$A11,'jiliarena_活动分析数据_底稿'!$L:$L,AV$3) -> 734.22 | AW11: =SUMIFS('jiliarena_活动分析数据_底稿'!$K:$K,'jiliarena_活动分析数据_底稿'!$B:$B,$A11,'jiliarena_活动分析数据_底稿'!$L:$L,AW$3) -> 4988 | AX11: =SUMIFS('jiliarena_活动分析数据_底稿'!$K:$K,'jiliarena_活动分析数据_底稿'!$B:$B,$A11,'jiliarena_活动分析数据_底稿'!$L:$L,AX$3) -> 572 | AY11: =SUMIFS('jiliarena_活动分析数据_底稿'!$K:$K,'jiliarena_活动分析数据_底稿'!$B:$B,$A11,'jiliarena_活动分析数据_底稿'!$L:$L,AY$3) -> 0 | AZ11: =SUMIFS('jiliarena_活动分析数据_底稿'!$K:$K,'jiliarena_活动分析数据_底稿'!$B:$B,$A11,'jiliarena_活动分析数据_底稿'!$L:$L,AZ$3) -> 0 | BA11: =SUMIFS('jiliarena_活动分析数据_底稿'!$K:$K,'jiliarena_活动分析数据_底稿'!$B:$B,$A11,'jiliarena_活动分析数据_底稿'!$L:$L,BA$3) -> 0 | ... BP11: =SUMIFS('jiliarena_活动分析数据_底稿'!$K:$K,'jiliarena_活动分析数据_底稿'!$B:$B,$A11,'jiliarena_活动分析数据_底稿'!$L:$L,BP$3) -> 0 | BQ11: =SUM(AT11:BP11) -> 32032.43 | BR11: =AT11 -> 2895.46 | BS11: =BB11 -> 381.75 | BT11: =iferror(IF(BQ11="","",ROUND(BQ11/X11,6)),"") -> 0.019135 | BU11: =iferror(BQ11/L11,"") -> 0.17135048 | BV11: =iferror(BQ11/Y11,"") -> 0.3912868 | BW11: =IF(BQ11="","",Y11-BQ11) -> 49831.895 | BX11: =iferror(BQ11/BW11,"") -> 0.64280979 | BY11: =L11*$BY$1 -> 4505.2781 | BZ11: =M11*$BZ$1 -> 262.006 | CA11: =BY11+BZ11 -> 4767.2841 | CB11: =IF(Y11="","",ROUND(Y11*9%,0)) -> 7368 | CC11: =iferror(CA11/BW11,"") -> 0.095667325 | CD11: {=index('jiliarena_日报_底稿'!$P$3:$DS$34,match(A11,'jiliarena_日报_底稿'!$P$3:$P$34,0),match("综合性分红",'jiliarena_日报_底稿'!$P$3:$DS$3,0))} -> 0 | CF11: {=INDEX('jiliarena_日报_底稿'!$P$2:$DS$34,MATCH($A11,'jiliarena_日报_底稿'!$P$2:$P$34,0),MATCH(CF$3,'jiliarena_日报_底稿'!$P$3:$DS$3,0))} -> 0 | CG11: {=-INDEX('jiliarena_日报_底稿'!$P$2:$DS$34,MATCH($A11,'jiliarena_日报_底稿'!$P$2:$P$34,0),MATCH(CG$3,'jiliarena_日报_底稿'!$P$3:$DS$3,0))} -> 0 | CH11: {=INDEX('jiliarena_日报_底稿'!$P$2:$DS$34,MATCH($A11,'jiliarena_日报_底稿'!$P$2:$P$34,0),MATCH(CH$3,'jiliarena_日报_底稿'!$P$3:$DS$3,0))} -> 119399.8 | CI11: =IF(CA11="","",BW11-CA11-CD11-CB11) -> 37696.611 | CJ11: =IFERROR(month(A11),"") -> 3 | CK11: =IFERROR(DAY(A11),"") -> 1
A12: SUB total | B12: =SUM(B5:B11) -> 4833 | C12: =SUM(C5:C11) -> 1690 | D12: =SUM(D5:D11) -> 24785 | E12: =SUM(E5:E11) -> 445 | F12: =SUM(F5:F11) -> 3630 | G12: =SUM(G5:G11) -> 5017 | H12: =SUM(H5:H11) -> 773 | I12: =SUM(I5:I11) -> 1410 | ... M12: =SUM(M5:M11) -> 584868 | N12: =IF(C12="","",ROUND(C12/B12,4)) -> 0.3497 | O12: =IF(K12="","",ROUND(K12/C12,0)) -> 137 | P12: =IF(L12="","",ROUND(K12/L12,6)) -> 0.300583 | Q12: =IF(G12="","",ROUND(G12/F12,1)) -> 1.4 | R12: =IF(L12="","",ROUND(L12/F12,0)) -> 212 | S12: =IF(L12="","",ROUND(L12/G12,0)) -> 154 | T12: =IF(S12="","",ROUND(S12/O12,1)) -> 1.1 | U12: =IF(M12="","",ROUND(M12/H12,0)) -> 757 | V12: =IF(M12="","",L12-M12) -> 185918 | W12: =SUM(W5:W11) -> 7152126.1 | X12: =SUM(X5:X11) -> 6705516.3 | Y12: =SUM(Y5:Y11) -> 237737.79 | Z12: =SUM(Z5:Z11) -> 6914388.3 | AA12: =IFERROR(ROUND(1-(Z12/W12),6),"") -> 0.03324 | AB12: =SUM(AB5:AB11) -> 512 | AC12: =SUM(AC5:AC11) -> 386.15 | AD12: =IF(AC12="","",ROUND((1-(AC12/AB12)),6)) -> 0.245801 | AE12: =SUM(AE5:AE11) -> 6916771.2 | AF12: =SUM(AF5:AF11) -> 6685907.3 | AG12: =IF(AF12="","",ROUND((1-(AF12/AE12)),6)) -> 0.033377 | AH12: =SUM(AH5:AH11) -> 70550.51 | AI12: =SUM(AI5:AI11) -> 65143.54 | AJ12: =IF(AI12="","",ROUND((1-(AI12/AH12)),6)) -> 0.07664 | AK12: =SUM(AK5:AK11) -> 160657.28 | AL12: =SUM(AL5:AL11) -> 159473.83 | AM12: =IF(AL12="","",ROUND((1-(AL12/AK12)),6)) -> 0.007366 | AN12: =SUM(AN5:AN11) -> 3613.1 | AO12: =SUM(AO5:AO11) -> 2397.49 | AP12: =IF(AO12="","",ROUND((1-(AO12/AN12)),6)) -> 0.336445 | AQ12: =SUM(AQ5:AQ11) -> 22 | AR12: =SUM(AR5:AR11) -> 1080 | AS12: =IF(AR12="","",ROUND((1-(AR12/AQ12)),6)) -> -48.090909 | AT12: =SUM(AT5:AT11) -> 22560.01 | AU12: =SUM(AU5:AU11) -> 0 | AV12: =SUM(AV5:AV11) -> 19651.39 | AW12: =SUM(AW5:AW11) -> 29892 | AX12: =SUM(AX5:AX11) -> 3299 | AY12: =SUM(AY5:AY11) -> 0 | AZ12: =SUM(AZ5:AZ11) -> 0 | BA12: =SUM(BA5:BA11) -> 0 | ... BS12: =SUM(BS5:BS11) -> 1956.86 | BT12: =iferror(IF(BQ12="","",ROUND(BQ12/X12,6)),"") -> 0.01892 | BU12: =iferror(BQ12/L12,"") -> 0.16459985 | BV12: =iferror(BQ12/Y12,"") -> 0.53366048 | BW12: =IF(BQ12="","",Y12-BQ12) -> 110866.52 | BX12: =iferror(BQ12/BW12,"") -> 1.1443604 | BY12: =L12*$BY$1 -> 18575.943 | BZ12: =M12*$BZ$1 -> 1169.736 | CA12: =BY12+BZ12 -> 19745.679 | CB12: =IF(Y12="","",ROUND(Y12*9%,0)) -> 21396 | CC12: =iferror(CA12/BW12,"") -> 0.17810316 | CD12: =SUM(CD5:CD11) -> 0 | CE12: =SUM(CE5:CE11) -> 0 | CF12: =SUM(CF5:CF11) -> 0 | CG12: =SUM(CG5:CG11) -> 0 | CH12: =SUM(CH5:CH11) -> 701739.9 | CI12: =IF(CA12="","",BW12-CA12-CD12-CB12) -> 69724.846 | CJ12: =IFERROR(month(A12),"") | CK12: =IFERROR(DAY(A12),"")
A13: =A11+1 -> 46083 | B13: {=INDEX('jiliarena_日报_底稿'!$A$3:$N$34,MATCH($A13,'jiliarena_日报_底稿'!$A$3:$A$34,0),MATCH(B$3,'jiliarena_日报_底稿'!$A$3:$N$3,0))} -> 197 | C13: {=INDEX('jiliarena_日报_底稿'!$A$3:$N$34,MATCH($A13,'jiliarena_日报_底稿'!$A$3:$A$34,0),MATCH(C$3,'jiliarena_日报_底稿'!$A$3:$N$3,0))} -> 140 | D13: {=INDEX('jiliarena_日报_底稿'!$A$3:$N$34,MATCH($A13,'jiliarena_日报_底稿'!$A$3:$A$34,0),MATCH(D$3,'jiliarena_日报_底稿'!$A$3:$N$3,0))} -> 3109 | E13: 23 | F13: {=INDEX('jiliarena_日报_底稿'!$A$3:$N$34,MATCH($A13,'jiliarena_日报_底稿'!$A$3:$A$34,0),MATCH(F$3,'jiliarena_日报_底稿'!$A$3:$N$3,0))} -> 423 | G13: =SUMIFS('渠道充值成功率_底稿'!$F:$F,'渠道充值成功率_底稿'!$A:$A,A13) -> 599 | H13: {=INDEX('jiliarena_日报_底稿'!$A$3:$N$34,MATCH($A13,'jiliarena_日报_底稿'!$A$3:$A$34,0),MATCH(H$3,'jiliarena_日报_底稿'!$A$3:$N$3,0))} -> 96 | I13: 121 | J13: {=INDEX('jiliarena_日报_底稿'!$A$3:$N$34,MATCH($A13,'jiliarena_日报_底稿'!$A$3:$A$34,0),MATCH(J$3,'jiliarena_日报_底稿'!$A$3:$N$3,0))} -> 2227 | K13: =SUMIFS('渠道充值成功率_底稿'!$J:$J,'渠道充值成功率_底稿'!$A:$A,$A13) -> 19695 | L13: {=INDEX('jiliarena_日报_底稿'!$A$3:$N$34,MATCH($A13,'jiliarena_日报_底稿'!$A$3:$A$34,0),MATCH(L$3,'jiliarena_日报_底稿'!$A$3:$N$3,0))} -> 90451 | M13: {=INDEX('jiliarena_日报_底稿'!$P$2:$DS$34,MATCH($A13,'jiliarena_日报_底稿'!$P$2:$P$34,0),MATCH($M$3,'jiliarena_日报_底稿'!$P$3:$DS$3,0))} -> 66903 | N13: =IF(C13="","",ROUND(C13/B13,4)) -> 0.7107 | O13: =IF(K13="","",ROUND(K13/C13,0)) -> 141 | P13: =IF(L13="","",ROUND(K13/L13,6)) -> 0.217742 | Q13: =IF(G13="","",ROUND(G13/F13,1)) -> 1.4 | R13: =IF(L13="","",ROUND(L13/F13,0)) -> 214 | S13: =IF(L13="","",ROUND(L13/G13,0)) -> 151 | T13: =IF(S13="","",ROUND(S13/O13,1)) -> 1.1 | U13: =IF(M13="","",ROUND(M13/H13,0)) -> 697 | V13: =IF(M13="","",L13-M13) -> 23548 | W13: =AB13+AE13+AH13+AK13+AN13+AQ13 -> 889864.08 | X13: {=index('jiliarena_日报_底稿'!$P$2:$DS$34,match($A13,'jiliarena_日报_底稿'!$P$2:$P$34,0),match("电子有效投注",'jiliarena_日报_底稿'!$P$3:$DS$3,0))+index('jiliarena_日报_底稿'!$P$2:$DS$34,match($A13,'jiliarena_日报_底稿'!$P$2:$P$34,0),match("真人有效投注",'jiliarena_日报_底稿'!$P$3:$DS$3,0))+index('jiliarena_日报_底稿'!$P$2:$DS$34,match($A13,'jiliarena_日报_底稿'!$P$2:$P$34,0),match("彩票有效投注",'jiliarena_日报_底稿'!$P$3:$DS$3,0))+index('jiliarena_日报_底稿'!$P$2:$DS$34,match($A13,'jiliarena_日报_底稿'!$P$2:$P$34,0),match("棋牌有效投注",'jiliarena_日报_底稿'!$P$3:$DS$3,0))+index('jiliarena_日报_底稿'!$P$2:$DS$34,match($A13,'jiliarena_日报_底稿'!$P$2:$P$34,0),match("捕鱼有效投注",'jiliarena_日报_底稿'!$P$3:$DS$3,0))+index('jiliarena_日报_底稿'!$P$2:$DS$34,match($A13,'jiliarena_日报_底稿'!$P$2:$P$34,0),match("体育有效投注",'jiliarena_日报_底稿'!$P$3:$DS$3,0))+index('jiliarena_日报_底稿'!$P$2:$DS$34,match($A13,'jiliarena_日报_底稿'!$P$2:$P$34,0),match("盘口彩票有效投注",'jiliarena_日报_底稿'!$P$3:$DS$3,0))} -> 830058.92 | Y13: =AB13+AE13+AH13+AK13+AN13+AQ13-AR13-AO13-AL13-AI13-AF13-AC13 -> 26535.125 | Z13: =AC13+AF13+AI13+AL13+AO13+AR13 -> 863328.95 | AA13: =IFERROR(ROUND(1-(Z13/W13),6),"") -> 0.029819 | AB13: {=INDEX('jiliarena_日报_底稿'!$P$2:$DS$34,MATCH($A13,'jiliarena_日报_底稿'!$P$2:$P$34,0),MATCH(AB$3,'jiliarena_日报_底稿'!$P$3:$DS$3,0))} -> 0 | AC13: {=INDEX('jiliarena_日报_底稿'!$P$2:$DS$34,MATCH($A13,'jiliarena_日报_底稿'!$P$2:$P$34,0),MATCH(AC$3,'jiliarena_日报_底稿'!$P$3:$DS$3,0))} -> 0 | AD13: =IF(AC13="","",ROUND((1-(AC13/AB13)),6)) -> #DIV/0! | AE13: {=INDEX('jiliarena_日报_底稿'!$P$2:$DS$34,MATCH($A13,'jiliarena_日报_底稿'!$P$2:$P$34,0),MATCH(AE$3,'jiliarena_日报_底稿'!$P$3:$DS$3,0))} -> 853219.28 | AF13: {=INDEX('jiliarena_日报_底稿'!$P$2:$DS$34,MATCH($A13,'jiliarena_日报_底稿'!$P$2:$P$34,0),MATCH(AF$3,'jiliarena_日报_底稿'!$P$3:$DS$3,0))} -> 821850.07 | AG13: =IF(AF13="","",ROUND((1-(AF13/AE13)),6)) -> 0.036766 | AH13: {=INDEX('jiliarena_日报_底稿'!$P$2:$DS$34,MATCH($A13,'jiliarena_日报_底稿'!$P$2:$P$34,0),MATCH(AH$3,'jiliarena_日报_底稿'!$P$3:$DS$3,0))} -> 931.05 | AI13: {=INDEX('jiliarena_日报_底稿'!$P$2:$DS$34,MATCH($A13,'jiliarena_日报_底稿'!$P$2:$P$34,0),MATCH(AI$3,'jiliarena_日报_底稿'!$P$3:$DS$3,0))} -> 717.6 | AJ13: =IF(AI13="","",ROUND((1-(AI13/AH13)),6)) -> 0.229257 | AK13: {=INDEX('jiliarena_日报_底稿'!$P$2:$DS$34,MATCH($A13,'jiliarena_日报_底稿'!$P$2:$P$34,0),MATCH(AK$3,'jiliarena_日报_底稿'!$P$3:$DS$3,0))} -> 35624.75 | AL13: {=INDEX('jiliarena_日报_底稿'!$P$2:$DS$34,MATCH($A13,'jiliarena_日报_底稿'!$P$2:$P$34,0),MATCH(AL$3,'jiliarena_日报_底稿'!$P$3:$DS$3,0))} -> 40761.28 | AM13: =IF(AL13="","",ROUND((1-(AL13/AK13)),6)) -> -0.144184 | AN13: {=INDEX('jiliarena_日报_底稿'!$P$2:$DS$34,MATCH($A13,'jiliarena_日报_底稿'!$P$2:$P$34,0),MATCH(AN$3,'jiliarena_日报_底稿'!$P$3:$DS$3,0))} -> 85 | AO13: {=INDEX('jiliarena_日报_底稿'!$P$2:$DS$34,MATCH($A13,'jiliarena_日报_底稿'!$P$2:$P$34,0),MATCH(AO$3,'jiliarena_日报_底稿'!$P$3:$DS$3,0))} -> 0 | AP13: =IF(AO13="","",ROUND((1-(AO13/AN13)),6)) -> 1 | AQ13: {=INDEX('jiliarena_日报_底稿'!$P$2:$DS$34,MATCH($A13,'jiliarena_日报_底稿'!$P$2:$P$34,0),MATCH(AQ$3,'jiliarena_日报_底稿'!$P$3:$DS$3,0))} -> 4 | AR13: {=INDEX('jiliarena_日报_底稿'!$P$2:$DS$34,MATCH($A13,'jiliarena_日报_底稿'!$P$2:$P$34,0),MATCH(AR$3,'jiliarena_日报_底稿'!$P$3:$DS$3,0))} -> 0 | AS13: =IF(AR13="","",ROUND((1-(AR13/AQ13)),6)) -> 1 | AT13: =SUMIFS('jiliarena_活动分析数据_底稿'!$K:$K,'jiliarena_活动分析数据_底稿'!$B:$B,$A13,'jiliarena_活动分析数据_底稿'!$L:$L,AT$3) -> 4082.18 | AU13: =SUMIFS('jiliarena_活动分析数据_底稿'!$K:$K,'jiliarena_活动分析数据_底稿'!$B:$B,$A13,'jiliarena_活动分析数据_底稿'!$L:$L,AU$3) -> 0 | AV13: =SUMIFS('jiliarena_活动分析数据_底稿'!$K:$K,'jiliarena_活动分析数据_底稿'!$B:$B,$A13,'jiliarena_活动分析数据_底稿'!$L:$L,AV$3) -> 523.26 | AW13: =SUMIFS('jiliarena_活动分析数据_底稿'!$K:$K,'jiliarena_活动分析数据_底稿'!$B:$B,$A13,'jiliarena_活动分析数据_底稿'!$L:$L,AW$3) -> 4192 | AX13: =SUMIFS('jiliarena_活动分析数据_底稿'!$K:$K,'jiliarena_活动分析数据_底稿'!$B:$B,$A13,'jiliarena_活动分析数据_底稿'!$L:$L,AX$3) -> 276 | AY13: =SUMIFS('jiliarena_活动分析数据_底稿'!$K:$K,'jiliarena_活动分析数据_底稿'!$B:$B,$A13,'jiliarena_活动分析数据_底稿'!$L:$L,AY$3) -> 0 | AZ13: =SUMIFS('jiliarena_活动分析数据_底稿'!$K:$K,'jiliarena_活动分析数据_底稿'!$B:$B,$A13,'jiliarena_活动分析数据_底稿'!$L:$L,AZ$3) -> 0 | BA13: =SUMIFS('jiliarena_活动分析数据_底稿'!$K:$K,'jiliarena_活动分析数据_底稿'!$B:$B,$A13,'jiliarena_活动分析数据_底稿'!$L:$L,BA$3) -> 0 | ... BP13: =SUMIFS('jiliarena_活动分析数据_底稿'!$K:$K,'jiliarena_活动分析数据_底稿'!$B:$B,$A13,'jiliarena_活动分析数据_底稿'!$L:$L,BP$3) -> 0 | BQ13: =SUM(AT13:BP13) -> 13886.28 | BR13: =AT13 -> 4082.18 | BS13: =BB13 -> 178.84 | BT13: =iferror(IF(BQ13="","",ROUND(BQ13/X13,6)),"") -> 0.016729 | BU13: =iferror(BQ13/L13,"") -> 0.15352268 | BV13: =iferror(BQ13/Y13,"") -> 0.52331692 | BW13: =IF(BQ13="","",Y13-BQ13) -> 12648.845 | BX13: =iferror(BQ13/BW13,"") -> 1.0978299 | BY13: =L13*$BY$1 -> 2179.8691 | BZ13: =M13*$BZ$1 -> 133.806 | CA13: =BY13+BZ13 -> 2313.6751 | CB13: =IF(Y13="","",ROUND(Y13*9%,0)) -> 2388 | CC13: =iferror(CA13/BW13,"") -> 0.18291592 | CD13: {=index('jiliarena_日报_底稿'!$P$3:$DS$34,match(A13,'jiliarena_日报_底稿'!$P$3:$P$34,0),match("综合性分红",'jiliarena_日报_底稿'!$P$3:$DS$3,0))} -> 0 | CF13: {=INDEX('jiliarena_日报_底稿'!$P$2:$DS$34,MATCH($A13,'jiliarena_日报_底稿'!$P$2:$P$34,0),MATCH(CF$3,'jiliarena_日报_底稿'!$P$3:$DS$3,0))} -> 0 | CG13: {=-INDEX('jiliarena_日报_底稿'!$P$2:$DS$34,MATCH($A13,'jiliarena_日报_底稿'!$P$2:$P$34,0),MATCH(CG$3,'jiliarena_日报_底稿'!$P$3:$DS$3,0))} -> 0 | CH13: {=INDEX('jiliarena_日报_底稿'!$P$2:$DS$34,MATCH($A13,'jiliarena_日报_底稿'!$P$2:$P$34,0),MATCH(CH$3,'jiliarena_日报_底稿'!$P$3:$DS$3,0))} -> 120153.84 | CI13: =IF(CA13="","",BW13-CA13-CD13-CB13) -> 7947.1699 | CJ13: =IFERROR(month(A13),"") -> 3 | CK13: =IFERROR(DAY(A13),"") -> 2
