Workbook

Sheet 渠道充值成功率-统整
B1: Date | C1: jiliarena | D1: GCash | E1: QRPH | F1: GCashQR | G1: Maya | H1: GRABPAY | I1: Online Banking | J1: USDT | K1: GOTYME | L1: GCASHPAY
A2: =B2 -> 46054 | B2: 46054 | C2: 申请笔数 | D2: =SUMIFS('渠道充值成功率_底稿'!$C:$C,'渠道充值成功率_底稿'!$A:$A,$A2,'渠道充值成功率_底稿'!$B:$B,D$1) -> 0 | E2: =SUMIFS('渠道充值成功率_底稿'!$C:$C,'渠道充值成功率_底稿'!$A:$A,$A2,'渠道充值成功率_底稿'!$B:$B,E$1) -> 0 | F2: =SUMIFS('渠道充值成功率_底稿'!$C:$C,'渠道充值成功率_底稿'!$A:$A,$A2,'渠道充值成功率_底稿'!$B:$B,F$1) -> 0 | G2: =SUMIFS('渠道充值成功率_底稿'!$C:$C,'渠道充值成功率_底稿'!$A:$A,$A2,'渠道充值成功率_底稿'!$B:$B,G$1) -> 0 | H2: =SUMIFS('渠道充值成功率_底稿'!$C:$C,'渠道充值成功率_底稿'!$A:$A,$A2,'渠道充值成功率_底稿'!$B:$B,H$1) -> 0 | I2: =SUMIFS('渠道充值成功率_底稿'!$C:$C,'渠道充值成功率_底稿'!$A:$A,$A2,'渠道充值成功率_底稿'!$B:$B,I$1) -> 0 | J2: =SUMIFS('渠道充值成功率_底稿'!$C:$C,'渠道充值成功率_底稿'!$A:$A,$A2,'渠道充值成功率_底稿'!$B:$B,J$1) -> 0 | K2: =SUMIFS('渠道充值成功率_底稿'!$C:$C,'渠道充值成功率_底稿'!$A:$A,$A2,'渠道充值成功率_底稿'!$B:$B,K$1) -> 0 | L2: =SUMIFS('渠道充值成功率_底稿'!$C:$C,'渠道充值成功率_底稿'!$A:$A,$A2,'渠道充值成功率_底稿'!$B:$B,L$1) -> 0
A3: =B2 -> 46054 | C3: 到账笔数 | D3: =SUMIFS('渠道充值成功率_底稿'!$F:$F,'渠道充值成功率_底稿'!$A:$A,$A3,'渠道充值成功率_底稿'!$B:$B,D$1) -> 0 | E3: =SUMIFS('渠道充值成功率_底稿'!$F:$F,'渠道充值成功率_底稿'!$A:$A,$A3,'渠道充值成功率_底稿'!$B:$B,E$1) -> 0 | F3: =SUMIFS('渠道充值成功率_底稿'!$F:$F,'渠道充值成功率_底稿'!$A:$A,$A3,'渠道充值成功率_底稿'!$B:$B,F$1) -> 0 | G3: =SUMIFS('渠道充值成功率_底稿'!$F:$F,'渠道充值成功率_底稿'!$A:$A,$A3,'渠道充值成功率_底稿'!$B:$B,G$1) -> 0 | H3: =SUMIFS('渠道充值成功率_底稿'!$F:$F,'渠道充值成功率_底稿'!$A:$A,$A3,'渠道充值成功率_底稿'!$B:$B,H$1) -> 0 | I3: =SUMIFS('渠道充值成功率_底稿'!$F:$F,'渠道充值成功率_底稿'!$A:$A,$A3,'渠道充值成功率_底稿'!$B:$B,I$1) -> 0 | J3: =SUMIFS('渠道充值成功率_底稿'!$F:$F,'渠道充值成功率_底稿'!$A:$A,$A3,'渠道充值成功率_底稿'!$B:$B,J$1) -> 0 | K3: =SUMIFS('渠道充值成功率_底稿'!$F:$F,'渠道充值成功率_底稿'!$A:$A,$A3,'渠道充值成功率_底稿'!$B:$B,K$1) -> 0 | L3: =SUMIFS('渠道充值成功率_底稿'!$F:$F,'渠道充值成功率_底稿'!$A:$A,$A3,'渠道充值成功率_底稿'!$B:$B,L$1) -> 0
A4: =B2 -> 46054 | C4: 笔数成功率 | D4: =IFERROR(ROUND(D3/D2,6),"0") -> 0 | E4: =IFERROR(ROUND(E3/E2,6),"0") -> 0 | F4: =IFERROR(ROUND(F3/F2,6),"0") -> 0 | G4: =IFERROR(ROUND(G3/G2,6),"0") -> 0 | H4: =IFERROR(ROUND(H3/H2,6),"0") -> 0 | I4: =IFERROR(ROUND(I3/I2,6),"0") -> 0 | J4: =IFERROR(ROUND(J3/J2,6),"0") -> 0 | K4: =IFERROR(ROUND(K3/K2,6),"0") -> 0 | L4: =IFERROR(ROUND(L3/L2,6),"0") -> 0
A5: =B2 -> 46054 | C5: 申请金额 | D5: =SUMIFS('渠道充值成功率_底稿'!$D:$D,'渠道充值成功率_底稿'!$A:$A,$A6,'渠道充值成功率_底稿'!$B:$B,D$1) -> 0 | E5: =SUMIFS('渠道充值成功率_底稿'!$D:$D,'渠道充值成功率_底稿'!$A:$A,$A5,'渠道充值成功率_底稿'!$B:$B,E$1) -> 0 | F5: =SUMIFS('渠道充值成功率_底稿'!$D:$D,'渠道充值成功率_底稿'!$A:$A,$A5,'渠道充值成功率_底稿'!$B:$B,F$1) -> 0 | G5: =SUMIFS('渠道充值成功率_底稿'!$D:$D,'渠道充值成功率_底稿'!$A:$A,$A5,'渠道充值成功率_底稿'!$B:$B,G$1) -> 0 | H5: =SUMIFS('渠道充值成功率_底稿'!$D:$D,'渠道充值成功率_底稿'!$A:$A,$A5,'渠道充值成功率_底稿'!$B:$B,H$1) -> 0 | I5: =SUMIFS('渠道充值成功率_底稿'!$D:$D,'渠道充值成功率_底稿'!$A:$A,$A5,'渠道充值成功率_底稿'!$B:$B,I$1) -> 0 | J5: =SUMIFS('渠道充值成功率_底稿'!$D:$D,'渠道充值成功率_底稿'!$A:$A,$A5,'渠道充值成功率_底稿'!$B:$B,J$1) -> 0 | K5: =SUMIFS('渠道充值成功率_底稿'!$D:$D,'渠道充值成功率_底稿'!$A:$A,$A5,'渠道充值成功率_底稿'!$B:$B,K$1) -> 0 | L5: =SUMIFS('渠道充值成功率_底稿'!$D:$D,'渠道充值成功率_底稿'!$A:$A,$A5,'渠道充值成功率_底稿'!$B:$B,L$1) -> 0
A6: =B2 -> 46054 | C6: 到账金额 | D6: =SUMIFS('渠道充值成功率_底稿'!$G:$G,'渠道充值成功率_底稿'!$A:$A,$A7,'渠道充值成功率_底稿'!$B:$B,D$1) -> 0 | E6: =SUMIFS('渠道充值成功率_底稿'!$G:$G,'渠道充值成功率_底稿'!$A:$A,$A6,'渠道充值成功率_底稿'!$B:$B,E$1) -> 0 | F6: =SUMIFS('渠道充值成功率_底稿'!$G:$G,'渠道充值成功率_底稿'!$A:$A,$A6,'渠道充值成功率_底稿'!$B:$B,F$1) -> 0 | G6: =SUMIFS('渠道充值成功率_底稿'!$G:$G,'渠道充值成功率_底稿'!$A:$A,$A6,'渠道充值成功率_底稿'!$B:$B,G$1) -> 0 | H6: =SUMIFS('渠道充值成功率_底稿'!$G:$G,'渠道充值成功率_底稿'!$A:$A,$A6,'渠道充值成功率_底稿'!$B:$B,H$1) -> 0 | I6: =SUMIFS('渠道充值成功率_底稿'!$G:$G,'渠道充值成功率_底稿'!$A:$A,$A6,'渠道充值成功率_底稿'!$B:$B,I$1) -> 0 | J6: =SUMIFS('渠道充值成功率_底稿'!$G:$G,'渠道充值成功率_底稿'!$A:$A,$A6,'渠道充值成功率_底稿'!$B:$B,J$1) -> 0 | K6: =SUMIFS('渠道充值成功率_底稿'!$G:$G,'渠道充值成功率_底稿'!$A:$A,$A6,'渠道充值成功率_底稿'!$B:$B,K$1) -> 0 | L6: =SUMIFS('渠道充值成功率_底稿'!$G:$G,'渠道充值成功率_底稿'!$A:$A,$A6,'渠道充值成功率_底稿'!$B:$B,L$1) -> 0
A7: =B2 -> 46054 | C7: 金额成功率 | D7: =IFERROR(ROUND(D6/D5,6),"0") -> 0 | E7: =IFERROR(ROUND(E6/E5,6),"0") -> 0 | F7: =IFERROR(ROUND(F6/F5,6),"0") -> 0 | G7: =IFERROR(ROUND(G6/G5,6),"0") -> 0 | H7: =IFERROR(ROUND(H6/H5,6),"0") -> 0 | I7: =IFERROR(ROUND(I6/I5,6),"0") -> 0 | J7: =IFERROR(ROUND(J6/J5,6),"0") -> 0 | K7: =IFERROR(ROUND(K6/K5,6),"0") -> 0 | L7: =IFERROR(ROUND(L6/L5,6),"0") -> 0
A8: =B8 -> 46055 | B8: =B2+1 -> 46055 | C8: 申请笔数 | D8: =SUMIFS('渠道充值成功率_底稿'!$C:$C,'渠道充值成功率_底稿'!$A:$A,$A8,'渠道充值成功率_底稿'!$B:$B,D$1) -> 0 | E8: =SUMIFS('渠道充值成功率_底稿'!$C:$C,'渠道充值成功率_底稿'!$A:$A,$A8,'渠道充值成功率_底稿'!$B:$B,E$1) -> 0 | F8: =SUMIFS('渠道充值成功率_底稿'!$C:$C,'渠道充值成功率_底稿'!$A:$A,$A8,'渠道充值成功率_底稿'!$B:$B,F$1) -> 0 | G8: =SUMIFS('渠道充值成功率_底稿'!$C:$C,'渠道充值成功率_底稿'!$A:$A,$A8,'渠道充值成功率_底稿'!$B:$B,G$1) -> 0 | H8: =SUMIFS('渠道充值成功率_底稿'!$C:$C,'渠道充值成功率_底稿'!$A:$A,$A8,'渠道充值成功率_底稿'!$B:$B,H$1) -> 0 | I8: =SUMIFS('渠道充值成功率_底稿'!$C:$C,'渠道充值成功率_底稿'!$A:$A,$A8,'渠道充值成功率_底稿'!$B:$B,I$1) -> 0 | J8: =SUMIFS('渠道充值成功率_底稿'!$C:$C,'渠道充值成功率_底稿'!$A:$A,$A8,'渠道充值成功率_底稿'!$B:$B,J$1) -> 0 | K8: =SUMIFS('渠道充值成功率_底稿'!$C:$C,'渠道充值成功率_底稿'!$A:$A,$A8,'渠道充值成功率_底稿'!$B:$B,K$1) -> 0 | L8: =SUMIFS('渠道充值成功率_底稿'!$C:$C,'渠道充值成功率_底稿'!$A:$A,$A8,'渠道充值成功率_底稿'!$B:$B,L$1) -> 0
A9: =B8 -> 46055 | C9: 到账笔数 | D9: =SUMIFS('渠道充值成功率_底稿'!$F:$F,'渠道充值成功率_底稿'!$A:$A,$A9,'渠道充值成功率_底稿'!$B:$B,D$1) -> 0 | E9: =SUMIFS('渠道充值成功率_底稿'!$F:$F,'渠道充值成功率_底稿'!$A:$A,$A9,'渠道充值成功率_底稿'!$B:$B,E$1) -> 0 | F9: =SUMIFS('渠道充值成功率_底稿'!$F:$F,'渠道充值成功率_底稿'!$A:$A,$A9,'渠道充值成功率_底稿'!$B:$B,F$1) -> 0 | G9: =SUMIFS('渠道充值成功率_底稿'!$F:$F,'渠道充值成功率_底稿'!$A:$A,$A9,'渠道充值成功率_底稿'!$B:$B,G$1) -> 0 | H9: =SUMIFS('渠道充值成功率_底稿'!$F:$F,'渠道充值成功率_底稿'!$A:$A,$A9,'渠道充值成功率_底稿'!$B:$B,H$1) -> 0 | I9: =SUMIFS('渠道充值成功率_底稿'!$F:$F,'渠道充值成功率_底稿'!$A:$A,$A9,'渠道充值成功率_底稿'!$B:$B,I$1) -> 0 | J9: =SUMIFS('渠道充值成功率_底稿'!$F:$F,'渠道充值成功率_底稿'!$A:$A,$A9,'渠道充值成功率_底稿'!$B:$B,J$1) -> 0 | K9: =SUMIFS('渠道充值成功率_底稿'!$F:$F,'渠道充值成功率_底稿'!$A:$A,$A9,'渠道充值成功率_底稿'!$B:$B,K$1) -> 0 | L9: =SUMIFS('渠道充值成功率_底稿'!$F:$F,'渠道充值成功率_底稿'!$A:$A,$A9,'渠道充值成功率_底稿'!$B:$B,L$1) -> 0
A10: =B8 -> 46055 | C10: 笔数成功率 | D10: =IFERROR(ROUND(D9/D8,6),"0") -> 0 | E10: =IFERROR(ROUND(E9/E8,6),"0") -> 0 | F10: =IFERROR(ROUND(F9/F8,6),"0") -> 0 | G10: =IFERROR(ROUND(G9/G8,6),"0") -> 0 | H10: =IFERROR(ROUND(H9/H8,6),"0") -> 0 | I10: =IFERROR(ROUND(I9/I8,6),"0") -> 0 | J10: =IFERROR(ROUND(J9/J8,6),"0") -> 0 | K10: =IFERROR(ROUND(K9/K8,6),"0") -> 0 | L10: =IFERROR(ROUND(L9/L8,6),"0") -> 0
A11: =B8 -> 46055 | C11: 申请金额 | D11: =SUMIFS('渠道充值成功率_底稿'!$D:$D,'渠道充值成功率_底稿'!$A:$A,$A12,'渠道充值成功率_底稿'!$B:$B,D$1) -> 0 | E11: =SUMIFS('渠道充值成功率_底稿'!$D:$D,'渠道充值成功率_底稿'!$A:$A,$A11,'渠道充值成功率_底稿'!$B:$B,E$1) -> 0 | F11: =SUMIFS('渠道充值成功率_底稿'!$D:$D,'渠道充值成功率_底稿'!$A:$A,$A11,'渠道充值成功率_底稿'!$B:$B,F$1) -> 0 | G11: =SUMIFS('渠道充值成功率_底稿'!$D:$D,'渠道充值成功率_底稿'!$A:$A,$A11,'渠道充值成功率_底稿'!$B:$B,G$1) -> 0 | H11: =SUMIFS('渠道充值成功率_底稿'!$D:$D,'渠道充值成功率_底稿'!$A:$A,$A11,'渠道充值成功率_底稿'!$B:$B,H$1) -> 0 | I11: =SUMIFS('渠道充值成功率_底稿'!$D:$D,'渠道充值成功率_底稿'!$A:$A,$A11,'渠道充值成功率_底稿'!$B:$B,I$1) -> 0 | J11: =SUMIFS('渠道充值成功率_底稿'!$D:$D,'渠道充值成功率_底稿'!$A:$A,$A11,'渠道充值成功率_底稿'!$B:$B,J$1) -> 0 | K11: =SUMIFS('渠道充值成功率_底稿'!$D:$D,'渠道充值成功率_底稿'!$A:$A,$A11,'渠道充值成功率_底稿'!$B:$B,K$1) -> 0 | L11: =SUMIFS('渠道充值成功率_底稿'!$D:$D,'渠道充值成功率_底稿'!$A:$A,$A11,'渠道充值成功率_底稿'!$B:$B,L$1) -> 0
A12: =B8 -> 46055 | C12: 到账金额 | D12: =SUMIFS('渠道充值成功率_底稿'!$G:$G,'渠道充值成功率_底稿'!$A:$A,$A13,'渠道充值成功率_底稿'!$B:$B,D$1) -> 0 | E12: =SUMIFS('渠道充值成功率_底稿'!$G:$G,'渠道充值成功率_底稿'!$A:$A,$A12,'渠道充值成功率_底稿'!$B:$B,E$1) -> 0 | F12: =SUMIFS('渠道充值成功率_底稿'!$G:$G,'渠道充值成功率_底稿'!$A:$A,$A12,'渠道充值成功率_底稿'!$B:$B,F$1) -> 0 | G12: =SUMIFS('渠道充值成功率_底稿'!$G:$G,'渠道充值成功率_底稿'!$A:$A,$A12,'渠道充值成功率_底稿'!$B:$B,G$1) -> 0 | H12: =SUMIFS('渠道充值成功率_底稿'!$G:$G,'渠道充值成功率_底稿'!$A:$A,$A12,'渠道充值成功率_底稿'!$B:$B,H$1) -> 0 | I12: =SUMIFS('渠道充值成功率_底稿'!$G:$G,'渠道充值成功率_底稿'!$A:$A,$A12,'渠道充值成功率_底稿'!$B:$B,I$1) -> 0 | J12: =SUMIFS('渠道充值成功率_底稿'!$G:$G,'渠道充值成功率_底稿'!$A:$A,$A12,'渠道充值成功率_底稿'!$B:$B,J$1) -> 0 | K12: =SUMIFS('渠道充值成功率_底稿'!$G:$G,'渠道充值成功率_底稿'!$A:$A,$A12,'渠道充值成功率_底稿'!$B:$B,K$1) -> 0 | L12: =SUMIFS('渠道充值成功率_底稿'!$G:$G,'渠道充值成功率_底稿'!$A:$A,$A12,'渠道充值成功率_底稿'!$B:$B,L$1) -> 0
A13: =B8 -> 46055 | C13: 金额成功率 | D13: =IFERROR(ROUND(D12/D11,6),"0") -> 0 | E13: =IFERROR(ROUND(E12/E11,6),"0") -> 0 | F13: =IFERROR(ROUND(F12/F11,6),"0") -> 0 | G13: =IFERROR(ROUND(G12/G11,6),"0") -> 0 | H13: =IFERROR(ROUND(H12/H11,6),"0") -> 0 | I13: =IFERROR(ROUND(I12/I11,6),"0") -> 0 | J13: =IFERROR(ROUND(J12/J11,6),"0") -> 0 | K13: =IFERROR(ROUND(K12/K11,6),"0") -> 0 | L13: =IFERROR(ROUND(L12/L11,6),"0") -> 0
A14: =B14 -> 46056 | B14: =B8+1 -> 46056 | C14: 申请笔数 | D14: =SUMIFS('渠道充值成功率_底稿'!$C:$C,'渠道充值成功率_底稿'!$A:$A,$A14,'渠道充值成功率_底稿'!$B:$B,D$1) -> 0 | E14: =SUMIFS('渠道充值成功率_底稿'!$C:$C,'渠道充值成功率_底稿'!$A:$A,$A14,'渠道充值成功率_底稿'!$B:$B,E$1) -> 0 | F14: =SUMIFS('渠道充值成功率_底稿'!$C:$C,'渠道充值成功率_底稿'!$A:$A,$A14,'渠道充值成功率_底稿'!$B:$B,F$1) -> 0 | G14: =SUMIFS('渠道充值成功率_底稿'!$C:$C,'渠道充值成功率_底稿'!$A:$A,$A14,'渠道充值成功率_底稿'!$B:$B,G$1) -> 0 | H14: =SUMIFS('渠道充值成功率_底稿'!$C:$C,'渠道充值成功率_底稿'!$A:$A,$A14,'渠道充值成功率_底稿'!$B:$B,H$1) -> 0 | I14: =SUMIFS('渠道充值成功率_底稿'!$C:$C,'渠道充值成功率_底稿'!$A:$A,$A14,'渠道充值成功率_底稿'!$B:$B,I$1) -> 0 | J14: =SUMIFS('渠道充值成功率_底稿'!$C:$C,'渠道充值成功率_底稿'!$A:$A,$A14,'渠道充值成功率_底稿'!$B:$B,J$1) -> 0 | K14: =SUMIFS('渠道充值成功率_底稿'!$C:$C,'渠道充值成功率_底稿'!$A:$A,$A14,'渠道充值成功率_底稿'!$B:$B,K$1) -> 0 | L14: =SUMIFS('渠道充值成功率_底稿'!$C:$C,'渠道充值成功率_底稿'!$A:$A,$A14,'渠道充值成功率_底稿'!$B:$B,L$1) -> 0
A15: =B14 -> 46056 | C15: 到账笔数 | D15: =SUMIFS('渠道充值成功率_底稿'!$F:$F,'渠道充值成功率_底稿'!$A:$A,$A15,'渠道充值成功率_底稿'!$B:$B,D$1) -> 0 | E15: =SUMIFS('渠道充值成功率_底稿'!$F:$F,'渠道充值成功率_底稿'!$A:$A,$A15,'渠道充值成功率_底稿'!$B:$B,E$1) -> 0 | F15: =SUMIFS('渠道充值成功率_底稿'!$F:$F,'渠道充值成功率_底稿'!$A:$A,$A15,'渠道充值成功率_底稿'!$B:$B,F$1) -> 0 | G15: =SUMIFS('渠道充值成功率_底稿'!$F:$F,'渠道充值成功率_底稿'!$A:$A,$A15,'渠道充值成功率_底稿'!$B:$B,G$1) -> 0 | H15: =SUMIFS('渠道充值成功率_底稿'!$F:$F,'渠道充值成功率_底稿'!$A:$A,$A15,'渠道充值成功率_底稿'!$B:$B,H$1) -> 0 | I15: =SUMIFS('渠道充值成功率_底稿'!$F:$F,'渠道充值成功率_底稿'!$A:$A,$A15,'渠道充值成功率_底稿'!$B:$B,I$1) -> 0 | J15: =SUMIFS('渠道充值成功率_底稿'!$F:$F,'渠道充值成功率_底稿'!$A:$A,$A15,'渠道充值成功率_底稿'!$B:$B,J$1) -> 0 | K15: =SUMIFS('渠道充值成功率_底稿'!$F:$F,'渠道充值成功率_底稿'!$A:$A,$A15,'渠道充值成功率_底稿'!$B:$B,K$1) -> 0 | L15: =SUMIFS('渠道充值成功率_底稿'!$F:$F,'渠道充值成功率_底稿'!$A:$A,$A15,'渠道充值成功率_底稿'!$B:$B,L$1) -> 0
A16: =B14 -> 46056 | C16: 笔数成功率 | D16: =IFERROR(ROUND(D15/D14,6),"0") -> 0 | E16: =IFERROR(ROUND(E15/E14,6),"0") -> 0 | F16: =IFERROR(ROUND(F15/F14,6),"0") -> 0 | G16: =IFERROR(ROUND(G15/G14,6),"0") -> 0 | H16: =IFERROR(ROUND(H15/H14,6),"0") -> 0 | I16: =IFERROR(ROUND(I15/I14,6),"0") -> 0 | J16: =IFERROR(ROUND(J15/J14,6),"0") -> 0 | K16: =IFERROR(ROUND(K15/K14,6),"0") -> 0 | L16: =IFERROR(ROUND(L15/L14,6),"0") -> 0
A17: =B14 -> 46056 | C17: 申请金额 | D17: =SUMIFS('渠道充值成功率_底稿'!$D:$D,'渠道充值成功率_底稿'!$A:$A,$A18,'渠道充值成功率_底稿'!$B:$B,D$1) -> 0 | E17: =SUMIFS('渠道充值成功率_底稿'!$D:$D,'渠道充值成功率_底稿'!$A:$A,$A17,'渠道充值成功率_底稿'!$B:$B,E$1) -> 0 | F17: =SUMIFS('渠道充值成功率_底稿'!$D:$D,'渠道充值成功率_底稿'!$A:$A,$A17,'渠道充值成功率_底稿'!$B:$B,F$1) -> 0 | G17: =SUMIFS('渠道充值成功率_底稿'!$D:$D,'渠道充值成功率_底稿'!$A:$A,$A17,'渠道充值成功率_底稿'!$B:$B,G$1) -> 0 | H17: =SUMIFS('渠道充值成功率_底稿'!$D:$D,'渠道充值成功率_底稿'!$A:$A,$A17,'渠道充值成功率_底稿'!$B:$B,H$1) -> 0 | I17: =SUMIFS('渠道充值成功率_底稿'!$D:$D,'渠道充值成功率_底稿'!$A:$A,$A17,'渠道充值成功率_底稿'!$B:$B,I$1) -> 0 | J17: =SUMIFS('渠道充值成功率_底稿'!$D:$D,'渠道充值成功率_底稿'!$A:$A,$A17,'渠道充值成功率_底稿'!$B:$B,J$1) -> 0 | K17: =SUMIFS('渠道充值成功率_底稿'!$D:$D,'渠道充值成功率_底稿'!$A:$A,$A17,'渠道充值成功率_底稿'!$B:$B,K$1) -> 0 | L17: =SUMIFS('渠道充值成功率_底稿'!$D:$D,'渠道充值成功率_底稿'!$A:$A,$A17,'渠道充值成功率_底稿'!$B:$B,L$1) -> 0
A18: =B14 -> 46056 | C18: 到账金额 | D18: =SUMIFS('渠道充值成功率_底稿'!$G:$G,'渠道充值成功率_底稿'!$A:$A,$A19,'渠道充值成功率_底稿'!$B:$B,D$1) -> 0 | E18: =SUMIFS('渠道充值成功率_底稿'!$G:$G,'渠道充值成功率_底稿'!$A:$A,$A18,'渠道充值成功率_底稿'!$B:$B,E$1) -> 0 | F18: =SUMIFS('渠道充值成功率_底稿'!$G:$G,'渠道充值成功率_底稿'!$A:$A,$A18,'渠道充值成功率_底稿'!$B:$B,F$1) -> 0 | G18: =SUMIFS('渠道充值成功率_底稿'!$G:$G,'渠道充值成功率_底稿'!$A:$A,$A18,'渠道充值成功率_底稿'!$B:$B,G$1) -> 0 | H18: =SUMIFS('渠道充值成功率_底稿'!$G:$G,'渠道充值成功率_底稿'!$A:$A,$A18,'渠道充值成功率_底稿'!$B:$B,H$1) -> 0 | I18: =SUMIFS('渠道充值成功率_底稿'!$G:$G,'渠道充值成功率_底稿'!$A:$A,$A18,'渠道充值成功率_底稿'!$B:$B,I$1) -> 0 | J18: =SUMIFS('渠道充值成功率_底稿'!$G:$G,'渠道充值成功率_底稿'!$A:$A,$A18,'渠道充值成功率_底稿'!$B:$B,J$1) -> 0 | K18: =SUMIFS('渠道充值成功率_底稿'!$G:$G,'渠道充值成功率_底稿'!$A:$A,$A18,'渠道充值成功率_底稿'!$B:$B,K$1) -> 0 | L18: =SUMIFS('渠道充值成功率_底稿'!$G:$G,'渠道充值成功率_底稿'!$A:$A,$A18,'渠道充值成功率_底稿'!$B:$B,L$1) -> 0
A19: =B14 -> 46056 | C19: 金额成功率 | D19: =IFERROR(ROUND(D18/D17,6),"0") -> 0 | E19: =IFERROR(ROUND(E18/E17,6),"0") -> 0 | F19: =IFERROR(ROUND(F18/F17,6),"0") -> 0 | G19: =IFERROR(ROUND(G18/G17,6),"0") -> 0 | H19: =IFERROR(ROUND(H18/H17,6),"0") -> 0 | I19: =IFERROR(ROUND(I18/I17,6),"0") -> 0 | J19: =IFERROR(ROUND(J18/J17,6),"0") -> 0 | K19: =IFERROR(ROUND(K18/K17,6),"0") -> 0 | L19: =IFERROR(ROUND(L18/L17,6),"0") -> 0
A20: =B20 -> 46057 | B20: =B14+1 -> 46057 | C20: 申请笔数 | D20: =SUMIFS('渠道充值成功率_底稿'!$C:$C,'渠道充值成功率_底稿'!$A:$A,$A20,'渠道充值成功率_底稿'!$B:$B,D$1) -> 0 | E20: =SUMIFS('渠道充值成功率_底稿'!$C:$C,'渠道充值成功率_底稿'!$A:$A,$A20,'渠道充值成功率_底稿'!$B:$B,E$1) -> 0 | F20: =SUMIFS('渠道充值成功率_底稿'!$C:$C,'渠道充值成功率_底稿'!$A:$A,$A20,'渠道充值成功率_底稿'!$B:$B,F$1) -> 0 | G20: =SUMIFS('渠道充值成功率_底稿'!$C:$C,'渠道充值成功率_底稿'!$A:$A,$A20,'渠道充值成功率_底稿'!$B:$B,G$1) -> 0 | H20: =SUMIFS('渠道充值成功率_底稿'!$C:$C,'渠道充值成功率_底稿'!$A:$A,$A20,'渠道充值成功率_底稿'!$B:$B,H$1) -> 0 | I20: =SUMIFS('渠道充值成功率_底稿'!$C:$C,'渠道充值成功率_底稿'!$A:$A,$A20,'渠道充值成功率_底稿'!$B:$B,I$1) -> 0 | J20: =SUMIFS('渠道充值成功率_底稿'!$C:$C,'渠道充值成功率_底稿'!$A:$A,$A20,'渠道充值成功率_底稿'!$B:$B,J$1) -> 0 | K20: =SUMIFS('渠道充值成功率_底稿'!$C:$C,'渠道充值成功率_底稿'!$A:$A,$A20,'渠道充值成功率_底稿'!$B:$B,K$1) -> 0 | L20: =SUMIFS('渠道充值成功率_底稿'!$C:$C,'渠道充值成功率_底稿'!$A:$A,$A20,'渠道充值成功率_底稿'!$B:$B,L$1) -> 0
A21: =B20 -> 46057 | C21: 到账笔数 | D21: =SUMIFS('渠道充值成功率_底稿'!$F:$F,'渠道充值成功率_底稿'!$A:$A,$A21,'渠道充值成功率_底稿'!$B:$B,D$1) -> 0 | E21: =SUMIFS('渠道充值成功率_底稿'!$F:$F,'渠道充值成功率_底稿'!$A:$A,$A21,'渠道充值成功率_底稿'!$B:$B,E$1) -> 0 | F21: =SUMIFS('渠道充值成功率_底稿'!$F:$F,'渠道充值成功率_底稿'!$A:$A,$A21,'渠道充值成功率_底稿'!$B:$B,F$1) -> 0 | G21: =SUMIFS('渠道充值成功率_底稿'!$F:$F,'渠道充值成功率_底稿'!$A:$A,$A21,'渠道充值成功率_底稿'!$B:$B,G$1) -> 0 | H21: =SUMIFS('渠道充值成功率_底稿'!$F:$F,'渠道充值成功率_底稿'!$A:$A,$A21,'渠道充值成功率_底稿'!$B:$B,H$1) -> 0 | I21: =SUMIFS('渠道充值成功率_底稿'!$F:$F,'渠道充值成功率_底稿'!$A:$A,$A21,'渠道充值成功率_底稿'!$B:$B,I$1) -> 0 | J21: =SUMIFS('渠道充值成功率_底稿'!$F:$F,'渠道充值成功率_底稿'!$A:$A,$A21,'渠道充值成功率_底稿'!$B:$B,J$1) -> 0 | K21: =SUMIFS('渠道充值成功率_底稿'!$F:$F,'渠道充值成功率_底稿'!$A:$A,$A21,'渠道充值成功率_底稿'!$B:$B,K$1) -> 0 | L21: =SUMIFS('渠道充值成功率_底稿'!$F:$F,'渠道充值成功率_底稿'!$A:$A,$A21,'渠道充值成功率_底稿'!$B:$B,L$1) -> 0
A22: =B20 -> 46057 | C22: 笔数成功率 | D22: =IFERROR(ROUND(D21/D20,6),"0") -> 0 | E22: =IFERROR(ROUND(E21/E20,6),"0") -> 0 | F22: =IFERROR(ROUND(F21/F20,6),"0") -> 0 | G22: =IFERROR(ROUND(G21/G20,6),"0") -> 0 | H22: =IFERROR(ROUND(H21/H20,6),"0") -> 0 | I22: =IFERROR(ROUND(I21/I20,6),"0") -> 0 | J22: =IFERROR(ROUND(J21/J20,6),"0") -> 0 | K22: =IFERROR(ROUND(K21/K20,6),"0") -> 0 | L22: =IFERROR(ROUND(L21/L20,6),"0") -> 0
A23: =B20 -> 46057 | C23: 申请金额 | D23: =SUMIFS('渠道充值成功率_底稿'!$D:$D,'渠道充值成功率_底稿'!$A:$A,$A24,'渠道充值成功率_底稿'!$B:$B,D$1) -> 0 | E23: =SUMIFS('渠道充值成功率_底稿'!$D:$D,'渠道充值成功率_底稿'!$A:$A,$A23,'渠道充值成功率_底稿'!$B:$B,E$1) -> 0 | F23: =SUMIFS('渠道充值成功率_底稿'!$D:$D,'渠道充值成功率_底稿'!$A:$A,$A23,'渠道充值成功率_底稿'!$B:$B,F$1) -> 0 | G23: =SUMIFS('渠道充值成功率_底稿'!$D:$D,'渠道充值成功率_底稿'!$A:$A,$A23,'渠道充值成功率_底稿'!$B:$B,G$1) -> 0 | H23: =SUMIFS('渠道充值成功率_底稿'!$D:$D,'渠道充值成功率_底稿'!$A:$A,$A23,'渠道充值成功率_底稿'!$B:$B,H$1) -> 0 | I23: =SUMIFS('渠道充值成功率_底稿'!$D:$D,'渠道充值成功率_底稿'!$A:$A,$A23,'渠道充值成功率_底稿'!$B:$B,I$1) -> 0 | J23: =SUMIFS('渠道充值成功率_底稿'!$D:$D,'渠道充值成功率_底稿'!$A:$A,$A23,'渠道充值成功率_底稿'!$B:$B,J$1) -> 0 | K23: =SUMIFS('渠道充值成功率_底稿'!$D:$D,'渠道充值成功率_底稿'!$A:$A,$A23,'渠道充值成功率_底稿'!$B:$B,K$1) -> 0 | L23: =SUMIFS('渠道充值成功率_底稿'!$D:$D,'渠道充值成功率_底稿'!$A:$A,$A23,'渠道充值成功率_底稿'!$B:$B,L$1) -> 0
A24: =B20 -> 46057 | C24: 到账金额 | D24: =SUMIFS('渠道充值成功率_底稿'!$G:$G,'渠道充值成功率_底稿'!$A:$A,$A25,'渠道充值成功率_底稿'!$B:$B,D$1) -> 0 | E24: =SUMIFS('渠道充值成功率_底稿'!$G:$G,'渠道充值成功率_底稿'!$A:$A,$A24,'渠道充值成功率_底稿'!$B:$B,E$1) -> 0 | F24: =SUMIFS('渠道充值成功率_底稿'!$G:$G,'渠道充值成功率_底稿'!$A:$A,$A24,'渠道充值成功率_底稿'!$B:$B,F$1) -> 0 | G24: =SUMIFS('渠道充值成功率_底稿'!$G:$G,'渠道充值成功率_底稿'!$A:$A,$A24,'渠道充值成功率_底稿'!$B:$B,G$1) -> 0 | H24: =SUMIFS('渠道充值成功率_底稿'!$G:$G,'渠道充值成功率_底稿'!$A:$A,$A24,'渠道充值成功率_底稿'!$B:$B,H$1) -> 0 | I24: =SUMIFS('渠道充值成功率_底稿'!$G:$G,'渠道充值成功率_底稿'!$A:$A,$A24,'渠道充值成功率_底稿'!$B:$B,I$1) -> 0 | J24: =SUMIFS('渠道充值成功率_底稿'!$G:$G,'渠道充值成功率_底稿'!$A:$A,$A24,'渠道充值成功率_底稿'!$B:$B,J$1) -> 0 | K24: =SUMIFS('渠道充值成功率_底稿'!$G:$G,'渠道充值成功率_底稿'!$A:$A,$A24,'渠道充值成功率_底稿'!$B:$B,K$1) -> 0 | L24: =SUMIFS('渠道充值成功率_底稿'!$G:$G,'渠道充值成功率_底稿'!$A:$A,$A24,'渠道充值成功率_底稿'!$B:$B,L$1) -> 0
A25: =B20 -> 46057 | C25: 金额成功率 | D25: =IFERROR(ROUND(D24/D23,6),"0") -> 0 | E25: =IFERROR(ROUND(E24/E23,6),"0") -> 0 | F25: =IFERROR(ROUND(F24/F23,6),"0") -> 0 | G25: =IFERROR(ROUND(G24/G23,6),"0") -> 0 | H25: =IFERROR(ROUND(H24/H23,6),"0") -> 0 | I25: =IFERROR(ROUND(I24/I23,6),"0") -> 0 | J25: =IFERROR(ROUND(J24/J23,6),"0") -> 0 | K25: =IFERROR(ROUND(K24/K23,6),"0") -> 0 | L25: =IFERROR(ROUND(L24/L23,6),"0") -> 0
A26: =B26 -> 46058 | B26: =B20+1 -> 46058 | C26: 申请笔数 | D26: =SUMIFS('渠道充值成功率_底稿'!$C:$C,'渠道充值成功率_底稿'!$A:$A,$A26,'渠道充值成功率_底稿'!$B:$B,D$1) -> 0 | E26: =SUMIFS('渠道充值成功率_底稿'!$C:$C,'渠道充值成功率_底稿'!$A:$A,$A26,'渠道充值成功率_底稿'!$B:$B,E$1) -> 0 | F26: =SUMIFS('渠道充值成功率_底稿'!$C:$C,'渠道充值成功率_底稿'!$A:$A,$A26,'渠道充值成功率_底稿'!$B:$B,F$1) -> 0 | G26: =SUMIFS('渠道充值成功率_底稿'!$C:$C,'渠道充值成功率_底稿'!$A:$A,$A26,'渠道充值成功率_底稿'!$B:$B,G$1) -> 0 | H26: =SUMIFS('渠道充值成功率_底稿'!$C:$C,'渠道充值成功率_底稿'!$A:$A,$A26,'渠道充值成功率_底稿'!$B:$B,H$1) -> 0 | I26: =SUMIFS('渠道充值成功率_底稿'!$C:$C,'渠道充值成功率_底稿'!$A:$A,$A26,'渠道充值成功率_底稿'!$B:$B,I$1) -> 0 | J26: =SUMIFS('渠道充值成功率_底稿'!$C:$C,'渠道充值成功率_底稿'!$A:$A,$A26,'渠道充值成功率_底稿'!$B:$B,J$1) -> 0 | K26: =SUMIFS('渠道充值成功率_底稿'!$C:$C,'渠道充值成功率_底稿'!$A:$A,$A26,'渠道充值成功率_底稿'!$B:$B,K$1) -> 0 | L26: =SUMIFS('渠道充值成功率_底稿'!$C:$C,'渠道充值成功率_底稿'!$A:$A,$A26,'渠道充值成功率_底稿'!$B:$B,L$1) -> 0
A27: =B26 -> 46058 | C27: 到账笔数 | D27: =SUMIFS('渠道充值成功率_底稿'!$F:$F,'渠道充值成功率_底稿'!$A:$A,$A27,'渠道充值成功率_底稿'!$B:$B,D$1) -> 0 | E27: =SUMIFS('渠道充值成功率_底稿'!$F:$F,'渠道充值成功率_底稿'!$A:$A,$A27,'渠道充值成功率_底稿'!$B:$B,E$1) -> 0 | F27: =SUMIFS('渠道充值成功率_底稿'!$F:$F,'渠道充值成功率_底稿'!$A:$A,$A27,'渠道充值成功率_底稿'!$B:$B,F$1) -> 0 | G27: =SUMIFS('渠道充值成功率_底稿'!$F:$F,'渠道充值成功率_底稿'!$A:$A,$A27,'渠道充值成功率_底稿'!$B:$B,G$1) -> 0 | H27: =SUMIFS('渠道充值成功率_底稿'!$F:$F,'渠道充值成功率_底稿'!$A:$A,$A27,'渠道充值成功率_底稿'!$B:$B,H$1) -> 0 | I27: =SUMIFS('渠道充值成功率_底稿'!$F:$F,'渠道充值成功率_底稿'!$A:$A,$A27,'渠道充值成功率_底稿'!$B:$B,I$1) -> 0 | J27: =SUMIFS('渠道充值成功率_底稿'!$F:$F,'渠道充值成功率_底稿'!$A:$A,$A27,'渠道充值成功率_底稿'!$B:$B,J$1) -> 0 | K27: =SUMIFS('渠道充值成功率_底稿'!$F:$F,'渠道充值成功率_底稿'!$A:$A,$A27,'渠道充值成功率_底稿'!$B:$B,K$1) -> 0 | L27: =SUMIFS('渠道充值成功率_底稿'!$F:$F,'渠道充值成功率_底稿'!$A:$A,$A27,'渠道充值成功率_底稿'!$B:$B,L$1) -> 0
A28: =B26 -> 46058 | C28: 笔数成功率 | D28: =IFERROR(ROUND(D27/D26,6),"0") -> 0 | E28: =IFERROR(ROUND(E27/E26,6),"0") -> 0 | F28: =IFERROR(ROUND(F27/F26,6),"0") -> 0 | G28: =IFERROR(ROUND(G27/G26,6),"0") -> 0 | H28: =IFERROR(ROUND(H27/H26,6),"0") -> 0 | I28: =IFERROR(ROUND(I27/I26,6),"0") -> 0 | J28: =IFERROR(ROUND(J27/J26,6),"0") -> 0 | K28: =IFERROR(ROUND(K27/K26,6),"0") -> 0 | L28: =IFERROR(ROUND(L27/L26,6),"0") -> 0
A29: =B26 -> 46058 | C29: 申请金额 | D29: =SUMIFS('渠道充值成功率_底稿'!$D:$D,'渠道充值成功率_底稿'!$A:$A,$A30,'渠道充值成功率_底稿'!$B:$B,D$1) -> 0 | E29: =SUMIFS('渠道充值成功率_底稿'!$D:$D,'渠道充值成功率_底稿'!$A:$A,$A29,'渠道充值成功率_底稿'!$B:$B,E$1) -> 0 | F29: =SUMIFS('渠道充值成功率_底稿'!$D:$D,'渠道充值成功率_底稿'!$A:$A,$A29,'渠道充值成功率_底稿'!$B:$B,F$1) -> 0 | G29: =SUMIFS('渠道充值成功率_底稿'!$D:$D,'渠道充值成功率_底稿'!$A:$A,$A29,'渠道充值成功率_底稿'!$B:$B,G$1) -> 0 | H29: =SUMIFS('渠道充值成功率_底稿'!$D:$D,'渠道充值成功率_底稿'!$A:$A,$A29,'渠道充值成功率_底稿'!$B:$B,H$1) -> 0 | I29: =SUMIFS('渠道充值成功率_底稿'!$D:$D,'渠道充值成功率_底稿'!$A:$A,$A29,'渠道充值成功率_底稿'!$B:$B,I$1) -> 0 | J29: =SUMIFS('渠道充值成功率_底稿'!$D:$D,'渠道充值成功率_底稿'!$A:$A,$A29,'渠道充值成功率_底稿'!$B:$B,J$1) -> 0 | K29: =SUMIFS('渠道充值成功率_底稿'!$D:$D,'渠道充值成功率_底稿'!$A:$A,$A29,'渠道充值成功率_底稿'!$B:$B,K$1) -> 0 | L29: =SUMIFS('渠道充值成功率_底稿'!$D:$D,'渠道充值成功率_底稿'!$A:$A,$A29,'渠道充值成功率_底稿'!$B:$B,L$1) -> 0
A30: =B26 -> 46058 | C30: 到账金额 | D30: =SUMIFS('渠道充值成功率_底稿'!$G:$G,'渠道充值成功率_底稿'!$A:$A,$A31,'渠道充值成功率_底稿'!$B:$B,D$1) -> 0 | E30: =SUMIFS('渠道充值成功率_底稿'!$G:$G,'渠道充值成功率_底稿'!$A:$A,$A30,'渠道充值成功率_底稿'!$B:$B,E$1) -> 0 | F30: =SUMIFS('渠道充值成功率_底稿'!$G:$G,'渠道充值成功率_底稿'!$A:$A,$A30,'渠道充值成功率_底稿'!$B:$B,F$1) -> 0 | G30: =SUMIFS('渠道充值成功率_底稿'!$G:$G,'渠道充值成功率_底稿'!$A:$A,$A30,'渠道充值成功率_底稿'!$B:$B,G$1) -> 0 | H30: =SUMIFS('渠道充值成功率_底稿'!$G:$G,'渠道充值成功率_底稿'!$A:$A,$A30,'渠道充值成功率_底稿'!$B:$B,H$1) -> 0 | I30: =SUMIFS('渠道充值成功率_底稿'!$G:$G,'渠道充值成功率_底稿'!$A:$A,$A30,'渠道充值成功率_底稿'!$B:$B,I$1) -> 0 | J30: =SUMIFS('渠道充值成功率_底稿'!$G:$G,'渠道充值成功率_底稿'!$A:$A,$A30,'渠道充值成功率_底稿'!$B:$B,J$1) -> 0 | K30: =SUMIFS('渠道充值成功率_底稿'!$G:$G,'渠道充值成功率_底稿'!$A:$A,$A30,'渠道充值成功率_底稿'!$B:$B,K$1) -> 0 | L30: =SUMIFS('渠道充值成功率_底稿'!$G:$G,'渠道充值成功率_底稿'!$A:$A,$A30,'渠道充值成功率_底稿'!$B:$B,L$1) -> 0
A31: =B26 -> 46058 | C31: 金额成功率 | D31: =IFERROR(ROUND(D30/D29,6),"0") -> 0 | E31: =IFERROR(ROUND(E30/E29,6),"0") -> 0 | F31: =IFERROR(ROUND(F30/F29,6),"0") -> 0 | G31: =IFERROR(ROUND(G30/G29,6),"0") -> 0 | H31: =IFERROR(ROUND(H30/H29,6),"0") -> 0 | I31: =IFERROR(ROUND(I30/I29,6),"0") -> 0 | J31: =IFERROR(ROUND(J30/J29,6),"0") -> 0 | K31: =IFERROR(ROUND(K30/K29,6),"0") -> 0 | L31: =IFERROR(ROUND(L30/L29,6),"0") -> 0
A32: =B32 -> 46059 | B32: =B26+1 -> 46059 | C32: 申请笔数 | D32: =SUMIFS('渠道充值成功率_底稿'!$C:$C,'渠道充值成功率_底稿'!$A:$A,$A32,'渠道充值成功率_底稿'!$B:$B,D$1) -> 0 | E32: =SUMIFS('渠道充值成功率_底稿'!$C:$C,'渠道充值成功率_底稿'!$A:$A,$A32,'渠道充值成功率_底稿'!$B:$B,E$1) -> 0 | F32: =SUMIFS('渠道充值成功率_底稿'!$C:$C,'渠道充值成功率_底稿'!$A:$A,$A32,'渠道充值成功率_底稿'!$B:$B,F$1) -> 0 | G32: =SUMIFS('渠道充值成功率_底稿'!$C:$C,'渠道充值成功率_底稿'!$A:$A,$A32,'渠道充值成功率_底稿'!$B:$B,G$1) -> 0 | H32: =SUMIFS('渠道充值成功率_底稿'!$C:$C,'渠道充值成功率_底稿'!$A:$A,$A32,'渠道充值成功率_底稿'!$B:$B,H$1) -> 0 | I32: =SUMIFS('渠道充值成功率_底稿'!$C:$C,'渠道充值成功率_底稿'!$A:$A,$A32,'渠道充值成功率_底稿'!$B:$B,I$1) -> 0 | J32: =SUMIFS('渠道充值成功率_底稿'!$C:$C,'渠道充值成功率_底稿'!$A:$A,$A32,'渠道充值成功率_底稿'!$B:$B,J$1) -> 0 | K32: =SUMIFS('渠道充值成功率_底稿'!$C:$C,'渠道充值成功率_底稿'!$A:$A,$A32,'渠道充值成功率_底稿'!$B:$B,K$1) -> 0 | L32: =SUMIFS('渠道充值成功率_底稿'!$C:$C,'渠道充值成功率_底稿'!$A:$A,$A32,'渠道充值成功率_底稿'!$B:$B,L$1) -> 0
A33: =B32 -> 46059 | C33: 到账笔数 | D33: =SUMIFS('渠道充值成功率_底稿'!$F:$F,'渠道充值成功率_底稿'!$A:$A,$A33,'渠道充值成功率_底稿'!$B:$B,D$1) -> 0 | E33: =SUMIFS('渠道充值成功率_底稿'!$F:$F,'渠道充值成功率_底稿'!$A:$A,$A33,'渠道充值成功率_底稿'!$B:$B,E$1) -> 0 | F33: =SUMIFS('渠道充值成功率_底稿'!$F:$F,'渠道充值成功率_底稿'!$A:$A,$A33,'渠道充值成功率_底稿'!$B:$B,F$1) -> 0 | G33: =SUMIFS('渠道充值成功率_底稿'!$F:$F,'渠道充值成功率_底稿'!$A:$A,$A33,'渠道充值成功率_底稿'!$B:$B,G$1) -> 0 | H33: =SUMIFS('渠道充值成功率_底稿'!$F:$F,'渠道充值成功率_底稿'!$A:$A,$A33,'渠道充值成功率_底稿'!$B:$B,H$1) -> 0 | I33: =SUMIFS('渠道充值成功率_底稿'!$F:$F,'渠道充值成功率_底稿'!$A:$A,$A33,'渠道充值成功率_底稿'!$B:$B,I$1) -> 0 | J33: =SUMIFS('渠道充值成功率_底稿'!$F:$F,'渠道充值成功率_底稿'!$A:$A,$A33,'渠道充值成功率_底稿'!$B:$B,J$1) -> 0 | K33: =SUMIFS('渠道充值成功率_底稿'!$F:$F,'渠道充值成功率_底稿'!$A:$A,$A33,'渠道充值成功率_底稿'!$B:$B,K$1) -> 0 | L33: =SUMIFS('渠道充值成功率_底稿'!$F:$F,'渠道充值成功率_底稿'!$A:$A,$A33,'渠道充值成功率_底稿'!$B:$B,L$1) -> 0
A34: =B32 -> 46059 | C34: 笔数成功率 | D34: =IFERROR(ROUND(D33/D32,6),"0") -> 0 | E34: =IFERROR(ROUND(E33/E32,6),"0") -> 0 | F34: =IFERROR(ROUND(F33/F32,6),"0") -> 0 | G34: =IFERROR(ROUND(G33/G32,6),"0") -> 0 | H34: =IFERROR(ROUND(H33/H32,6),"0") -> 0 | I34: =IFERROR(ROUND(I33/I32,6),"0") -> 0 | J34: =IFERROR(ROUND(J33/J32,6),"0") -> 0 | K34: =IFERROR(ROUND(K33/K32,6),"0") -> 0 | L34: =IFERROR(ROUND(L33/L32,6),"0") -> 0
A35: =B32 -> 46059 | C35: 申请金额 | D35: =SUMIFS('渠道充值成功率_底稿'!$D:$D,'渠道充值成功率_底稿'!$A:$A,$A36,'渠道充值成功率_底稿'!$B:$B,D$1) -> 0 | E35: =SUMIFS('渠道充值成功率_底稿'!$D:$D,'渠道充值成功率_底稿'!$A:$A,$A35,'渠道充值成功率_底稿'!$B:$B,E$1) -> 0 | F35: =SUMIFS('渠道充值成功率_底稿'!$D:$D,'渠道充值成功率_底稿'!$A:$A,$A35,'渠道充值成功率_底稿'!$B:$B,F$1) -> 0 | G35: =SUMIFS('渠道充值成功率_底稿'!$D:$D,'渠道充值成功率_底稿'!$A:$A,$A35,'渠道充值成功率_底稿'!$B:$B,G$1) -> 0 | H35: =SUMIFS('渠道充值成功率_底稿'!$D:$D,'渠道充值成功率_底稿'!$A:$A,$A35,'渠道充值成功率_底稿'!$B:$B,H$1) -> 0 | I35: =SUMIFS('渠道充值成功率_底稿'!$D:$D,'渠道充值成功率_底稿'!$A:$A,$A35,'渠道充值成功率_底稿'!$B:$B,I$1) -> 0 | J35: =SUMIFS('渠道充值成功率_底稿'!$D:$D,'渠道充值成功率_底稿'!$A:$A,$A35,'渠道充值成功率_底稿'!$B:$B,J$1) -> 0 | K35: =SUMIFS('渠道充值成功率_底稿'!$D:$D,'渠道充值成功率_底稿'!$A:$A,$A35,'渠道充值成功率_底稿'!$B:$B,K$1) -> 0 | L35: =SUMIFS('渠道充值成功率_底稿'!$D:$D,'渠道充值成功率_底稿'!$A:$A,$A35,'渠道充值成功率_底稿'!$B:$B,L$1) -> 0
A36: =B32 -> 46059 | C36: 到账金额 | D36: =SUMIFS('渠道充值成功率_底稿'!$G:$G,'渠道充值成功率_底稿'!$A:$A,$A37,'渠道充值成功率_底稿'!$B:$B,D$1) -> 0 | E36: =SUMIFS('渠道充值成功率_底稿'!$G:$G,'渠道充值成功率_底稿'!$A:$A,$A36,'渠道充值成功率_底稿'!$B:$B,E$1) -> 0 | F36: =SUMIFS('渠道充值成功率_底稿'!$G:$G,'渠道充值成功率_底稿'!$A:$A,$A36,'渠道充值成功率_底稿'!$B:$B,F$1) -> 0 | G36: =SUMIFS('渠道充值成功率_底稿'!$G:$G,'渠道充值成功率_底稿'!$A:$A,$A36,'渠道充值成功率_底稿'!$B:$B,G$1) -> 0 | H36: =SUMIFS('渠道充值成功率_底稿'!$G:$G,'渠道充值成功率_底稿'!$A:$A,$A36,'渠道充值成功率_底稿'!$B:$B,H$1) -> 0 | I36: =SUMIFS('渠道充值成功率_底稿'!$G:$G,'渠道充值成功率_底稿'!$A:$A,$A36,'渠道充值成功率_底稿'!$B:$B,I$1) -> 0 | J36: =SUMIFS('渠道充值成功率_底稿'!$G:$G,'渠道充值成功率_底稿'!$A:$A,$A36,'渠道充值成功率_底稿'!$B:$B,J$1) -> 0 | K36: =SUMIFS('渠道充值成功率_底稿'!$G:$G,'渠道充值成功率_底稿'!$A:$A,$A36,'渠道充值成功率_底稿'!$B:$B,K$1) -> 0 | L36: =SUMIFS('渠道充值成功率_底稿'!$G:$G,'渠道充值成功率_底稿'!$A:$A,$A36,'渠道充值成功率_底稿'!$B:$B,L$1) -> 0
A37: =B32 -> 46059 | C37: 金额成功率 | D37: =IFERROR(ROUND(D36/D35,6),"0") -> 0 | E37: =IFERROR(ROUND(E36/E35,6),"0") -> 0 | F37: =IFERROR(ROUND(F36/F35,6),"0") -> 0 | G37: =IFERROR(ROUND(G36/G35,6),"0") -> 0 | H37: =IFERROR(ROUND(H36/H35,6),"0") -> 0 | I37: =IFERROR(ROUND(I36/I35,6),"0") -> 0 | J37: =IFERROR(ROUND(J36/J35,6),"0") -> 0 | K37: =IFERROR(ROUND(K36/K35,6),"0") -> 0 | L37: =IFERROR(ROUND(L36/L35,6),"0") -> 0
A38: =B38 -> 46060 | B38: =B32+1 -> 46060 | C38: 申请笔数 | D38: =SUMIFS('渠道充值成功率_底稿'!$C:$C,'渠道充值成功率_底稿'!$A:$A,$A38,'渠道充值成功率_底稿'!$B:$B,D$1) -> 0 | E38: =SUMIFS('渠道充值成功率_底稿'!$C:$C,'渠道充值成功率_底稿'!$A:$A,$A38,'渠道充值成功率_底稿'!$B:$B,E$1) -> 0 | F38: =SUMIFS('渠道充值成功率_底稿'!$C:$C,'渠道充值成功率_底稿'!$A:$A,$A38,'渠道充值成功率_底稿'!$B:$B,F$1) -> 0 | G38: =SUMIFS('渠道充值成功率_底稿'!$C:$C,'渠道充值成功率_底稿'!$A:$A,$A38,'渠道充值成功率_底稿'!$B:$B,G$1) -> 0 | H38: =SUMIFS('渠道充值成功率_底稿'!$C:$C,'渠道充值成功率_底稿'!$A:$A,$A38,'渠道充值成功率_底稿'!$B:$B,H$1) -> 0 | I38: =SUMIFS('渠道充值成功率_底稿'!$C:$C,'渠道充值成功率_底稿'!$A:$A,$A38,'渠道充值成功率_底稿'!$B:$B,I$1) -> 0 | J38: =SUMIFS('渠道充值成功率_底稿'!$C:$C,'渠道充值成功率_底稿'!$A:$A,$A38,'渠道充值成功率_底稿'!$B:$B,J$1) -> 0 | K38: =SUMIFS('渠道充值成功率_底稿'!$C:$C,'渠道充值成功率_底稿'!$A:$A,$A38,'渠道充值成功率_底稿'!$B:$B,K$1) -> 0 | L38: =SUMIFS('渠道充值成功率_底稿'!$C:$C,'渠道充值成功率_底稿'!$A:$A,$A38,'渠道充值成功率_底稿'!$B:$B,L$1) -> 0
A39: =B38 -> 46060 | C39: 到账笔数 | D39: =SUMIFS('渠道充值成功率_底稿'!$F:$F,'渠道充值成功率_底稿'!$A:$A,$A39,'渠道充值成功率_底稿'!$B:$B,D$1) -> 0 | E39: =SUMIFS('渠道充值成功率_底稿'!$F:$F,'渠道充值成功率_底稿'!$A:$A,$A39,'渠道充值成功率_底稿'!$B:$B,E$1) -> 0 | F39: =SUMIFS('渠道充值成功率_底稿'!$F:$F,'渠道充值成功率_底稿'!$A:$A,$A39,'渠道充值成功率_底稿'!$B:$B,F$1) -> 0 | G39: =SUMIFS('渠道充值成功率_底稿'!$F:$F,'渠道充值成功率_底稿'!$A:$A,$A39,'渠道充值成功率_底稿'!$B:$B,G$1) -> 0 | H39: =SUMIFS('渠道充值成功率_底稿'!$F:$F,'渠道充值成功率_底稿'!$A:$A,$A39,'渠道充值成功率_底稿'!$B:$B,H$1) -> 0 | I39: =SUMIFS('渠道充值成功率_底稿'!$F:$F,'渠道充值成功率_底稿'!$A:$A,$A39,'渠道充值成功率_底稿'!$B:$B,I$1) -> 0 | J39: =SUMIFS('渠道充值成功率_底稿'!$F:$F,'渠道充值成功率_底稿'!$A:$A,$A39,'渠道充值成功率_底稿'!$B:$B,J$1) -> 0 | K39: =SUMIFS('渠道充值成功率_底稿'!$F:$F,'渠道充值成功率_底稿'!$A:$A,$A39,'渠道充值成功率_底稿'!$B:$B,K$1) -> 0 | L39: =SUMIFS('渠道充值成功率_底稿'!$F:$F,'渠道充值成功率_底稿'!$A:$A,$A39,'渠道充值成功率_底稿'!$B:$B,L$1) -> 0
A40: =B38 -> 46060 | C40: 笔数成功率 | D40: =IFERROR(ROUND(D39/D38,6),"0") -> 0 | E40: =IFERROR(ROUND(E39/E38,6),"0") -> 0 | F40: =IFERROR(ROUND(F39/F38,6),"0") -> 0 | G40: =IFERROR(ROUND(G39/G38,6),"0") -> 0 | H40: =IFERROR(ROUND(H39/H38,6),"0") -> 0 | I40: =IFERROR(ROUND(I39/I38,6),"0") -> 0 | J40: =IFERROR(ROUND(J39/J38,6),"0") -> 0 | K40: =IFERROR(ROUND(K39/K38,6),"0") -> 0 | L40: =IFERROR(ROUND(L39/L38,6),"0") -> 0
...

Sheet 渠道充值成功率_底稿
B1: jiliarena
A2: 时间 | B2: 充值方式 | C2: 申请笔数 | D2: 申请金额 | E2: 申请人数 | F2: 到账笔数 | G2: 到账金额 | H2: 到账人数 | I2: 首存人数 | J2: 首存金额 | K2: 成功率 (%) | L2: 到账金额占比 (%) | M2: 平均到账时间
A3: 46064 | B3: GOTYME | C3: 2 | D3: 400 | E3: 2 | F3: 2 | G3: 400 | H3: 2 | I3: 2 | J3: 400 | K3: 100.00 % | L3: 0.78 % | M3: 0.00085648148
A4: 46064 | B4: QRPH | C4: 15 | D4: 9270 | E4: 11 | F4: 14 | G4: 9070 | H4: 10 | I4: 10 | J4: 2270 | K4: 93.33 % | L4: 17.88 % | M4: 0.00061342593
A5: 46064 | B5: GCash | C5: 336 | D5: 45098 | E5: 261 | F5: 264 | G5: 34978 | H5: 234 | I5: 233 | J5: 30238 | K5: 78.57 % | L5: 68.97 % | M5: 0.00099537037
A6: 46064 | B6: GCashQR | C6: 7 | D6: 700 | E6: 6 | F6: 6 | G6: 600 | H6: 6 | I6: 6 | J6: 600 | K6: 85.71 % | L6: 1.18 % | M6: 0.00068287037
A7: 46064 | B7: Maya | C7: 57 | D7: 6415 | E7: 46 | F7: 45 | G7: 5665 | H7: 43 | I7: 43 | J7: 5415 | K7: 78.94 % | L7: 11.17 % | M7: 0.00060185185
A9: 46065 | B9: GOTYME | C9: 17 | D9: 3970 | E9: 12 | F9: 16 | G9: 3870 | H9: 12 | I9: 12 | J9: 3270 | K9: 94.11 % | L9: 0.70 % | M9: 0.00072916667
A10: 46065 | B10: QRPH | C10: 176 | D10: 41417 | E10: 145 | F10: 151 | G10: 35097 | H10: 139 | I10: 125 | J10: 28610 | K10: 85.79 % | L10: 6.39 % | M10: 0.00074074074
A11: 46065 | B11: GCash | C11: 3522 | D11: 594748 | E11: 2253 | F11: 2658 | G11: 393917 | H11: 2124 | I11: 2026 | J11: 297423 | K11: 75.46 % | L11: 71.78 % | M11: 0.00087962963
A12: 46065 | B12: GCashQR | C12: 238 | D12: 45503 | E12: 170 | F12: 132 | G12: 26162 | H12: 122 | I12: 107 | J12: 21600 | K12: 55.46 % | L12: 4.76 % | M12: 0.00070601852
A13: 46065 | B13: Maya | C13: 609 | D13: 114956 | E13: 427 | F13: 487 | G13: 89690 | H13: 402 | I13: 359 | J13: 60636 | K13: 79.96 % | L13: 16.34 % | M13: 0.0006712963
A15: 46066 | B15: GOTYME | C15: 76 | D15: 23630 | E15: 62 | F15: 59 | G15: 18270 | H15: 56 | I15: 54 | J15: 16470 | K15: 77.63 | L15: 3.32 | M15: 0.00070601852
A16: 46066 | B16: QRPH | C16: 145 | D16: 33078 | E16: 115 | F16: 123 | G16: 28478 | H16: 106 | I16: 82 | J16: 18755 | K16: 84.82 | L16: 5.18 | M16: 0.00072916667
A17: 46066 | B17: GCash | C17: 3138 | D17: 480873 | E17: 2198 | F17: 2662 | G17: 388877 | H17: 2102 | I17: 1668 | J17: 245396 | K17: 84.83 | L17: 70.79 | M17: 0.00092592593
A18: 46066 | B18: GCashQR | C18: 221 | D18: 45857 | E18: 163 | F18: 155 | G18: 30188 | H18: 140 | I18: 103 | J18: 21798 | K18: 70.13 | L18: 5.49 | M18: 0.0010185185
A19: 46066 | B19: Maya | C19: 574 | D19: 101172 | E19: 427 | F19: 471 | G19: 83453 | H19: 408 | I19: 337 | J19: 65947 | K19: 82.05 | L19: 15.19 | M19: 0.00065972222
A21: 46067 | B21: GCash | C21: 2086 | D21: 341824 | E21: 1415 | F21: 1749 | G21: 283234 | H21: 1328 | I21: 859 | J21: 136474 | K21: 83.84 % | L21: 64.08 % | M21: 0.00086805556
A22: 46067 | B22: QRPH | C22: 104 | D22: 47720 | E22: 84 | F22: 93 | G22: 44710 | H22: 80 | I22: 59 | J22: 15099 | K22: 89.42 % | L22: 10.11 % | M22: 0.00072916667
A23: 46067 | B23: GOTYME | C23: 64 | D23: 21990 | E23: 60 | F23: 62 | G23: 21390 | H23: 60 | I23: 57 | J23: 20640 | K23: 96.87 % | L23: 4.83 % | M23: 0.00063657407
A24: 46067 | B24: GCashQR | C24: 101 | D24: 22175 | E24: 74 | F24: 71 | G24: 12977 | H24: 61 | I24: 39 | J24: 6280 | K24: 70.29 % | L24: 2.93 % | M24: 0.00081018519
A25: 46067 | B25: Maya | C25: 349 | D25: 88258 | E25: 263 | F25: 297 | G25: 79670 | H25: 249 | I25: 165 | J25: 28343 | K25: 85.10 % | L25: 18.02 % | M25: 0.00070601852
A27: 46068 | B27: GCash | C27: 1356 | D27: 190005 | E27: 848 | F27: 1073 | G27: 153442 | H27: 775 | I27: 414 | J27: 56094 | K27: 79.12 % | L27: 82.07 % | M27: 0.00086805556
A28: 46068 | B28: GOTYME | C28: 8 | D28: 2980 | E28: 6 | F28: 6 | G28: 2480 | H28: 5 | I28: 4 | J28: 2280 | K28: 75.00 % | L28: 1.32 % | M28: 0.00065972222
A29: 46068 | B29: QRPH | C29: 33 | D29: 4520 | E29: 20 | F29: 22 | G29: 3120 | H29: 14 | I29: 3 | J29: 300 | K29: 66.66 % | L29: 1.66 % | M29: 0.00075231481
A30: 46068 | B30: Maya | C30: 177 | D30: 21445 | E30: 121 | F30: 150 | G30: 17255 | H30: 109 | I30: 51 | J30: 5420 | K30: 84.74 % | L30: 9.22 % | M30: 0.00065972222
A31: 46068 | B31: GCashQR | C31: 124 | D31: 21716 | E31: 58 | F31: 59 | G31: 10656 | H31: 36 | I31: 18 | J31: 2735 | K31: 47.58 % | L31: 5.69 % | M31: 0.00085648148
A33: 46069 | B33: GCash | C33: 1232 | D33: 190784 | E33: 756 | F33: 907 | G33: 137585 | H33: 688 | I33: 339 | J33: 49268 | K33: 73.62 % | L33: 85.21 % | M33: 0.0009837963
A34: 46069 | B34: QRPH | C34: 63 | D34: 11471 | E34: 19 | F34: 24 | G34: 3026 | H34: 17 | I34: 8 | J34: 900 | K34: 38.09 % | L34: 1.87 % | M34: 0.00074074074
... A37: 46069 | B37: GCashQR | C37: 76 | D37: 10714 | E37: 52 | F37: 38 | G37: 5000 | H37: 30 | I37: 16 | J37: 2300 | K37: 50.00 % | L37: 3.09 % | M37: 0.00072916667
A39: 46070 | B39: GOTYME | C39: 22 | D39: 5800 | E39: 21 | F39: 20 | G39: 5600 | H39: 20 | I39: 20 | J39: 5600 | K39: 90.9 | L39: 3.38 | M39: 0.000625
A40: 46070 | B40: QRPH | C40: 30 | D40: 6485 | E40: 21 | F40: 28 | G40: 6185 | H40: 21 | I40: 5 | J40: 1355 | K40: 93.33 | L40: 3.73 | M40: 0.00056712963
A41: 46070 | B41: GCash | C41: 1081 | D41: 166483 | E41: 708 | F41: 859 | G41: 136348 | H41: 640 | I41: 306 | J41: 44430 | K41: 79.46 | L41: 82.3 | M41: 0.00078703704
A42: 46070 | B42: GCashQR | C42: 53 | D42: 7970 | E42: 43 | F42: 33 | G42: 5050 | H42: 30 | I42: 11 | J42: 1650 | K42: 62.26 | L42: 3.04 | M42: 0.00077546296
A43: 46070 | B43: Maya | C43: 138 | D43: 15328 | E43: 105 | F43: 112 | G43: 12483 | H43: 91 | I43: 36 | J43: 4696 | K43: 81.15 | L43: 7.53 | M43: 0.00068287037
A45: 46071 | B45: GOTYME | C45: 58 | D45: 30880 | E45: 28 | F45: 34 | G45: 10280 | H45: 26 | I45: 24 | J45: 9280 | K45: 58.62 % | L45: 7.84 % | M45: 0.00082175926
A46: 46071 | B46: QRPH | C46: 50 | D46: 9007 | E46: 26 | F46: 46 | G46: 8387 | H46: 25 | I46: 13 | J46: 2317 | K46: 92.00 % | L46: 6.39 % | M46: 0.00064814815
A47: 46071 | B47: GCash | C47: 888 | D47: 122582 | E47: 571 | F47: 699 | G47: 94531 | H47: 529 | I47: 209 | J47: 26798 | K47: 78.71 % | L47: 72.11 % | M47: 0.00076388889
A48: 46071 | B48: GCashQR | C48: 50 | D48: 12006 | E48: 35 | F48: 29 | G48: 6828 | H48: 22 | I48: 9 | J48: 1430 | K48: 58.00 % | L48: 5.20 % | M48: 0.0005787037
A49: 46071 | B49: Maya | C49: 140 | D49: 15164 | E49: 101 | F49: 102 | G49: 11062 | H49: 86 | I49: 36 | J49: 3239 | K49: 72.85 % | L49: 8.43 % | M49: 0.00064814815
...

Sheet jiliarena-每日报告
A2: 日期： | B2: 46065 | C2: =B2-1 -> 46064
B4: Date | C4: jiliarena | D4: GCash | E4: QRPH | F4: GCashQR | G4: Maya | H4: GRABPAY | I4: Online Banking | J4: USDT | K4: GOTYME | L4: GCASHPAY | M4: 加总 | N4: 差额
B5: =B2 -> 46065 | C5: 申请笔数 | D5: =SUMIFS('渠道充值成功率_底稿'!$C:$C,'渠道充值成功率_底稿'!$A:$A,$B$5,'渠道充值成功率_底稿'!$B:$B,D$4) -> 3522 | E5: =SUMIFS('渠道充值成功率_底稿'!$C:$C,'渠道充值成功率_底稿'!$A:$A,$B$5,'渠道充值成功率_底稿'!$B:$B,E$4) -> 176 | F5: =SUMIFS('渠道充值成功率_底稿'!$C:$C,'渠道充值成功率_底稿'!$A:$A,$B$5,'渠道充值成功率_底稿'!$B:$B,F$4) -> 238 | G5: =SUMIFS('渠道充值成功率_底稿'!$C:$C,'渠道充值成功率_底稿'!$A:$A,$B$5,'渠道充值成功率_底稿'!$B:$B,G$4) -> 609 | H5: =SUMIFS('渠道充值成功率_底稿'!$C:$C,'渠道充值成功率_底稿'!$A:$A,$B$5,'渠道充值成功率_底稿'!$B:$B,H$4) -> 0 | I5: =SUMIFS('渠道充值成功率_底稿'!$C:$C,'渠道充值成功率_底稿'!$A:$A,$B$5,'渠道充值成功率_底稿'!$B:$B,I$4) -> 0 | J5: =SUMIFS('渠道充值成功率_底稿'!$C:$C,'渠道充值成功率_底稿'!$A:$A,$B$5,'渠道充值成功率_底稿'!$B:$B,J$4) -> 0 | K5: =SUMIFS('渠道充值成功率_底稿'!$C:$C,'渠道充值成功率_底稿'!$A:$A,$B$5,'渠道充值成功率_底稿'!$B:$B,K$4) -> 17 | L5: =SUMIFS('渠道充值成功率_底稿'!$C:$C,'渠道充值成功率_底稿'!$A:$A,$B$5,'渠道充值成功率_底稿'!$B:$B,L$4) -> 0 | M5: =SUM(D5:L5) -> 4562 | N5: =M5-M13 -> 4145
C6: 到账笔数 | D6: =SUMIFS('渠道充值成功率_底稿'!$F:$F,'渠道充值成功率_底稿'!$A:$A,$B5,'渠道充值成功率_底稿'!$B:$B,D$4) -> 2658 | E6: =SUMIFS('渠道充值成功率_底稿'!$F:$F,'渠道充值成功率_底稿'!$A:$A,$B5,'渠道充值成功率_底稿'!$B:$B,E$4) -> 151 | F6: =SUMIFS('渠道充值成功率_底稿'!$F:$F,'渠道充值成功率_底稿'!$A:$A,$B5,'渠道充值成功率_底稿'!$B:$B,F$4) -> 132 | G6: =SUMIFS('渠道充值成功率_底稿'!$F:$F,'渠道充值成功率_底稿'!$A:$A,$B5,'渠道充值成功率_底稿'!$B:$B,G$4) -> 487 | H6: =SUMIFS('渠道充值成功率_底稿'!$F:$F,'渠道充值成功率_底稿'!$A:$A,$B5,'渠道充值成功率_底稿'!$B:$B,H$4) -> 0 | I6: =SUMIFS('渠道充值成功率_底稿'!$F:$F,'渠道充值成功率_底稿'!$A:$A,$B5,'渠道充值成功率_底稿'!$B:$B,I$4) -> 0 | J6: =SUMIFS('渠道充值成功率_底稿'!$F:$F,'渠道充值成功率_底稿'!$A:$A,$B5,'渠道充值成功率_底稿'!$B:$B,J$4) -> 0 | K6: =SUMIFS('渠道充值成功率_底稿'!$F:$F,'渠道充值成功率_底稿'!$A:$A,$B5,'渠道充值成功率_底稿'!$B:$B,K$4) -> 16 | L6: =SUMIFS('渠道充值成功率_底稿'!$F:$F,'渠道充值成功率_底稿'!$A:$A,$B5,'渠道充值成功率_底稿'!$B:$B,L$4) -> 0 | M6: =SUM(D6:L6) -> 3444 | N6: =M6-M14 -> 3113
C7: 笔数成功率 | D7: =IFERROR(ROUND(D6/D5,6),"0") -> 0.754685 | E7: =IFERROR(ROUND(E6/E5,6),"0") -> 0.857955 | F7: =IFERROR(ROUND(F6/F5,6),"0") -> 0.554622 | G7: =IFERROR(ROUND(G6/G5,6),"0") -> 0.799672 | H7: =IFERROR(ROUND(H6/H5,6),"0") -> 0 | I7: =IFERROR(ROUND(I6/I5,6),"0") -> 0 | J7: =IFERROR(ROUND(J6/J5,6),"0") -> 0 | K7: =IFERROR(ROUND(K6/K5,6),"0") -> 0.941176 | L7: =IFERROR(ROUND(L6/L5,6),"0") -> 0 | M7: =M6/M5 -> 0.75493205 | N7: =M7-M15 -> -0.038832941
C8: 申请金额 | D8: =SUMIFS('渠道充值成功率_底稿'!$D:$D,'渠道充值成功率_底稿'!$A:$A,$B$2,'渠道充值成功率_底稿'!$B:$B,D$4) -> 594748 | E8: =SUMIFS('渠道充值成功率_底稿'!$D:$D,'渠道充值成功率_底稿'!$A:$A,$B$2,'渠道充值成功率_底稿'!$B:$B,E$4) -> 41417 | F8: =SUMIFS('渠道充值成功率_底稿'!$D:$D,'渠道充值成功率_底稿'!$A:$A,$B$2,'渠道充值成功率_底稿'!$B:$B,F$4) -> 45503 | G8: =SUMIFS('渠道充值成功率_底稿'!$D:$D,'渠道充值成功率_底稿'!$A:$A,$B$2,'渠道充值成功率_底稿'!$B:$B,G$4) -> 114956 | H8: =SUMIFS('渠道充值成功率_底稿'!$D:$D,'渠道充值成功率_底稿'!$A:$A,$B$2,'渠道充值成功率_底稿'!$B:$B,H$4) -> 0 | I8: =SUMIFS('渠道充值成功率_底稿'!$D:$D,'渠道充值成功率_底稿'!$A:$A,$B$2,'渠道充值成功率_底稿'!$B:$B,I$4) -> 0 | J8: =SUMIFS('渠道充值成功率_底稿'!$D:$D,'渠道充值成功率_底稿'!$A:$A,$B$2,'渠道充值成功率_底稿'!$B:$B,J$4) -> 0 | K8: =SUMIFS('渠道充值成功率_底稿'!$D:$D,'渠道充值成功率_底稿'!$A:$A,$B$2,'渠道充值成功率_底稿'!$B:$B,K$4) -> 3970 | L8: =SUMIFS('渠道充值成功率_底稿'!$D:$D,'渠道充值成功率_底稿'!$A:$A,$B$2,'渠道充值成功率_底稿'!$B:$B,L$4) -> 0 | M8: =SUM(D8:L8) -> 800594 | N8: =M8-M16 -> 738711
C9: 到账金额 | D9: =SUMIFS('渠道充值成功率_底稿'!$G:$G,'渠道充值成功率_底稿'!$A:$A,$B$2,'渠道充值成功率_底稿'!$B:$B,D$4) -> 393917 | E9: =SUMIFS('渠道充值成功率_底稿'!$G:$G,'渠道充值成功率_底稿'!$A:$A,$B$2,'渠道充值成功率_底稿'!$B:$B,E$4) -> 35097 | F9: =SUMIFS('渠道充值成功率_底稿'!$G:$G,'渠道充值成功率_底稿'!$A:$A,$B$2,'渠道充值成功率_底稿'!$B:$B,F$4) -> 26162 | G9: =SUMIFS('渠道充值成功率_底稿'!$G:$G,'渠道充值成功率_底稿'!$A:$A,$B$2,'渠道充值成功率_底稿'!$B:$B,G$4) -> 89690 | H9: =SUMIFS('渠道充值成功率_底稿'!$G:$G,'渠道充值成功率_底稿'!$A:$A,$B$2,'渠道充值成功率_底稿'!$B:$B,H$4) -> 0 | I9: =SUMIFS('渠道充值成功率_底稿'!$G:$G,'渠道充值成功率_底稿'!$A:$A,$B$2,'渠道充值成功率_底稿'!$B:$B,I$4) -> 0 | J9: =SUMIFS('渠道充值成功率_底稿'!$G:$G,'渠道充值成功率_底稿'!$A:$A,$B$2,'渠道充值成功率_底稿'!$B:$B,J$4) -> 0 | K9: =SUMIFS('渠道充值成功率_底稿'!$G:$G,'渠道充值成功率_底稿'!$A:$A,$B$2,'渠道充值成功率_底稿'!$B:$B,K$4) -> 3870 | L9: =SUMIFS('渠道充值成功率_底稿'!$G:$G,'渠道充值成功率_底稿'!$A:$A,$B$2,'渠道充值成功率_底稿'!$B:$B,L$4) -> 0 | M9: =SUM(D9:L9) -> 548736 | N9: =M9-M17 -> 498023
C10: 金额成功率 | D10: =IFERROR(ROUND(D9/D8,6),"0") -> 0.662326 | E10: =IFERROR(ROUND(E9/E8,6),"0") -> 0.847406 | F10: =IFERROR(ROUND(F9/F8,6),"0") -> 0.574951 | G10: =IFERROR(ROUND(G9/G8,6),"0") -> 0.780212 | H10: =IFERROR(ROUND(H9/H8,6),"0") -> 0 | I10: =IFERROR(ROUND(I9/I8,6),"0") -> 0 | J10: =IFERROR(ROUND(J9/J8,6),"0") -> 0 | K10: =IFERROR(ROUND(K9/K8,6),"0") -> 0.974811 | L10: =IFERROR(ROUND(L9/L8,6),"0") -> 0 | M10: =M9/M8 -> 0.68541108 | N10: =M10-M18 -> -0.134087
B12: Date | C12: jiliarena | D12: GCash | E12: QRPH | F12: GCashQR | G12: Maya | H12: GRABPAY | I12: Online Banking | J12: USDT | K12: GOTYME | L12: GCASHPAY | M12: 加总
B13: =B2-1 -> 46064 | C13: 申请笔数 | D13: =SUMIFS('渠道充值成功率_底稿'!$C:$C,'渠道充值成功率_底稿'!$A:$A,$B$13,'渠道充值成功率_底稿'!$B:$B,D$4) -> 336 | E13: =SUMIFS('渠道充值成功率_底稿'!$C:$C,'渠道充值成功率_底稿'!$A:$A,$B$13,'渠道充值成功率_底稿'!$B:$B,E$4) -> 15 | F13: =SUMIFS('渠道充值成功率_底稿'!$C:$C,'渠道充值成功率_底稿'!$A:$A,$B$13,'渠道充值成功率_底稿'!$B:$B,F$4) -> 7 | G13: =SUMIFS('渠道充值成功率_底稿'!$C:$C,'渠道充值成功率_底稿'!$A:$A,$B$13,'渠道充值成功率_底稿'!$B:$B,G$4) -> 57 | H13: =SUMIFS('渠道充值成功率_底稿'!$C:$C,'渠道充值成功率_底稿'!$A:$A,$B$13,'渠道充值成功率_底稿'!$B:$B,H$4) -> 0 | I13: =SUMIFS('渠道充值成功率_底稿'!$C:$C,'渠道充值成功率_底稿'!$A:$A,$B$13,'渠道充值成功率_底稿'!$B:$B,I$4) -> 0 | J13: =SUMIFS('渠道充值成功率_底稿'!$C:$C,'渠道充值成功率_底稿'!$A:$A,$B$13,'渠道充值成功率_底稿'!$B:$B,J$4) -> 0 | K13: =SUMIFS('渠道充值成功率_底稿'!$C:$C,'渠道充值成功率_底稿'!$A:$A,$B$13,'渠道充值成功率_底稿'!$B:$B,K$4) -> 2 | L13: =SUMIFS('渠道充值成功率_底稿'!$C:$C,'渠道充值成功率_底稿'!$A:$A,$B$13,'渠道充值成功率_底稿'!$B:$B,L$4) -> 0 | M13: =SUM(D13:L13) -> 417
C14: 到账笔数 | D14: =SUMIFS('渠道充值成功率_底稿'!$F:$F,'渠道充值成功率_底稿'!$A:$A,$B13,'渠道充值成功率_底稿'!$B:$B,D$4) -> 264 | E14: =SUMIFS('渠道充值成功率_底稿'!$F:$F,'渠道充值成功率_底稿'!$A:$A,$B13,'渠道充值成功率_底稿'!$B:$B,E$4) -> 14 | F14: =SUMIFS('渠道充值成功率_底稿'!$F:$F,'渠道充值成功率_底稿'!$A:$A,$B13,'渠道充值成功率_底稿'!$B:$B,F$4) -> 6 | G14: =SUMIFS('渠道充值成功率_底稿'!$F:$F,'渠道充值成功率_底稿'!$A:$A,$B13,'渠道充值成功率_底稿'!$B:$B,G$4) -> 45 | H14: =SUMIFS('渠道充值成功率_底稿'!$F:$F,'渠道充值成功率_底稿'!$A:$A,$B13,'渠道充值成功率_底稿'!$B:$B,H$4) -> 0 | I14: =SUMIFS('渠道充值成功率_底稿'!$F:$F,'渠道充值成功率_底稿'!$A:$A,$B13,'渠道充值成功率_底稿'!$B:$B,I$4) -> 0 | J14: =SUMIFS('渠道充值成功率_底稿'!$F:$F,'渠道充值成功率_底稿'!$A:$A,$B13,'渠道充值成功率_底稿'!$B:$B,J$4) -> 0 | K14: =SUMIFS('渠道充值成功率_底稿'!$F:$F,'渠道充值成功率_底稿'!$A:$A,$B13,'渠道充值成功率_底稿'!$B:$B,K$4) -> 2 | L14: =SUMIFS('渠道充值成功率_底稿'!$F:$F,'渠道充值成功率_底稿'!$A:$A,$B13,'渠道充值成功率_底稿'!$B:$B,L$4) -> 0 | M14: =SUM(D14:L14) -> 331
C15: 笔数成功率 | D15: =IFERROR(ROUND(D14/D13,6),"0") -> 0.785714 | E15: =IFERROR(ROUND(E14/E13,6),"0") -> 0.933333 | F15: =IFERROR(ROUND(F14/F13,6),"0") -> 0.857143 | G15: =IFERROR(ROUND(G14/G13,6),"0") -> 0.789474 | H15: =IFERROR(ROUND(H14/H13,6),"0") -> 0 | I15: =IFERROR(ROUND(I14/I13,6),"0") -> 0 | J15: =IFERROR(ROUND(J14/J13,6),"0") -> 0 | K15: =IFERROR(ROUND(K14/K13,6),"0") -> 1 | L15: =IFERROR(ROUND(L14/L13,6),"0") -> 0 | M15: =M14/M13 -> 0.79376499
C16: 申请金额 | D16: =SUMIFS('渠道充值成功率_底稿'!$D:$D,'渠道充值成功率_底稿'!$A:$A,$B$13,'渠道充值成功率_底稿'!$B:$B,D$4) -> 45098 | E16: =SUMIFS('渠道充值成功率_底稿'!$D:$D,'渠道充值成功率_底稿'!$A:$A,$B$13,'渠道充值成功率_底稿'!$B:$B,E$4) -> 9270 | F16: =SUMIFS('渠道充值成功率_底稿'!$D:$D,'渠道充值成功率_底稿'!$A:$A,$B$13,'渠道充值成功率_底稿'!$B:$B,F$4) -> 700 | G16: =SUMIFS('渠道充值成功率_底稿'!$D:$D,'渠道充值成功率_底稿'!$A:$A,$B$13,'渠道充值成功率_底稿'!$B:$B,G$4) -> 6415 | H16: =SUMIFS('渠道充值成功率_底稿'!$D:$D,'渠道充值成功率_底稿'!$A:$A,$B$13,'渠道充值成功率_底稿'!$B:$B,H$4) -> 0 | I16: =SUMIFS('渠道充值成功率_底稿'!$D:$D,'渠道充值成功率_底稿'!$A:$A,$B$13,'渠道充值成功率_底稿'!$B:$B,I$4) -> 0 | J16: =SUMIFS('渠道充值成功率_底稿'!$D:$D,'渠道充值成功率_底稿'!$A:$A,$B$13,'渠道充值成功率_底稿'!$B:$B,J$4) -> 0 | K16: =SUMIFS('渠道充值成功率_底稿'!$D:$D,'渠道充值成功率_底稿'!$A:$A,$B$13,'渠道充值成功率_底稿'!$B:$B,K$4) -> 400 | L16: =SUMIFS('渠道充值成功率_底稿'!$D:$D,'渠道充值成功率_底稿'!$A:$A,$B$13,'渠道充值成功率_底稿'!$B:$B,L$4) -> 0 | M16: =SUM(D16:L16) -> 61883
C17: 到账金额 | D17: =SUMIFS('渠道充值成功率_底稿'!$G:$G,'渠道充值成功率_底稿'!$A:$A,$B$13,'渠道充值成功率_底稿'!$B:$B,D$4) -> 34978 | E17: =SUMIFS('渠道充值成功率_底稿'!$G:$G,'渠道充值成功率_底稿'!$A:$A,$B$13,'渠道充值成功率_底稿'!$B:$B,E$4) -> 9070 | F17: =SUMIFS('渠道充值成功率_底稿'!$G:$G,'渠道充值成功率_底稿'!$A:$A,$B$13,'渠道充值成功率_底稿'!$B:$B,F$4) -> 600 | G17: =SUMIFS('渠道充值成功率_底稿'!$G:$G,'渠道充值成功率_底稿'!$A:$A,$B$13,'渠道充值成功率_底稿'!$B:$B,G$4) -> 5665 | H17: =SUMIFS('渠道充值成功率_底稿'!$G:$G,'渠道充值成功率_底稿'!$A:$A,$B$13,'渠道充值成功率_底稿'!$B:$B,H$4) -> 0 | I17: =SUMIFS('渠道充值成功率_底稿'!$G:$G,'渠道充值成功率_底稿'!$A:$A,$B$13,'渠道充值成功率_底稿'!$B:$B,I$4) -> 0 | J17: =SUMIFS('渠道充值成功率_底稿'!$G:$G,'渠道充值成功率_底稿'!$A:$A,$B$13,'渠道充值成功率_底稿'!$B:$B,J$4) -> 0 | K17: =SUMIFS('渠道充值成功率_底稿'!$G:$G,'渠道充值成功率_底稿'!$A:$A,$B$13,'渠道充值成功率_底稿'!$B:$B,K$4) -> 400 | L17: =SUMIFS('渠道充值成功率_底稿'!$G:$G,'渠道充值成功率_底稿'!$A:$A,$B$13,'渠道充值成功率_底稿'!$B:$B,L$4) -> 0 | M17: =SUM(D17:L17) -> 50713
C18: 金额成功率 | D18: =IFERROR(ROUND(D17/D16,6),"0") -> 0.7756 | E18: =IFERROR(ROUND(E17/E16,6),"0") -> 0.978425 | F18: =IFERROR(ROUND(F17/F16,6),"0") -> 0.857143 | G18: =IFERROR(ROUND(G17/G16,6),"0") -> 0.883087 | H18: =IFERROR(ROUND(H17/H16,6),"0") -> 0 | I18: =IFERROR(ROUND(I17/I16,6),"0") -> 0 | J18: =IFERROR(ROUND(J17/J16,6),"0") -> 0 | K18: =IFERROR(ROUND(K17/K16,6),"0") -> 1 | L18: =IFERROR(ROUND(L17/L16,6),"0") -> 0 | M18: =M17/M16 -> 0.81949809
B22: =MONTH(B2)&"/"&DAY(B2) &" WP充值分析" -> 2/12 WP充值分析
B24: ="总充值申请笔数："&TEXT($M$5,"0,000") -> 总充值申请笔数：4,562
B25: ="总充值到帐笔数："&TEXT($M$6,"0,000") -> 总充值到帐笔数：3,444
B26: ="总笔数成功率："&TEXT($M$6/$M$5,"0.00%") -> 总笔数成功率：75.49%
B27: ="总充值申请金额："&TEXT($M$8,"0,000") -> 总充值申请金额：800,594
B28: ="总充值到帐金额："&TEXT($M$9,"0,000") -> 总充值到帐金额：548,736
B29: ="总笔数成功率："&TEXT($M$9/$M$8,"0.00%") -> 总笔数成功率：68.54%
B30: ="总充值申请人数："&text(sumifs('渠道充值成功率_底稿'!$E:$E,'渠道充值成功率_底稿'!$A:$A,$B$2),"0,000") -> 总充值申请人数：3,007
B31: ="总充值到帐人数："&text(sumifs('渠道充值成功率_底稿'!$H:$H,'渠道充值成功率_底稿'!$A:$A,$B$2),"0,000") -> 总充值到帐人数：2,799
B34: ="对比前日充值申请笔数"&IF(M6-M14>0,"增长："&TEXT(M5-M13,"000"),"减少："&TEXT(M5-M13,"000")) -> 对比前日充值申请笔数增长：4145
B35: ="对比前日充值到帐笔数"&IF(M6-M14>0,"增长："&TEXT(M6-M14,"000"),"减少："&TEXT(M6-M14,"000")) -> 对比前日充值到帐笔数增长：3113
B36: ="对比前日充值申请金额"&IF(M9-M17>0,"增长："&TEXT(M8-M16,"0,000"),"减少："&TEXT(M8-M16,"0,000")) -> 对比前日充值申请金额增长：738,711
B37: ="对比前日充值到帐金额"&IF(M9-M17>0,"增长："&TEXT(M9-M17,"0,000"),"减少："&TEXT(M9-M17,"0,000")) -> 对比前日充值到帐金额增长：498,023
B38: ="对比前日充值金额成功率"&IF(((M9/M8)-(M17/M16))>0,"增长："&TEXT(((M9/M8)-(M17/M16)),"0.00%"),"减少："&TEXT(((M9/M8)-(M17/M16)),"0.00%")) -> 对比前日充值金额成功率减少：-13.41%
B39: ="对比前日充值申请人数"&text(if(sumifs('渠道充值成功率_底稿'!$E:$E,'渠道充值成功率_底稿'!$A:$A,$B$2)-sumifs('渠道充值成功率_底稿'!$E:$E,'渠道充值成功率_底稿'!$A:$A,($B$2-1))>0,"增加："&sumifs('渠道充值成功率_底稿'!$E:$E,'渠道充值成功率_底稿'!$A:$A,$B$2)-sumifs('渠道充值成功率_底稿'!$E:$E,'渠道充值成功率_底稿'!$A:$A,($B$2-1)),"减少："&sumifs('渠道充值成功率_底稿'!$E:$E,'渠道充值成功率_底稿'!$A:$A,$B$2)-sumifs('渠道充值成功率_底稿'!$E:$E,'渠道充值成功率_底稿'!$A:$A,($B$2-1))),"0,000") -> 对比前日充值申请人数增加：2681
B40: ="对比前日充值到帐人数"&text(if(sumifs('渠道充值成功率_底稿'!$H:$H,'渠道充值成功率_底稿'!$A:$A,$B$2)-sumifs('渠道充值成功率_底稿'!$H:$H,'渠道充值成功率_底稿'!$A:$A,($B$2-1))>0,"增加："&sumifs('渠道充值成功率_底稿'!$H:$H,'渠道充值成功率_底稿'!$A:$A,$B$2)-sumifs('渠道充值成功率_底稿'!$H:$H,'渠道充值成功率_底稿'!$A:$A,($B$2-1)),"减少："&sumifs('渠道充值成功率_底稿'!$H:$H,'渠道充值成功率_底稿'!$A:$A,$B$2)-sumifs('渠道充值成功率_底稿'!$H:$H,'渠道充值成功率_底稿'!$A:$A,($B$2-1))),"0,000") -> 对比前日充值到帐人数增加：2504
B42: {="主要充值金额渠道："&index($C$4:$L$10,1,match(max($C$9:$L$9),C9:L9,0))} -> 主要充值金额渠道：GCash | G42: {=index($C$4:$L$10,1,match(max($C$9:$L$9),C9:L9,0))} -> GCash
B43: ="充值金额："&text(max($C$9:$L9),"0,000") -> 充值金额：393,917
B44: {="充值笔数："&text(index($C$4:$L$10,3,match(G42,$C$4:$L$4,0)),"0,000")} -> 充值笔数：2,658
B45: {="成功率："&text(index($C$4:$L$10,7,match(G42,$C$4:$L$4,0)),"0.00%")} -> 成功率：66.23%
B46: {="充值成功率最低渠道："&index($C$4:$L$10,1,match(MIN($C$9:$L$9),C9:L9,0))} -> 充值成功率最低渠道：GRABPAY | G46: {=index($C$4:$L$10,1,match(MIN($C$9:$L$9),C9:L9,0))} -> GRABPAY
B47: ="充值金额："&text(MIN($C$9:$L9),"0,000") -> 充值金额：0,000
B48: {="充值笔数："&text(index($C$4:$L$10,3,match(G46,$C$4:$L$4,0)),"0,000")} -> 充值笔数：0,000
B49: {="成功率："&text(index($C$4:$L$10,7,match(G46,$C$4:$L$4,0)),"0.00%")} -> 成功率：0.00%
A82: =MONTH(B2)&"月"&DAY(B2) &"日"&" jiliarena 活动红利分析" -> 2月12日 jiliarena 活动红利分析
...

Sheet jiliarena_日报_底稿
B1: WP
A2: 报表管理-活跃用户分析 | P2: 报表管理-平台损益
A3: 日期 | B3: 总账号 | C3: 登录人数 | D3: 投注人数 | E3: 存款人数 | F3: 提款人数 | G3: 注册人数 | H3: 首投人数 | I3: 首充人数 | J3: 首提人数 | K3: 彩金领取人数 | L3: 充提差 | M3: 日充值 | N3: ARPU | P3: 日期 | Q3: 平台毛利 | R3: 充值 | S3: 提款金额 | T3: 充值人数 | U3: 提现人数 | V3: 充提差 | W3: 玩家充值手续费 | X3: 玩家提款手续费 | Y3: 渠道手续费 | Z3: 手续费 | AA3: 电子投注 | AB3: 电子有效投注 | AC3: 电子中奖 | AD3: 电子红利 | AE3: 电子返水 | AF3: 电子邀请返佣 | AG3: 电子代理返点 | AH3: 电子代理日工资 | AI3: 电子代理佣金 | AJ3: 电子代理分红 | AK3: 电子盈亏 | AL3: 真人投注 | AM3: 真人有效投注 | AN3: 真人中奖 | AO3: 真人红利 | AP3: 真人返水 | AQ3: 真人邀请返佣 | AR3: 真人代理返点 | AS3: 真人代理日工资 | AT3: 真人代理佣金 | AU3: 真人代理分红 | AV3: 真人盈亏 | AW3: 彩票投注 | AX3: 彩票有效投注 | AY3: 彩票中奖 | AZ3: 彩票红利 | BA3: 彩票返水 | BB3: 彩票邀请返佣 | BC3: 彩票代理返点 | BD3: 平台佣金 | BE3: 彩票代理日工资 | BF3: 彩票代理佣金 | BG3: 彩票代理分红 | BH3: 彩票盈亏 | BI3: 棋牌输额 | BJ3: 棋牌有效投注 | BK3: 棋牌赢额 | BL3: 棋牌红利 | BM3: 棋牌返水 | BN3: 棋牌邀请返佣 | BO3: 棋牌代理返点 | BP3: 棋牌代理日工资 | BQ3: 棋牌代理佣金 | BR3: 棋牌代理分红 | BS3: 棋牌盈亏 | BT3: 捕鱼投注 | BU3: 捕鱼有效投注 | BV3: 捕鱼中奖 | BW3: 捕鱼红利 | BX3: 捕鱼玩家返水 | BY3: 捕鱼邀请返佣 | BZ3: 捕鱼代理返点 | CA3: 捕鱼代理日工资 | CB3: 捕鱼代理佣金 | CC3: 捕鱼代理分红 | CD3: 捕鱼盈亏 | CE3: 体育投注 | CF3: 体育有效投注 | CG3: 体育中奖 | CH3: 体育红利 | CI3: 体育玩家返水 | CJ3: 体育邀请返佣 | CK3: 体育代理返点 | CL3: 体育代理日工资 | CM3: 体育代理佣金 | CN3: 体育代理分红 | CO3: 体育盈亏 | CP3: 盘口彩票投注 | CQ3: 盘口彩票有效投注 | CR3: 盘口彩票中奖 | CS3: 盘口彩票红利 | CT3: 盘口彩票玩家返水 | CU3: 盘口彩邀请返佣 | CV3: 盘口彩票代理返点 | CW3: 平台佣金 | CX3: 盘口彩票代理日工资 | CY3: 盘口彩票代理佣金 | CZ3: 盘口彩票代理分红 | DA3: 盘口彩票盈亏 | DB3: 开分 | DC3: 洗分 | DD3: 中心钱包红利 | DE3: 综合性分红 | DF3: 综合佣金 | DG3: 综合日工资 | DH3: 直播送礼 | DI3: 邀请奖励 | DJ3: 成就奖励 | DK3: 充值返佣 | DL3: 手续费返还 | DM3: 其他 | DN3: 中心开始馀额 | DO3: 中心开始浮动余额 | DP3: 开始余额 | DQ3: 中心结算馀额 | DR3: 中心结算浮动余额 | DS3: 结算余额
A4: =A5+1 -> 46081 | B4: 45101 | C4: 3515 | D4: 2404 | E4: 515 | F4: 98 | G4: 717 | H4: 438 | I4: 231 | J4: 44 | K4: 2936 | L4: 35409 | M4: 103745 | N4: 201.44 | P4: =P5+1 -> 46081 | Q4: 10242.68 | R4: 103745 | S4: 68336 | T4: 515 | U4: 98 | V4: 35409 | W4: 0 | X4: 0 | Y4: 1632.09 | Z4: -1632.09 | AA4: 893340.12 | AB4: 831495.63 | AC4: 864325.06 | AD4: 7942.1 | AE4: 2245.66 | AF4: 26.8151 | AG4: 0 | AH4: 0 | AI4: 0 | AJ4: 0 | AK4: 18800.485 | AL4: 7245.31 | AM4: 7020.31 | AN4: 8340 | AO4: 0 | AP4: 5.45 | AQ4: 0.175 | AR4: 0 | AS4: 0 | AT4: 0 | AU4: 0 | AV4: -1100.315 | AW4: 0 | AX4: 0 | AY4: 0 | AZ4: 0 | BA4: 0 | BB4: 0 | BC4: 0 | BD4: 0 | BE4: 0 | BF4: 0 | BG4: 0 | BH4: 0 | BI4: 1 | BJ4: 0.5 | BK4: 0 | BL4: 0 | BM4: 0 | BN4: 0 | BO4: 0 | BP4: 0 | BQ4: 0 | BR4: 0 | BS4: 1 | BT4: 12950.2 | BU4: 12930.2 | BV4: 13845.05 | BW4: 0 | BX4: 0 | BY4: 0 | BZ4: 0 | CA4: 0 | CB4: 0 | CC4: 0 | CD4: -894.85 | CE4: 0 | CF4: 0 | CG4: 0 | CH4: 0 | CI4: 0 | CJ4: 0 | CK4: 0 | CL4: 0 | CM4: 0 | CN4: 0 | CO4: 0 | CP4: 3 | CQ4: 3 | CR4: 0 | CS4: 0 | CT4: 0 | CU4: 0 | CV4: 0 | CW4: 0 | CX4: 0 | CY4: 0 | CZ4: 0 | DA4: 3 | DB4: 0 | DC4: 0 | DD4: 4900.49 | DE4: 0 | DF4: 0 | DG4: 0 | DH4: 30 | DI4: 0 | DJ4: 4.06 | DK4: 0 | DL4: 0 | DM4: -4934.55 | DN4: 96202.404 | DO4: 448009.19 | DP4: 96202.404 | DQ4: 113632.87 | DR4: 460446.19 | DS4: 113632.87
A5: =A6+1 -> 46080 | B5: 44226 | C5: 2890 | D5: 2122 | E5: 352 | F5: 92 | G5: 268 | H5: 203 | I5: 89 | J5: 40 | K5: 2466 | L5: 1319 | M5: 94962 | N5: 269.77 | P5: =P6+1 -> 46080 | Q5: -2378.5037 | R5: 94962 | S5: 93643 | T5: 352 | U5: 92 | V5: 1319 | W5: 0 | X5: 0 | Y5: 1563.72 | Z5: -1563.72 | AA5: 734752.98 | AB5: 685755.37 | AC5: 724516.44 | AD5: 4628.2 | AE5: 2559.04 | AF5: 38.0387 | AG5: 0 | AH5: 0 | AI5: 0 | AJ5: 0 | AK5: 3011.2563 | AL5: 2734.5 | AM5: 2453.5 | AN5: 1846.5 | AO5: 0 | AP5: 46 | AQ5: 0 | AR5: 0 | AS5: 0 | AT5: 0 | AU5: 0 | AV5: 842 | AW5: 0 | AX5: 0 | AY5: 0 | AZ5: 0 | BA5: 0 | BB5: 0 | BC5: 0 | BD5: 0 | BE5: 0 | BF5: 0 | BG5: 0 | BH5: 0 | BI5: 0 | BJ5: 0 | BK5: 0 | BL5: 0 | BM5: 0.17 | BN5: 0 | BO5: 0 | BP5: 0 | BQ5: 0 | BR5: 0 | BS5: -0.17 | BT5: 4639.9 | BU5: 4639.9 | BV5: 4734.4 | BW5: 0 | BX5: 0 | BY5: 0 | BZ5: 0 | CA5: 0 | CB5: 0 | CC5: 0 | CD5: -94.5 | CE5: 0 | CF5: 0 | CG5: 0 | CH5: 0 | CI5: 0 | CJ5: 0 | CK5: 0 | CL5: 0 | CM5: 0 | CN5: 0 | CO5: 0 | CP5: 2 | CQ5: 2 | CR5: 0 | CS5: 0 | CT5: 0 | CU5: 0 | CV5: 0 | CW5: 0 | CX5: 0 | CY5: 0 | CZ5: 0 | DA5: 2 | DB5: 0 | DC5: 0 | DD5: 4405.3 | DE5: 0 | DF5: 0 | DG5: 0 | DH5: 150 | DI5: 15 | DJ5: 5.07 | DK5: 0 | DL5: 0 | DM5: -4575.37 | DN5: 94316.745 | DO5: 459403.19 | DP5: 94316.745 | DQ5: 96202.404 | DR5: 448009.19 | DS5: 96202.404
A6: =A7+1 -> 46079 | B6: 43919 | C6: 3223 | D6: 2304 | E6: 437 | F6: 108 | G6: 594 | H6: 388 | I6: 172 | J6: 58 | K6: 2635 | L6: 6723 | M6: 96473 | N6: 220.76 | P6: =P7+1 -> 46079 | Q6: -4441.5865 | R6: 96473 | S6: 89750 | T6: 437 | U6: 108 | V6: 6723 | W6: 0 | X6: 0 | Y6: 1502.14 | Z6: -1502.14 | AA6: 821477.24 | AB6: 773582.83 | AC6: 808905.75 | AD6: 8075.7 | AE6: 3055.64 | AF6: 39.4043 | AG6: 0 | AH6: 0 | AI6: 0 | AJ6: 0 | AK6: 1400.7435 | AL6: 18235.59 | AM6: 17330.59 | AN6: 19190 | AO6: 0 | AP6: 20.86 | AQ6: 0 | AR6: 0 | AS6: 0 | AT6: 0 | AU6: 0 | AV6: -975.27 | AW6: 0 | AX6: 0 | AY6: 0 | AZ6: 0 | BA6: 0 | BB6: 0 | BC6: 0 | BD6: 0 | BE6: 0 | BF6: 0 | BG6: 0 | BH6: 0 | BI6: 60 | BJ6: 60 | BK6: 0 | BL6: 0 | BM6: 0 | BN6: 0 | BO6: 0 | BP6: 0 | BQ6: 0 | BR6: 0 | BS6: 60 | BT6: 13524.8 | BU6: 13332 | BV6: 12056.66 | BW6: 0 | BX6: 0 | BY6: 0 | BZ6: 0 | CA6: 0 | CB6: 0 | CC6: 0 | CD6: 1468.14 | CE6: 0 | CF6: 0 | CG6: 0 | CH6: 0 | CI6: 0 | CJ6: 0 | CK6: 0 | CL6: 0 | CM6: 0 | CN6: 0 | CO6: 0 | CP6: 1 | CQ6: 1 | CR6: 0 | CS6: 0 | CT6: 0 | CU6: 0 | CV6: 0 | CW6: 0 | CX6: 0 | CY6: 0 | CZ6: 0 | DA6: 1 | DB6: 0 | DC6: 0 | DD6: 4829 | DE6: 0 | DF6: 0 | DG6: 0 | DH6: 60 | DI6: 0 | DJ6: 5.06 | DK6: 0 | DL6: 0 | DM6: -4894.06 | DN6: 96459.381 | DO6: 442980.49 | DP6: 96459.381 | DQ6: 94316.745 | DR6: 459403.19 | DS6: 94316.745
A7: =A8+1 -> 46078 | B7: 43332 | C7: 3611 | D7: 2548 | E7: 481 | F7: 97 | G7: 826 | H7: 488 | I7: 213 | J7: 53 | K7: 2869 | L7: 17282 | M7: 92719 | N7: 192.76 | P7: =P8+1 -> 46078 | Q7: -1655.4399 | R7: 92719 | S7: 75437 | T7: 481 | U7: 97 | V7: 17282 | W7: 0 | X7: 0 | Y7: 1490.23 | Z7: -1490.23 | AA7: 840574.91 | AB7: 789677.61 | AC7: 823468.45 | AD7: 7556.2 | AE7: 3869.24 | AF7: 40.7879 | AG7: 0 | AH7: 0 | AI7: 0 | AJ7: 0 | AK7: 5640.2271 | AL7: 15722.08 | AM7: 15443.58 | AN7: 15147.22 | AO7: 0 | AP7: 37.62 | AQ7: 0 | AR7: 0 | AS7: 0 | AT7: 0 | AU7: 0 | AV7: 537.24 | AW7: 0 | AX7: 0 | AY7: 0 | AZ7: 0 | BA7: 0 | BB7: 0 | BC7: 0 | BD7: 0 | BE7: 0 | BF7: 0 | BG7: 0 | BH7: 0 | BI7: 0 | BJ7: 0 | BK7: 0 | BL7: 0 | BM7: 0 | BN7: 0 | BO7: 0 | BP7: 0 | BQ7: 0 | BR7: 0 | BS7: 0 | BT7: 17582.43 | BU7: 17427.73 | BV7: 18115.62 | BW7: 0 | BX7: 0 | BY7: 0 | BZ7: 0 | CA7: 0 | CB7: 0 | CC7: 0 | CD7: -533.19 | CE7: 100 | CF7: 100 | CG7: 0 | CH7: 0 | CI7: 0 | CJ7: 0 | CK7: 0 | CL7: 0 | CM7: 0 | CN7: 0 | CO7: 100 | CP7: 4 | CQ7: 4 | CR7: 0 | CS7: 0 | CT7: 0 | CU7: 0 | CV7: 0 | CW7: 0 | CX7: 0 | CY7: 0 | CZ7: 0 | DA7: 4 | DB7: 0 | DC7: 0 | DD7: 5682.31 | DE7: 0 | DF7: 0 | DG7: 0 | DH7: 210 | DI7: 15 | DJ7: 6.177 | DK7: 0 | DL7: 0 | DM7: -5913.487 | DN7: 93016.966 | DO7: 488797.49 | DP7: 93016.966 | DQ7: 96459.381 | DR7: 442980.49 | DS7: 96459.381
A8: =A9+1 -> 46077 | B8: 42520 | C8: 3785 | D8: 2686 | E8: 498 | F8: 95 | G8: 707 | H8: 455 | I8: 199 | J8: 50 | K8: 3090 | L8: 61492 | M8: 120843 | N8: 242.65 | P8: =P9+1 -> 46077 | Q8: 45355.231 | R8: 120843 | S8: 59351 | T8: 498 | U8: 95 | V8: 61492 | W8: 0 | X8: 0 | Y8: 1945.67 | Z8: -1945.67 | AA8: 1086922.3 | AB8: 1020854.9 | AC8: 1029615.4 | AD8: 7578.4 | AE8: 2413.28 | AF8: 50.5814 | AG8: 0 | AH8: 0 | AI8: 0 | AJ8: 0 | AK8: 47264.624 | AL8: 14221.23 | AM8: 13642.73 | AN8: 10874.82 | AO8: 0 | AP8: 4.67 | AQ8: 0 | AR8: 0 | AS8: 0 | AT8: 0 | AU8: 0 | AV8: 3341.74 | AW8: 0 | AX8: 0 | AY8: 0 | AZ8: 0 | BA8: 0 | BB8: 0 | BC8: 0 | BD8: 0 | BE8: 0 | BF8: 0 | BG8: 0 | BH8: 0 | BI8: 1 | BJ8: 0.5 | BK8: 0 | BL8: 0 | BM8: 0 | BN8: 0 | BO8: 0 | BP8: 0 | BQ8: 0 | BR8: 0 | BS8: 1 | BT8: 71861.15 | BU8: 71783.85 | BV8: 69691.8 | BW8: 0 | BX8: 0 | BY8: 0 | BZ8: 0 | CA8: 0 | CB8: 0 | CC8: 0 | CD8: 2169.35 | CE8: 2018 | CF8: 1998 | CG8: 1416.17 | CH8: 0 | CI8: 0 | CJ8: 0 | CK8: 0 | CL8: 0 | CM8: 0 | CN8: 0 | CO8: 601.83 | CP8: 2 | CQ8: 2 | CR8: 0 | CS8: 0 | CT8: 0 | CU8: 0 | CV8: 0 | CW8: 0 | CX8: 0 | CY8: 0 | CZ8: 0 | DA8: 2 | DB8: 0 | DC8: 0 | DD8: 5658.37 | DE8: 0 | DF8: 0 | DG8: 0 | DH8: 360 | DI8: 55 | DJ8: 6.273 | DK8: 0 | DL8: 0 | DM8: -6079.643 | DN8: 88711.731 | DO8: 488188.25 | DP8: 88711.731 | DQ8: 93016.966 | DR8: 488797.49 | DS8: 93016.966
A9: =A10+1 -> 46076 | B9: 41903 | C9: 3493 | D9: 2358 | E9: 419 | F9: 94 | G9: 623 | H9: 373 | I9: 161 | J9: 49 | K9: 2823 | L9: 7755 | M9: 75103 | N9: 179.24 | P9: =P10+1 -> 46076 | Q9: 4673.82 | R9: 75103 | S9: 67348 | T9: 419 | U9: 94 | V9: 7755 | W9: 0 | X9: 0 | Y9: 1245.56 | Z9: -1245.56 | AA9: 767010.59 | AB9: 719505.38 | AC9: 740575.58 | AD9: 7095.2 | AE9: 5099.51 | AF9: 56.636 | AG9: 0 | AH9: 0 | AI9: 0 | AJ9: 0 | AK9: 14183.664 | AL9: 3935 | AM9: 3935 | AN9: 4190 | AO9: 0 | AP9: 307.42 | AQ9: 0 | AR9: 0 | AS9: 0 | AT9: 0 | AU9: 0 | AV9: -562.42 | AW9: 0 | AX9: 0 | AY9: 0 | AZ9: 0 | BA9: 0 | BB9: 0 | BC9: 0 | BD9: 0 | BE9: 0 | BF9: 0 | BG9: 0 | BH9: 0 | BI9: 0 | BJ9: 0 | BK9: 0 | BL9: 0 | BM9: 0 | BN9: 0 | BO9: 0 | BP9: 0 | BQ9: 0 | BR9: 0 | BS9: 0 | BT9: 27093.9 | BU9: 27093.9 | BV9: 28727.6 | BW9: 0 | BX9: 0 | BY9: 0 | BZ9: 0 | CA9: 0 | CB9: 0 | CC9: 0 | CD9: -1633.7 | CE9: 1495.1 | CF9: 1416.1 | CG9: 981.32 | CH9: 0 | CI9: 0 | CJ9: 0 | CK9: 0 | CL9: 0 | CM9: 0 | CN9: 0 | CO9: 513.78 | CP9: 6 | CQ9: 6 | CR9: 1080 | CS9: 0 | CT9: 0 | CU9: 0 | CV9: 0 | CW9: 0 | CX9: 0 | CY9: 0 | CZ9: 0 | DA9: -1074 | DB9: 0 | DC9: 0 | DD9: 5106.9 | DE9: 0 | DF9: 0 | DG9: 0 | DH9: 360 | DI9: 35 | DJ9: 6.044 | DK9: 0 | DL9: 0 | DM9: -5507.944 | DN9: 87680.771 | DO9: 482503.45 | DP9: 87680.771 | DQ9: 88711.731 | DR9: 488188.25 | DS9: 88711.731
A10: =A11+1 -> 46075 | B10: 41171 | C10: 3650 | D10: 2691 | E10: 509 | F10: 117 | G10: 600 | H10: 445 | I10: 208 | J10: 73 | K10: 3089 | L10: 31371 | M10: 123790 | N10: 243.2 | P10: =P11+1 -> 46075 | Q10: 25652.215 | R10: 123790 | S10: 92419 | T10: 509 | U10: 117 | V10: 31371 | W10: 0 | X10: 0 | Y10: 2017.75 | Z10: -2017.75 | AA10: 1282834.1 | AB10: 1205444.1 | AC10: 1257340 | AD10: 8814.4 | AE10: 2430.01 | AF10: 52.5976 | AG10: 0 | AH10: 0 | AI10: 0 | AJ10: 0 | AK10: 14197.057 | AL10: 75223 | AM10: 74523 | AN10: 55475.5 | AO10: 0 | AP10: 157.01 | AQ10: 0 | AR10: 0 | AS10: 0 | AT10: 0 | AU10: 0 | AV10: 19590.49 | AW10: 0 | AX10: 0 | AY10: 0 | AZ10: 0 | BA10: 0 | BB10: 0 | BC10: 0 | BD10: 0 | BE10: 0 | BF10: 0 | BG10: 0 | BH10: 0 | BI10: 0 | BJ10: 0 | BK10: 0 | BL10: 0 | BM10: 0 | BN10: 0 | BO10: 0 | BP10: 0 | BQ10: 0 | BR10: 0 | BS10: 0 | BT10: 9369.9 | BU10: 9369.9 | BV10: 9514.16 | BW10: 0 | BX10: 0 | BY10: 0 | BZ10: 0 | CA10: 0 | CB10: 0 | CC10: 0 | CD10: -144.26 | CE10: 100 | CF10: 100 | CG10: 0 | CH10: 0 | CI10: 0 | CJ10: 0 | CK10: 0 | CL10: 0 | CM10: 0 | CN10: 0 | CO10: 100 | CP10: 9 | CQ10: 9 | CR10: 0 | CS10: 0 | CT10: 0 | CU10: 0 | CV10: 0 | CW10: 0 | CX10: 0 | CY10: 0 | CZ10: 0 | DA10: 9 | DB10: 0 | DC10: 0 | DD10: 5699.75 | DE10: 0 | DF10: 0 | DG10: 0 | DH10: 360 | DI10: 15 | DJ10: 7.572 | DK10: 0 | DL10: 0 | DM10: -6082.322 | DN10: 90410.522 | DO10: 487873.45 | DP10: 90410.522 | DQ10: 87680.771 | DR10: 482503.45 | DS10: 87680.771
A11: =A12+1 -> 46074 | B11: 40581 | C11: 3808 | D11: 2628 | E11: 554 | F11: 106 | G11: 676 | H11: 438 | I11: 227 | J11: 48 | K11: 3124 | L11: 58693 | M11: 128243 | N11: 231.48 | P11: =P12+1 -> 46074 | Q11: 45803.051 | R11: 128243 | S11: 69550 | T11: 554 | U11: 106 | V11: 58693 | W11: 0 | X11: 0 | Y11: 2030.24 | Z11: -2030.24 | AA11: 910332.01 | AB11: 853371.16 | AC11: 856643.71 | AD11: 10132 | AE11: 3998.37 | AF11: 45.0094 | AG11: 0 | AH11: 0 | AI11: 0 | AJ11: 0 | AK11: 39512.921 | AL11: 42245 | AM11: 41881 | AN11: 28142.5 | AO11: 0 | AP11: 16.42 | AQ11: 0.06 | AR11: 0 | AS11: 0 | AT11: 0 | AU11: 0 | AV11: 14086.02 | AW11: 0 | AX11: 0 | AY11: 0 | AZ11: 0 | BA11: 0 | BB11: 0 | BC11: 0 | BD11: 0 | BE11: 0 | BF11: 0 | BG11: 0 | BH11: 0 | BI11: 0 | BJ11: 0 | BK11: 0 | BL11: 0 | BM11: 0 | BN11: 0 | BO11: 0 | BP11: 0 | BQ11: 0 | BR11: 0 | BS11: 0 | BT11: 15435.25 | BU11: 15435.25 | BV11: 15335.42 | BW11: 0 | BX11: 0 | BY11: 0 | BZ11: 0 | CA11: 0 | CB11: 0 | CC11: 0 | CD11: 99.83 | CE11: 200 | CF11: 200 | CG11: 115 | CH11: 0 | CI11: 0 | CJ11: 0 | CK11: 0 | CL11: 0 | CM11: 0 | CN11: 0 | CO11: 85 | CP11: 2 | CQ11: 2 | CR11: 0 | CS11: 0 | CT11: 0 | CU11: 0 | CV11: 0 | CW11: 0 | CX11: 0 | CY11: 0 | CZ11: 0 | DA11: 2 | DB11: 0 | DC11: 0 | DD11: 5590.83 | DE11: 0 | DF11: 0 | DG11: 0 | DH11: 330 | DI11: 25 | DJ11: 6.65 | DK11: 0 | DL11: 0 | DM11: -5952.48 | DN11: 92945.162 | DO11: 482420.09 | DP11: 92945.162 | DQ11: 90410.522 | DR11: 487873.45 | DS11: 90410.522
A12: =A13+1 -> 46073 | B12: 39911 | C12: 4200 | D12: 2965 | E12: 625 | F12: 126 | G12: 739 | H12: 512 | I12: 272 | J12: 62 | K12: 3459 | L12: 34543 | M12: 139268 | N12: 222.82 | P12: =P13+1 -> 46073 | Q12: 11486.965 | R12: 139268 | S12: 104725 | T12: 625 | U12: 126 | V12: 34543 | W12: 0 | X12: 0 | Y12: 2285.87 | Z12: -2285.87 | AA12: 1259267.6 | AB12: 1158886.3 | AC12: 1233542.8 | AD12: 13097.1 | AE12: 4704.36 | AF12: 63.9716 | AG12: 0 | AH12: 0 | AI12: 0 | AJ12: 0 | AK12: 7859.384 | AL12: 7031.44 | AM12: 6418.44 | AN12: 5330.46 | AO12: 0 | AP12: 23.94 | AQ12: 0.31 | AR12: 0 | AS12: 0 | AT12: 0 | AU12: 0 | AV12: 1676.73 | AW12: 0 | AX12: 0 | AY12: 0 | AZ12: 0 | BA12: 0 | BB12: 0 | BC12: 0 | BD12: 0 | BE12: 0 | BF12: 0 | BG12: 0 | BH12: 0 | BI12: 0 | BJ12: 0 | BK12: 0 | BL12: 0 | BM12: 1.06 | BN12: 0 | BO12: 0 | BP12: 0 | BQ12: 0 | BR12: 0 | BS12: -1.06 | BT12: 31820.1 | BU12: 31820.1 | BV12: 20901.79 | BW12: 0 | BX12: 0 | BY12: 0 | BZ12: 0 | CA12: 0 | CB12: 0 | CC12: 0 | CD12: 10918.31 | CE12: 200 | CF12: 200 | CG12: 0 | CH12: 0 | CI12: 0 | CJ12: 0 | CK12: 0 | CL12: 0 | CM12: 0 | CN12: 0 | CO12: 200 | CP12: 17 | CQ12: 17 | CR12: 0 | CS12: 0 | CT12: 0 | CU12: 0 | CV12: 0 | CW12: 0 | CX12: 0 | CY12: 0 | CZ12: 0 | DA12: 17 | DB12: 0 | DC12: 0 | DD12: 6505.83 | DE12: 0 | DF12: 0 | DG12: 0 | DH12: 270 | DI12: 115 | DJ12: 6.699 | DK12: 0 | DL12: 0 | DM12: -6897.529 | DN12: 84574.532 | DO12: 470218.93 | DP12: 84574.532 | DQ12: 92945.162 | DR12: 482420.09 | DS12: 92945.162
