Workbook

Sheet 全平台汇总
A1: 46093 | F1: 全平台关键数据报表 | P1: 平台详细数据填制区
A2: 日期 | B2: 充值 | C2: 首存金额 | D2: 提款 | E2: 充提差 | F2: GP1 | G2: GP2 | H2: GP3 | I2: 登录人数 | J2: 投注人数 | K2: 注册人数 | L2: 首充人数 | M2: 续存人数 | N2: 存款人数 | O2: 存款次数 | P2: 投注 | Q2: 有效投注 | R2: 派彩 | S2: 综合优惠比 | T2: 活动红利 | U2: 返点 | V2: 邀请返佣 | W2: GP1 | X2: GP1杀率 | Y2: 游戏杀率 | Z2: 平台余额 | AA2: 周结&月结佣金 | AB2: 周结代理佣金 | AC2: 月结代理佣金 | AD2: GP2 | AE2: GP2杀率 | AF2: 存提手续费 | AG2: 存款手续费 | AH2: 提款手续费 | AI2: 平台费 | AJ2: 包网费(U） | AK2: 汇率 | AL2: 换算P | AM2: GP3 | AN2: GP3杀率 | AO2: 开分 | AP2: 洗分 | AQ2: 核对 | AR2: 差额
A3: 46082 | B3: =WP!L9+GJP!L9+SBET!L9+Sugarplay!L9 -> 10012561 | C3: =WP!K9+GJP!K9+SBET!K9+Sugarplay!K9 -> 101494 | D3: =WP!M9+GJP!M9+SBET!M9+Sugarplay!N9 -> 9438631 | E3: =B3-D3 -> 573929.6 | F3: =W3 -> 1023619.1 | G3: =AD3 -> 1023619.1 | H3: =AM3 -> 677871.75 | I3: =WP!D9+GJP!D9+SBET!D9+Sugarplay!D9 -> 37276 | J3: =WP!J9+GJP!J9+SBET!J9+Sugarplay!J9 -> 23624 | K3: =WP!B9+GJP!B9+SBET!B9+Sugarplay!B9 -> 1333 | L3: =WP!C9+GJP!C9+SBET!C9+Sugarplay!C9 -> 410 | M3: =WP!E9+GJP!E9+SBET!E9+Sugarplay!E9 -> 992 | N3: =WP!F9+GJP!F9+SBET!F9+Sugarplay!F9 -> 5857 | O3: =WP!G9+GJP!G9+SBET!G9+Sugarplay!G9 -> 12355 | P3: =WP!O9+GJP!O9+SBET!O9+Sugarplay!P9 -> 67076153 | Q3: =WP!P9+GJP!P9+SBET!P9+Sugarplay!Q9 -> 62681990 | R3: =WP!R9+GJP!R9+SBET!R9+Sugarplay!S9 -> 65320984 | S3: =T3/Q3 -> 0.011670818 | T3: =WP!S9+GJP!S9+SBET!S9+Sugarplay!T9 -> 731550.07 | U3: =WP!T9+GJP!T9+SBET!T9+Sugarplay!U9 -> 284236.48 | V3: =WP!U9+GJP!U9+SBET!U9+Sugarplay!V9 -> 29250.28 | W3: =P3-R3-T3 -> 1023619.1 | X3: =W3/P3 -> 0.015260552 | Y3: =(P3-R3)/P3 -> 0.026166814 | Z3: =WP!AE9+GJP!AE9+SBET!AF9+Sugarplay!AG9 -> 1965001.1 | AA3: =AB3+AC3 -> 0 | AB3: =WP!AA9+GJP!AA9+SBET!AB9+Sugarplay!AC9 -> 0 | AC3: =WP!AB9+GJP!AB9+SBET!AC9+Sugarplay!AD9 -> 0 | AD3: =W3-AB3-AC3 -> 1023619.1 | AE3: =AD3/P3 -> 0.015260552 | AF3: =AG3+AH3 -> 253621.64 | AG3: =WP!W9+GJP!W9+SBET!W9+Sugarplay!X9 -> 234744.3 | AH3: =WP!X9+GJP!X9+SBET!X9+Sugarplay!Y9 -> 18877.34 | AI3: =W3*0.09 -> 92125.72 | AJ3: 0 | AK3: 0 | AL3: 0 | AM3: =W3-AB3-AC3-AG3-AH3-AI3 -> 677871.75 | AN3: =AM3/P3 -> 0.010106002 | AO3: =WP!AC9+GJP!AC9+SBET!AD9+Sugarplay!AE9 -> 100 | AP3: =WP!AD9+GJP!AD9+SBET!AE9+Sugarplay!AF9 -> -2554.33 | AQ3: =AD3-AG3-AH3-AI3 -> 677871.75 | AR3: =AM3-AQ3 -> 0
A4: =A3+1 -> 46083 | B4: =WP!L10+GJP!L10+SBET!L10+Sugarplay!L10 -> 8816812.6 | C4: =WP!K10+GJP!K10+SBET!K10+Sugarplay!K10 -> 88437 | D4: =WP!M10+GJP!M10+SBET!M10+Sugarplay!N10 -> 8989445 | E4: =B4-D4 -> -172632.43 | F4: =W4 -> 817069.84 | G4: =AD4 -> -209948.92 | H4: =AM4 -> -508126 | I4: =WP!D10+GJP!D10+SBET!D10+Sugarplay!D10 -> 30062 | J4: =WP!J10+GJP!J10+SBET!J10+Sugarplay!J10 -> 19932 | K4: =WP!B10+GJP!B10+SBET!B10+Sugarplay!B10 -> 1326 | L4: =WP!C10+GJP!C10+SBET!C10+Sugarplay!C10 -> 384 | M4: =WP!E10+GJP!E10+SBET!E10+Sugarplay!E10 -> 903 | N4: =WP!F10+GJP!F10+SBET!F10+Sugarplay!F10 -> 4985 | O4: =WP!G10+GJP!G10+SBET!G10+Sugarplay!G10 -> 10948 | P4: =WP!O10+GJP!O10+SBET!O10+Sugarplay!P10 -> 57155008 | Q4: =WP!P10+GJP!P10+SBET!P10+Sugarplay!Q10 -> 53233162 | R4: =WP!R10+GJP!R10+SBET!R10+Sugarplay!S10 -> 55716597 | S4: =T4/Q4 -> 0.011672072 | T4: =WP!S10+GJP!S10+SBET!S10+Sugarplay!T10 -> 621341.32 | U4: =WP!T10+GJP!T10+SBET!T10+Sugarplay!U10 -> 249517.97 | V4: =WP!U10+GJP!U10+SBET!U10+Sugarplay!V10 -> 40804.38 | W4: =P4-R4-T4 -> 817069.84 | X4: =W4/P4 -> 0.014295682 | Y4: =(P4-R4)/P4 -> 0.025166844 | Z4: =WP!AE10+GJP!AE10+SBET!AF10+Sugarplay!AG10 -> 1882353.4 | AA4: =AB4+AC4 -> 1027018.8 | AB4: =WP!AA10+GJP!AA10+SBET!AB10+Sugarplay!AC10 -> 1027018.8 | AC4: =WP!AB10+GJP!AB10+SBET!AC10+Sugarplay!AD10 -> 0 | AD4: =W4-AB4-AC4 -> -209948.92 | AE4: =AD4/P4 -> -0.003673325 | AF4: =AG4+AH4 -> 224640.79 | AG4: =WP!W10+GJP!W10+SBET!W10+Sugarplay!X10 -> 206662.07 | AH4: =WP!X10+GJP!X10+SBET!X10+Sugarplay!Y10 -> 17978.72 | AI4: =W4*0.09 -> 73536.286 | AM4: =W4-AB4-AC4-AG4-AH4-AI4 -> -508126 | AN4: =AM4/P4 -> -0.0088903145 | AO4: =WP!AC10+GJP!AC10+SBET!AD10+Sugarplay!AE10 -> 24934.69 | AP4: =WP!AD10+GJP!AD10+SBET!AE10+Sugarplay!AF10 -> -5158.46 | AQ4: =AD4-AG4-AH4-AI4 -> -508126 | AR4: =AM4-AQ4 -> 0
A5: =A4+1 -> 46084 | B5: =WP!L11+GJP!L11+SBET!L11+Sugarplay!L11 -> 9493443 | C5: =WP!K11+GJP!K11+SBET!K11+Sugarplay!K11 -> 81720 | D5: =WP!M11+GJP!M11+SBET!M11+Sugarplay!N11 -> 7971259 | E5: =B5-D5 -> 1522184 | F5: =W5 -> 1120695 | G5: =AD5 -> 1116040 | H5: =AM5 -> 777674.26 | I5: =WP!D11+GJP!D11+SBET!D11+Sugarplay!D11 -> 32603 | J5: =WP!J11+GJP!J11+SBET!J11+Sugarplay!J11 -> 20872 | K5: =WP!B11+GJP!B11+SBET!B11+Sugarplay!B11 -> 1273 | L5: =WP!C11+GJP!C11+SBET!C11+Sugarplay!C11 -> 385 | M5: =WP!E11+GJP!E11+SBET!E11+Sugarplay!E11 -> 840 | N5: =WP!F11+GJP!F11+SBET!F11+Sugarplay!F11 -> 4859 | O5: =WP!G11+GJP!G11+SBET!G11+Sugarplay!G11 -> 10981 | P5: =WP!O11+GJP!O11+SBET!O11+Sugarplay!P11 -> 68808339 | Q5: =WP!P11+GJP!P11+SBET!P11+Sugarplay!Q11 -> 64088379 | R5: =WP!R11+GJP!R11+SBET!R11+Sugarplay!S11 -> 67156074 | S5: =T5/Q5 -> 0.00829434 | T5: =WP!S11+GJP!S11+SBET!S11+Sugarplay!T11 -> 531570.81 | U5: =WP!T11+GJP!T11+SBET!T11+Sugarplay!U11 -> 220355.21 | V5: =WP!U11+GJP!U11+SBET!U11+Sugarplay!V11 -> 31186.92 | W5: =P5-R5-T5 -> 1120695 | X5: =W5/P5 -> 0.016287197 | Y5: =(P5-R5)/P5 -> 0.024012581 | Z5: =WP!AE11+GJP!AE11+SBET!AF11+Sugarplay!AG11 -> 1834307.9 | AA5: =AB5+AC5 -> 4655 | AB5: =WP!AA11+GJP!AA11+SBET!AB11+Sugarplay!AC11 -> 4655 | AC5: =WP!AB11+GJP!AB11+SBET!AC11+Sugarplay!AD11 -> 0 | AD5: =W5-AB5-AC5 -> 1116040 | AE5: =AD5/P5 -> 0.016219545 | AF5: =AG5+AH5 -> 237503.17 | AG5: =WP!W11+GJP!W11+SBET!W11+Sugarplay!X11 -> 221560.78 | AH5: =WP!X11+GJP!X11+SBET!X11+Sugarplay!Y11 -> 15942.39 | AI5: =W5*0.09 -> 100862.55 | AM5: =W5-AB5-AC5-AG5-AH5-AI5 -> 777674.26 | AN5: =AM5/P5 -> 0.011302035 | AO5: =WP!AC11+GJP!AC11+SBET!AD11+Sugarplay!AE11 -> 14094.8 | AP5: =WP!AD11+GJP!AD11+SBET!AE11+Sugarplay!AF11 -> -56452.86 | AQ5: =AD5-AG5-AH5-AI5 -> 777674.26 | AR5: =AM5-AQ5 -> 0
A6: =A5+1 -> 46085 | B6: =WP!L12+GJP!L12+SBET!L12+Sugarplay!L12 -> 11799989 | C6: =WP!K12+GJP!K12+SBET!K12+Sugarplay!K12 -> 108144 | D6: =WP!M12+GJP!M12+SBET!M12+Sugarplay!N12 -> 9658460 | E6: =B6-D6 -> 2141529.1 | F6: =W6 -> 1836446 | G6: =AD6 -> 1836288 | H6: =AM6 -> 1375940.2 | I6: =WP!D12+GJP!D12+SBET!D12+Sugarplay!D12 -> 36056 | J6: =WP!J12+GJP!J12+SBET!J12+Sugarplay!J12 -> 22720 | K6: =WP!B12+GJP!B12+SBET!B12+Sugarplay!B12 -> 1133 | L6: =WP!C12+GJP!C12+SBET!C12+Sugarplay!C12 -> 456 | M6: =WP!E12+GJP!E12+SBET!E12+Sugarplay!E12 -> 857 | N6: =WP!F12+GJP!F12+SBET!F12+Sugarplay!F12 -> 5303 | O6: =WP!G12+GJP!G12+SBET!G12+Sugarplay!G12 -> 11724 | P6: =WP!O12+GJP!O12+SBET!O12+Sugarplay!P12 -> 81349421 | Q6: =WP!P12+GJP!P12+SBET!P12+Sugarplay!Q12 -> 75596780 | R6: =WP!R12+GJP!R12+SBET!R12+Sugarplay!S12 -> 78804731 | S6: =T6/Q6 -> 0.0093686982 | T6: =WP!S12+GJP!S12+SBET!S12+Sugarplay!T12 -> 708243.42 | U6: =WP!T12+GJP!T12+SBET!T12+Sugarplay!U12 -> 318389.11 | V6: =WP!U12+GJP!U12+SBET!U12+Sugarplay!V12 -> 39667.62 | W6: =P6-R6-T6 -> 1836446 | X6: =W6/P6 -> 0.022574789 | Y6: =(P6-R6)/P6 -> 0.031280978 | Z6: =WP!AE12+GJP!AE12+SBET!AF12+Sugarplay!AG12 -> 2275472.5 | AA6: =AB6+AC6 -> 158 | AB6: =WP!AA12+GJP!AA12+SBET!AB12+Sugarplay!AC12 -> 158 | AC6: =WP!AB12+GJP!AB12+SBET!AC12+Sugarplay!AD12 -> 0 | AD6: =W6-AB6-AC6 -> 1836288 | AE6: =AD6/P6 -> 0.022572847 | AF6: =AG6+AH6 -> 295067.71 | AG6: =WP!W12+GJP!W12+SBET!W12+Sugarplay!X12 -> 275750.39 | AH6: =WP!X12+GJP!X12+SBET!X12+Sugarplay!Y12 -> 19317.32 | AI6: =W6*0.09 -> 165280.14 | AM6: =W6-AB6-AC6-AG6-AH6-AI6 -> 1375940.2 | AN6: =AM6/P6 -> 0.016913952 | AO6: =WP!AC12+GJP!AC12+SBET!AD12+Sugarplay!AE12 -> 0 | AP6: =WP!AD12+GJP!AD12+SBET!AE12+Sugarplay!AF12 -> -693.1 | AQ6: =AD6-AG6-AH6-AI6 -> 1375940.2 | AR6: =AM6-AQ6 -> 0
A7: =A6+1 -> 46086 | B7: =WP!L13+GJP!L13+SBET!L13+Sugarplay!L13 -> 11070696 | C7: =WP!K13+GJP!K13+SBET!K13+Sugarplay!K13 -> 104683 | D7: =WP!M13+GJP!M13+SBET!M13+Sugarplay!N13 -> 9393354 | E7: =B7-D7 -> 1677341.8 | F7: =W7 -> 1716183.1 | G7: =AD7 -> 1715683.1 | H7: =AM7 -> 1283730.2 | I7: =WP!D13+GJP!D13+SBET!D13+Sugarplay!D13 -> 30390 | J7: =WP!J13+GJP!J13+SBET!J13+Sugarplay!J13 -> 20570 | K7: =WP!B13+GJP!B13+SBET!B13+Sugarplay!B13 -> 1126 | L7: =WP!C13+GJP!C13+SBET!C13+Sugarplay!C13 -> 373 | M7: =WP!E13+GJP!E13+SBET!E13+Sugarplay!E13 -> 843 | N7: =WP!F13+GJP!F13+SBET!F13+Sugarplay!F13 -> 4861 | O7: =WP!G13+GJP!G13+SBET!G13+Sugarplay!G13 -> 11389 | P7: =WP!O13+GJP!O13+SBET!O13+Sugarplay!P13 -> 74995038 | Q7: =WP!P13+GJP!P13+SBET!P13+Sugarplay!Q13 -> 70418491 | R7: =WP!R13+GJP!R13+SBET!R13+Sugarplay!S13 -> 72621807 | S7: =T7/Q7 -> 0.0093306258 | T7: =WP!S13+GJP!S13+SBET!S13+Sugarplay!T13 -> 657048.59 | U7: =WP!T13+GJP!T13+SBET!T13+Sugarplay!U13 -> 279745.75 | V7: =WP!U13+GJP!U13+SBET!U13+Sugarplay!V13 -> 36585.53 | W7: =P7-R7-T7 -> 1716183.1 | X7: =W7/P7 -> 0.022883956 | Y7: =(P7-R7)/P7 -> 0.031645183 | Z7: =WP!AE13+GJP!AE13+SBET!AF13+Sugarplay!AG13 -> 2290627.3 | AA7: =AB7+AC7 -> 500 | AB7: =WP!AA13+GJP!AA13+SBET!AB13+Sugarplay!AC13 -> 500 | AC7: =WP!AB13+GJP!AB13+SBET!AC13+Sugarplay!AD13 -> 0 | AD7: =W7-AB7-AC7 -> 1715683.1 | AE7: =AD7/P7 -> 0.022877288 | AF7: =AG7+AH7 -> 277496.43 | AG7: =WP!W13+GJP!W13+SBET!W13+Sugarplay!X13 -> 258709.75 | AH7: =WP!X13+GJP!X13+SBET!X13+Sugarplay!Y13 -> 18786.68 | AI7: =W7*0.09 -> 154456.48 | AM7: =W7-AB7-AC7-AG7-AH7-AI7 -> 1283730.2 | AN7: =AM7/P7 -> 0.017117535 | AO7: =WP!AC13+GJP!AC13+SBET!AD13+Sugarplay!AE13 -> 0 | AP7: =WP!AD13+GJP!AD13+SBET!AE13+Sugarplay!AF13 -> -15883.11 | AQ7: =AD7-AG7-AH7-AI7 -> 1283730.2 | AR7: =AM7-AQ7 -> 0
A8: =A7+1 -> 46087 | B8: =WP!L14+GJP!L14+SBET!L14+Sugarplay!L14 -> 11336766 | C8: =WP!K14+GJP!K14+SBET!K14+Sugarplay!K14 -> 102748 | D8: =WP!M14+GJP!M14+SBET!M14+Sugarplay!N14 -> 9913747 | E8: =B8-D8 -> 1423019 | F8: =W8 -> 2163495.7 | G8: =AD8 -> 2162895.7 | H8: =AM8 -> 1684159.8 | I8: =WP!D14+GJP!D14+SBET!D14+Sugarplay!D14 -> 34834 | J8: =WP!J14+GJP!J14+SBET!J14+Sugarplay!J14 -> 25291 | K8: =WP!B14+GJP!B14+SBET!B14+Sugarplay!B14 -> 1211 | L8: =WP!C14+GJP!C14+SBET!C14+Sugarplay!C14 -> 418 | M8: =WP!E14+GJP!E14+SBET!E14+Sugarplay!E14 -> 855 | N8: =WP!F14+GJP!F14+SBET!F14+Sugarplay!F14 -> 5432 | O8: =WP!G14+GJP!G14+SBET!G14+Sugarplay!G14 -> 12047 | P8: =WP!O14+GJP!O14+SBET!O14+Sugarplay!P14 -> 76693220 | Q8: =WP!P14+GJP!P14+SBET!P14+Sugarplay!Q14 -> 71420335 | R8: =WP!R14+GJP!R14+SBET!R14+Sugarplay!S14 -> 73651319 | S8: =T8/Q8 -> 0.012299094 | T8: =WP!S14+GJP!S14+SBET!S14+Sugarplay!T14 -> 878405.45 | U8: =WP!T14+GJP!T14+SBET!T14+Sugarplay!U14 -> 355546.15 | V8: =WP!U14+GJP!U14+SBET!U14+Sugarplay!V14 -> 27739.37 | W8: =P8-R8-T8 -> 2163495.7 | X8: =W8/P8 -> 0.028209739 | Y8: =(P8-R8)/P8 -> 0.039663234 | Z8: =WP!AE14+GJP!AE14+SBET!AF14+Sugarplay!AG14 -> 1772925.9 | AA8: =AB8+AC8 -> 600 | AB8: =WP!AA14+GJP!AA14+SBET!AB14+Sugarplay!AC14 -> 600 | AC8: =WP!AB14+GJP!AB14+SBET!AC14+Sugarplay!AD14 -> 0 | AD8: =W8-AB8-AC8 -> 2162895.7 | AE8: =AD8/P8 -> 0.028201915 | AF8: =AG8+AH8 -> 284021.27 | AG8: =WP!W14+GJP!W14+SBET!W14+Sugarplay!X14 -> 264193.49 | AH8: =WP!X14+GJP!X14+SBET!X14+Sugarplay!Y14 -> 19827.78 | AI8: =W8*0.09 -> 194714.61 | AM8: =W8-AB8-AC8-AG8-AH8-AI8 -> 1684159.8 | AN8: =AM8/P8 -> 0.021959696 | AO8: =WP!AC14+GJP!AC14+SBET!AD14+Sugarplay!AE14 -> 0 | AP8: =WP!AD14+GJP!AD14+SBET!AE14+Sugarplay!AF14 -> -22828.95 | AQ8: =AD8-AG8-AH8-AI8 -> 1684159.8 | AR8: =AM8-AQ8 -> 0
A9: =A8+1 -> 46088 | B9: =WP!L15+GJP!L15+SBET!L15+Sugarplay!L15 -> 9146001.2 | C9: =WP!K15+GJP!K15+SBET!K15+Sugarplay!K15 -> 80548 | D9: =WP!M15+GJP!M15+SBET!M15+Sugarplay!N15 -> 7388477 | E9: =B9-D9 -> 1757524.2 | F9: =W9 -> 2096383 | G9: =AD9 -> 2092285 | H9: =AM9 -> 1674812.2 | I9: =WP!D15+GJP!D15+SBET!D15+Sugarplay!D15 -> 31535 | J9: =WP!J15+GJP!J15+SBET!J15+Sugarplay!J15 -> 22766 | K9: =WP!B15+GJP!B15+SBET!B15+Sugarplay!B15 -> 1187 | L9: =WP!C15+GJP!C15+SBET!C15+Sugarplay!C15 -> 429 | M9: =WP!E15+GJP!E15+SBET!E15+Sugarplay!E15 -> 890 | N9: =WP!F15+GJP!F15+SBET!F15+Sugarplay!F15 -> 5370 | O9: =WP!G15+GJP!G15+SBET!G15+Sugarplay!G15 -> 12128 | P9: =WP!O15+GJP!O15+SBET!O15+Sugarplay!P15 -> 61440169 | Q9: =WP!P15+GJP!P15+SBET!P15+Sugarplay!Q15 -> 57446216 | R9: =WP!R15+GJP!R15+SBET!R15+Sugarplay!S15 -> 58710718 | S9: =T9/Q9 -> 0.011020182 | T9: =WP!S15+GJP!S15+SBET!S15+Sugarplay!T15 -> 633067.76 | U9: =WP!T15+GJP!T15+SBET!T15+Sugarplay!U15 -> 238979.64 | V9: =WP!U15+GJP!U15+SBET!U15+Sugarplay!V15 -> 44748.36 | W9: =P9-R9-T9 -> 2096383 | X9: =W9/P9 -> 0.034120723 | Y9: =(P9-R9)/P9 -> 0.044424531 | Z9: =WP!AE15+GJP!AE15+SBET!AF15+Sugarplay!AG15 -> 1822697.1 | AA9: =AB9+AC9 -> 4098 | AB9: =WP!AA15+GJP!AA15+SBET!AB15+Sugarplay!AC15 -> 4098 | AC9: =WP!AB15+GJP!AB15+SBET!AC15+Sugarplay!AD15 -> 0 | AD9: =W9-AB9-AC9 -> 2092285 | AE9: =AD9/P9 -> 0.034054023 | AF9: =AG9+AH9 -> 228798.32 | AG9: =WP!W15+GJP!W15+SBET!W15+Sugarplay!X15 -> 214021.57 | AH9: =WP!X15+GJP!X15+SBET!X15+Sugarplay!Y15 -> 14776.75 | AI9: =W9*0.09 -> 188674.47 | AM9: =W9-AB9-AC9-AG9-AH9-AI9 -> 1674812.2 | AN9: =AM9/P9 -> 0.027259238 | AO9: =WP!AC15+GJP!AC15+SBET!AD15+Sugarplay!AE15 -> 0 | AP9: =WP!AD15+GJP!AD15+SBET!AE15+Sugarplay!AF15 -> -6039.02 | AQ9: =AD9-AG9-AH9-AI9 -> 1674812.2 | AR9: =AM9-AQ9 -> 0
A10: =A9+1 -> 46089 | B10: =WP!L16+GJP!L16+SBET!L16+Sugarplay!L16 -> 8743030.4 | C10: =WP!K16+GJP!K16+SBET!K16+Sugarplay!K16 -> 89151 | D10: =WP!M16+GJP!M16+SBET!M16+Sugarplay!N16 -> 7021701 | E10: =B10-D10 -> 1721329.4 | F10: =W10 -> 1430284.9 | G10: =AD10 -> 1430284.9 | H10: =AM10 -> 1083093 | I10: =WP!D16+GJP!D16+SBET!D16+Sugarplay!D16 -> 44452 | J10: =WP!J16+GJP!J16+SBET!J16+Sugarplay!J16 -> 35587 | K10: =WP!B16+GJP!B16+SBET!B16+Sugarplay!B16 -> 1495 | L10: =WP!C16+GJP!C16+SBET!C16+Sugarplay!C16 -> 475 | M10: =WP!E16+GJP!E16+SBET!E16+Sugarplay!E16 -> 861 | N10: =WP!F16+GJP!F16+SBET!F16+Sugarplay!F16 -> 5524 | O10: =WP!G16+GJP!G16+SBET!G16+Sugarplay!G16 -> 11873 | P10: =WP!O16+GJP!O16+SBET!O16+Sugarplay!P16 -> 59518719 | Q10: =WP!P16+GJP!P16+SBET!P16+Sugarplay!Q16 -> 55414312 | R10: =WP!R16+GJP!R16+SBET!R16+Sugarplay!S16 -> 57454100 | S10: =T10/Q10 -> 0.011447123 | T10: =WP!S16+GJP!S16+SBET!S16+Sugarplay!T16 -> 634334.47 | U10: =WP!T16+GJP!T16+SBET!T16+Sugarplay!U16 -> 219316.17 | V10: =WP!U16+GJP!U16+SBET!U16+Sugarplay!V16 -> 35016.34 | W10: =P10-R10-T10 -> 1430284.9 | X10: =W10/P10 -> 0.024030841 | Y10: =(P10-R10)/P10 -> 0.034688571 | Z10: =WP!AE16+GJP!AE16+SBET!AF16+Sugarplay!AG16 -> 1959603.2 | AA10: =AB10+AC10 -> 0 | AB10: =WP!AA16+GJP!AA16+SBET!AB16+Sugarplay!AC16 -> 0 | AC10: =WP!AB16+GJP!AB16+SBET!AC16+Sugarplay!AD16 -> 0 | AD10: =W10-AB10-AC10 -> 1430284.9 | AE10: =AD10/P10 -> 0.024030841 | AF10: =AG10+AH10 -> 218466.26 | AG10: =WP!W16+GJP!W16+SBET!W16+Sugarplay!X16 -> 204422.46 | AH10: =WP!X16+GJP!X16+SBET!X16+Sugarplay!Y16 -> 14043.8 | AI10: =W10*0.09 -> 128725.64 | AM10: =W10-AB10-AC10-AG10-AH10-AI10 -> 1083093 | AN10: =AM10/P10 -> 0.018197518 | AO10: =WP!AC16+GJP!AC16+SBET!AD16+Sugarplay!AE16 -> 0 | AP10: =WP!AD16+GJP!AD16+SBET!AE16+Sugarplay!AF16 -> -32070.54 | AQ10: =AD10-AG10-AH10-AI10 -> 1083093 | AR10: =AM10-AQ10 -> 0
A11: =A10+1 -> 46090 | B11: =WP!L17+GJP!L17+SBET!L17+Sugarplay!L17 -> 8998021.2 | C11: =WP!K17+GJP!K17+SBET!K17+Sugarplay!K17 -> 84741 | D11: =WP!M17+GJP!M17+SBET!M17+Sugarplay!N17 -> 9075963 | E11: =B11-D11 -> -77941.79 | F11: =W11 -> 1168422.1 | G11: =AD11 -> -189137.81 | H11: =AM11 -> -522932.01 | I11: =WP!D17+GJP!D17+SBET!D17+Sugarplay!D17 -> 35036 | J11: =WP!J17+GJP!J17+SBET!J17+Sugarplay!J17 -> 26675 | K11: =WP!B17+GJP!B17+SBET!B17+Sugarplay!B17 -> 1324 | L11: =WP!C17+GJP!C17+SBET!C17+Sugarplay!C17 -> 465 | M11: =WP!E17+GJP!E17+SBET!E17+Sugarplay!E17 -> 812 | N11: =WP!F17+GJP!F17+SBET!F17+Sugarplay!F17 -> 4866 | O11: =WP!G17+GJP!G17+SBET!G17+Sugarplay!G17 -> 11121 | P11: =WP!O17+GJP!O17+SBET!O17+Sugarplay!P17 -> 62418180 | Q11: =WP!P17+GJP!P17+SBET!P17+Sugarplay!Q17 -> 57490214 | R11: =WP!R17+GJP!R17+SBET!R17+Sugarplay!S17 -> 60604634 | S11: =T11/Q11 -> 0.011221456 | T11: =WP!S17+GJP!S17+SBET!S17+Sugarplay!T17 -> 645123.92 | U11: =WP!T17+GJP!T17+SBET!T17+Sugarplay!U17 -> 251060.31 | V11: =WP!U17+GJP!U17+SBET!U17+Sugarplay!V17 -> 32777.63 | W11: =P11-R11-T11 -> 1168422.1 | X11: =W11/P11 -> 0.01871926 | Y11: =(P11-R11)/P11 -> 0.029054773 | Z11: =WP!AE17+GJP!AE17+SBET!AF17+Sugarplay!AG17 -> 2770004.3 | AA11: =AB11+AC11 -> 1357560 | AB11: =WP!AA17+GJP!AA17+SBET!AB17+Sugarplay!AC17 -> 1357560 | AC11: =WP!AB17+GJP!AB17+SBET!AC17+Sugarplay!AD17 -> 0 | AD11: =W11-AB11-AC11 -> -189137.81 | AE11: =AD11/P11 -> -0.0030301718 | AF11: =AG11+AH11 -> 228636.21 | AG11: =WP!W17+GJP!W17+SBET!W17+Sugarplay!X17 -> 210483.81 | AH11: =WP!X17+GJP!X17+SBET!X17+Sugarplay!Y17 -> 18152.4 | AI11: =W11*0.09 -> 105157.99 | AM11: =W11-AB11-AC11-AG11-AH11-AI11 -> -522932.01 | AN11: =AM11/P11 -> -0.0083778798 | AO11: =WP!AC17+GJP!AC17+SBET!AD17+Sugarplay!AE17 -> 123737.11 | AP11: =WP!AD17+GJP!AD17+SBET!AE17+Sugarplay!AF17 -> -147358.45 | AQ11: =AD11-AG11-AH11-AI11 -> -522932.01 | AR11: =AM11-AQ11 -> 0
A12: =A11+1 -> 46091 | B12: =WP!L18+GJP!L18+SBET!L18+Sugarplay!L18 -> 8656049.1 | C12: =WP!K18+GJP!K18+SBET!K18+Sugarplay!K18 -> 65052 | D12: =WP!M18+GJP!M18+SBET!M18+Sugarplay!N18 -> 7894537 | E12: =B12-D12 -> 761512.14 | F12: =W12 -> 1049437.1 | G12: =AD12 -> 1005714.1 | H12: =AM12 -> 693346.95 | I12: =WP!D18+GJP!D18+SBET!D18+Sugarplay!D18 -> 33657 | J12: =WP!J18+GJP!J18+SBET!J18+Sugarplay!J18 -> 24070 | K12: =WP!B18+GJP!B18+SBET!B18+Sugarplay!B18 -> 1282 | L12: =WP!C18+GJP!C18+SBET!C18+Sugarplay!C18 -> 394 | M12: =WP!E18+GJP!E18+SBET!E18+Sugarplay!E18 -> 850 | N12: =WP!F18+GJP!F18+SBET!F18+Sugarplay!F18 -> 4877 | O12: =WP!G18+GJP!G18+SBET!G18+Sugarplay!G18 -> 10991 | P12: =WP!O18+GJP!O18+SBET!O18+Sugarplay!P18 -> 60320102 | Q12: =WP!P18+GJP!P18+SBET!P18+Sugarplay!Q18 -> 56307616 | R12: =WP!R18+GJP!R18+SBET!R18+Sugarplay!S18 -> 58750252 | S12: =T12/Q12 -> 0.0092423188 | T12: =WP!S18+GJP!S18+SBET!S18+Sugarplay!T18 -> 520412.94 | U12: =WP!T18+GJP!T18+SBET!T18+Sugarplay!U18 -> 217343.52 | V12: =WP!U18+GJP!U18+SBET!U18+Sugarplay!V18 -> 29775.73 | W12: =P12-R12-T12 -> 1049437.1 | X12: =W12/P12 -> 0.0173978 | Y12: =(P12-R12)/P12 -> 0.02602532 | Z12: =WP!AE18+GJP!AE18+SBET!AF18+Sugarplay!AG18 -> 1998999.8 | AA12: =AB12+AC12 -> 43723 | AB12: =WP!AA18+GJP!AA18+SBET!AB18+Sugarplay!AC18 -> 43723 | AC12: =WP!AB18+GJP!AB18+SBET!AC18+Sugarplay!AD18 -> 0 | AD12: =W12-AB12-AC12 -> 1005714.1 | AE12: =AD12/P12 -> 0.01667295 | AF12: =AG12+AH12 -> 217917.77 | AG12: =WP!W18+GJP!W18+SBET!W18+Sugarplay!X18 -> 202128.61 | AH12: =WP!X18+GJP!X18+SBET!X18+Sugarplay!Y18 -> 15789.16 | AI12: =W12*0.09 -> 94449.335 | AM12: =W12-AB12-AC12-AG12-AH12-AI12 -> 693346.95 | AN12: =AM12/P12 -> 0.011494459 | AO12: =WP!AC18+GJP!AC18+SBET!AD18+Sugarplay!AE18 -> 3100 | AP12: =WP!AD18+GJP!AD18+SBET!AE18+Sugarplay!AF18 -> -11420.41 | AQ12: =AD12-AG12-AH12-AI12 -> 693346.95 | AR12: =AM12-AQ12 -> 0
A13: =A12+1 -> 46092 | B13: =WP!L19+GJP!L19+SBET!L19+Sugarplay!L19 -> 9771389.9 | C13: =WP!K19+GJP!K19+SBET!K19+Sugarplay!K19 -> 62776.89 | D13: =WP!M19+GJP!M19+SBET!M19+Sugarplay!N19 -> 7339569 | E13: =B13-D13 -> 2431820.9 | F13: =W13 -> 1578360.4 | G13: =AD13 -> 1578024.4 | H13: =AM13 -> 1193323.2 | I13: =WP!D19+GJP!D19+SBET!D19+Sugarplay!D19 -> 35220 | J13: =WP!J19+GJP!J19+SBET!J19+Sugarplay!J19 -> 25573 | K13: =WP!B19+GJP!B19+SBET!B19+Sugarplay!B19 -> 1043 | L13: =WP!C19+GJP!C19+SBET!C19+Sugarplay!C19 -> 340 | M13: =WP!E19+GJP!E19+SBET!E19+Sugarplay!E19 -> 793 | N13: =WP!F19+GJP!F19+SBET!F19+Sugarplay!F19 -> 4878 | O13: =WP!G19+GJP!G19+SBET!G19+Sugarplay!G19 -> 11239 | P13: =WP!O19+GJP!O19+SBET!O19+Sugarplay!P19 -> 57537374 | Q13: =WP!P19+GJP!P19+SBET!P19+Sugarplay!Q19 -> 53706677 | R13: =WP!R19+GJP!R19+SBET!R19+Sugarplay!S19 -> 55368621 | S13: =T13/Q13 -> 0.010992913 | T13: =WP!S19+GJP!S19+SBET!S19+Sugarplay!T19 -> 590392.81 | U13: =WP!T19+GJP!T19+SBET!T19+Sugarplay!U19 -> 242227.65 | V13: =WP!U19+GJP!U19+SBET!U19+Sugarplay!V19 -> 27742.02 | W13: =P13-R13-T13 -> 1578360.4 | X13: =W13/P13 -> 0.027431916 | Y13: =(P13-R13)/P13 -> 0.037692947 | Z13: =WP!AE19+GJP!AE19+SBET!AF19+Sugarplay!AG19 -> 2716736.4 | AA13: =AB13+AC13 -> 336 | AB13: =WP!AA19+GJP!AA19+SBET!AB19+Sugarplay!AC19 -> 336 | AC13: =WP!AB19+GJP!AB19+SBET!AC19+Sugarplay!AD19 -> 0 | AD13: =W13-AB13-AC13 -> 1578024.4 | AE13: =AD13/P13 -> 0.027426076 | AF13: =AG13+AH13 -> 242648.76 | AG13: =WP!W19+GJP!W19+SBET!W19+Sugarplay!X19 -> 227970.11 | AH13: =WP!X19+GJP!X19+SBET!X19+Sugarplay!Y19 -> 14678.65 | AI13: =W13*0.09 -> 142052.44 | AM13: =W13-AB13-AC13-AG13-AH13-AI13 -> 1193323.2 | AN13: =AM13/P13 -> 0.020739966 | AO13: =WP!AC19+GJP!AC19+SBET!AD19+Sugarplay!AE19 -> 0 | AP13: =WP!AD19+GJP!AD19+SBET!AE19+Sugarplay!AF19 -> -4601.87 | AQ13: =AD13-AG13-AH13-AI13 -> 1193323.2 | AR13: =AM13-AQ13 -> 0
A14: =A13+1 -> 46093 | B14: =WP!L20+GJP!L20+SBET!L20+Sugarplay!L20 -> 9124174.9 | C14: =WP!K20+GJP!K20+SBET!K20+Sugarplay!K20 -> 60659 | D14: =WP!M20+GJP!M20+SBET!M20+Sugarplay!N20 -> 8123782 | E14: =B14-D14 -> 1000392.9 | F14: =W14 -> 1754210.2 | G14: =AD14 -> 1754018.2 | H14: =AM14 -> 1367157.9 | I14: =WP!D20+GJP!D20+SBET!D20+Sugarplay!D20 -> 32710 | J14: =WP!J20+GJP!J20+SBET!J20+Sugarplay!J20 -> 22464 | K14: =WP!B20+GJP!B20+SBET!B20+Sugarplay!B20 -> 980 | L14: =WP!C20+GJP!C20+SBET!C20+Sugarplay!C20 -> 342 | M14: =WP!E20+GJP!E20+SBET!E20+Sugarplay!E20 -> 776 | N14: =WP!F20+GJP!F20+SBET!F20+Sugarplay!F20 -> 4825 | O14: =WP!G20+GJP!G20+SBET!G20+Sugarplay!G20 -> 11006 | P14: =WP!O20+GJP!O20+SBET!O20+Sugarplay!P20 -> 59989236 | Q14: =WP!P20+GJP!P20+SBET!P20+Sugarplay!Q20 -> 55758780 | R14: =WP!R20+GJP!R20+SBET!R20+Sugarplay!S20 -> 57642732 | S14: =T14/Q14 -> 0.010622436 | T14: =WP!S20+GJP!S20+SBET!S20+Sugarplay!T20 -> 592294.08 | U14: =WP!T20+GJP!T20+SBET!T20+Sugarplay!U20 -> 243554.97 | V14: =WP!U20+GJP!U20+SBET!U20+Sugarplay!V20 -> 26864.98 | W14: =P14-R14-T14 -> 1754210.2 | X14: =W14/P14 -> 0.029242082 | Y14: =(P14-R14)/P14 -> 0.039115421 | Z14: =WP!AE20+GJP!AE20+SBET!AF20+Sugarplay!AG20 -> 1808352.5 | AA14: =AB14+AC14 -> 192 | AB14: =WP!AA20+GJP!AA20+SBET!AB20+Sugarplay!AC20 -> 192 | AC14: =WP!AB20+GJP!AB20+SBET!AC20+Sugarplay!AD20 -> 0 | AD14: =W14-AB14-AC14 -> 1754018.2 | AE14: =AD14/P14 -> 0.029238881 | AF14: =AG14+AH14 -> 228981.39 | AG14: =WP!W20+GJP!W20+SBET!W20+Sugarplay!X20 -> 212733.99 | AH14: =WP!X20+GJP!X20+SBET!X20+Sugarplay!Y20 -> 16247.4 | AI14: =W14*0.09 -> 157878.91 | AM14: =W14-AB14-AC14-AG14-AH14-AI14 -> 1367157.9 | AN14: =AM14/P14 -> 0.022790053 | AO14: =WP!AC20+GJP!AC20+SBET!AD20+Sugarplay!AE20 -> 2100 | AP14: =WP!AD20+GJP!AD20+SBET!AE20+Sugarplay!AF20 -> -17213.99 | AQ14: =AD14-AG14-AH14-AI14 -> 1367157.9 | AR14: =AM14-AQ14 -> 0
A15: =A14+1 -> 46094 | B15: =WP!L21+GJP!L21+SBET!L21+Sugarplay!L21 -> 0 | C15: =WP!K21+GJP!K21+SBET!K21+Sugarplay!K21 -> 0 | D15: =WP!M21+GJP!M21+SBET!M21+Sugarplay!N21 -> 0 | E15: =B15-D15 -> 0 | F15: =W15 -> 0 | G15: =AD15 -> 0 | H15: =AM15 -> 0 | I15: =WP!D21+GJP!D21+SBET!D21+Sugarplay!D21 -> 0 | J15: =WP!J21+GJP!J21+SBET!J21+Sugarplay!J21 -> 0 | K15: =WP!B21+GJP!B21+SBET!B21+Sugarplay!B21 -> 0 | L15: =WP!C21+GJP!C21+SBET!C21+Sugarplay!C21 -> 0 | M15: =WP!E21+GJP!E21+SBET!E21+Sugarplay!E21 -> 0 | N15: =WP!F21+GJP!F21+SBET!F21+Sugarplay!F21 -> 0 | O15: =WP!G21+GJP!G21+SBET!G21+Sugarplay!G21 -> 0 | P15: =WP!O21+GJP!O21+SBET!O21+Sugarplay!P21 -> 0 | Q15: =WP!P21+GJP!P21+SBET!P21+Sugarplay!Q21 -> 0 | R15: =WP!R21+GJP!R21+SBET!R21+Sugarplay!S21 -> 0 | S15: =T15/Q15 -> #DIV/0! | T15: =WP!S21+GJP!S21+SBET!S21+Sugarplay!T21 -> 0 | U15: =WP!T21+GJP!T21+SBET!T21+Sugarplay!U21 -> 0 | V15: =WP!U21+GJP!U21+SBET!U21+Sugarplay!V21 -> 0 | W15: =P15-R15-T15 -> 0 | X15: =W15/P15 -> #DIV/0! | Y15: =(P15-R15)/P15 -> #DIV/0! | Z15: =WP!AE21+GJP!AE21+SBET!AF21+Sugarplay!AG21 -> 0 | AA15: =AB15+AC15 -> 0 | AB15: =WP!AA21+GJP!AA21+SBET!AB21+Sugarplay!AC21 -> 0 | AC15: =WP!AB21+GJP!AB21+SBET!AC21+Sugarplay!AD21 -> 0 | AD15: =W15-AB15-AC15 -> 0 | AE15: =AD15/P15 -> #DIV/0! | AF15: =AG15+AH15 -> 0 | AG15: =WP!W21+GJP!W21+SBET!W21+Sugarplay!X21 -> 0 | AH15: =WP!X21+GJP!X21+SBET!X21+Sugarplay!Y21 -> 0 | AI15: =W15*0.09 -> 0 | AM15: =W15-AB15-AC15-AG15-AH15-AI15 -> 0 | AN15: =AM15/P15 -> #DIV/0! | AO15: =WP!AC21+GJP!AC21+SBET!AD21+Sugarplay!AE21 -> 0 | AP15: =WP!AD21+GJP!AD21+SBET!AE21+Sugarplay!AF21 -> 0 | AQ15: =AD15-AG15-AH15-AI15 -> 0 | AR15: =AM15-AQ15 -> 0
... A33: =A32+1 -> 46112 | B33: =WP!L39+GJP!L39+SBET!L39+Sugarplay!L39 -> 0 | C33: =WP!K39+GJP!K39+SBET!K39+Sugarplay!K39 -> 0 | D33: =WP!M39+GJP!M39+SBET!M39+Sugarplay!N39 -> 0 | E33: =B33-D33 -> 0 | F33: =W33 -> 0 | G33: =AD33 -> 0 | H33: =AM33 -> 0 | I33: =WP!D39+GJP!D39+SBET!D39+Sugarplay!D39 -> 0 | J33: =WP!J39+GJP!J39+SBET!J39+Sugarplay!J39 -> 0 | K33: =WP!B39+GJP!B39+SBET!B39+Sugarplay!B39 -> 0 | L33: =WP!C39+GJP!C39+SBET!C39+Sugarplay!C39 -> 0 | M33: =WP!E39+GJP!E39+SBET!E39+Sugarplay!E39 -> 0 | N33: =WP!F39+GJP!F39+SBET!F39+Sugarplay!F39 -> 0 | O33: =WP!G39+GJP!G39+SBET!G39+Sugarplay!G39 -> 0 | P33: =WP!O39+GJP!O39+SBET!O39+Sugarplay!P39 -> 0 | Q33: =WP!P39+GJP!P39+SBET!P39+Sugarplay!Q39 -> 0 | R33: =WP!R39+GJP!R39+SBET!R39+Sugarplay!S39 -> 0 | S33: =T33/Q33 -> #DIV/0! | T33: =WP!S39+GJP!S39+SBET!S39+Sugarplay!T39 -> 0 | U33: =WP!T39+GJP!T39+SBET!T39+Sugarplay!U39 -> 0 | V33: =WP!U39+GJP!U39+SBET!U39+Sugarplay!V39 -> 0 | W33: =P33-R33-T33 -> 0 | X33: =W33/P33 -> #DIV/0! | Y33: =(P33-R33)/P33 -> #DIV/0! | Z33: =WP!AE39+GJP!AE39+SBET!AF39+Sugarplay!AG39 -> 0 | AA33: =AB33+AC33 -> 0 | AB33: =WP!AA39+GJP!AA39+SBET!AB39+Sugarplay!AC39 -> 0 | AC33: =WP!AB39+GJP!AB39+SBET!AC39+Sugarplay!AD39 -> 0 | AD33: =W33-AB33-AC33 -> 0 | AE33: =AD33/P33 -> #DIV/0! | AF33: =AG33+AH33 -> 0 | AG33: =WP!W39+GJP!W39+SBET!W39+Sugarplay!X39 -> 0 | AH33: =WP!X39+GJP!X39+SBET!X39+Sugarplay!Y39 -> 0 | AI33: =W33*0.09 -> 0 | AM33: =W33-AB33-AC33-AG33-AH33-AI33 -> 0 | AN33: =AM33/P33 -> #DIV/0! | AO33: =WP!AC39+GJP!AC39+SBET!AD39+Sugarplay!AE39 -> 0 | AP33: =WP!AD39+GJP!AD39+SBET!AE39+Sugarplay!AF39 -> 0 | AQ33: =AD33-AG33-AH33-AI33 -> 0 | AR33: =AM33-AQ33 -> 0
A34: 日均 | B34: =AVERAGE(B3:B14) -> 9747411.2 | C34: =AVERAGE(C3:C14) -> 85846.158 | D34: =AVERAGE(D3:D14) -> 8517410.4 | E34: =AVERAGE(E3:E14) -> 1230000.7 | F34: =AVERAGE(F3:F14) -> 1479550.5 | G34: =AVERAGE(G3:G14) -> 1276313.8 | H34: =AVERAGE(H3:H14) -> 898337.61 | I34: =AVERAGE(I3:I14) -> 34485.917 | ... R34: =AVERAGE(R3:R14) -> 63483547 | S34: =T312/Q312 -> #DIV/0! | T34: =AVERAGE(T3:T14) -> 645315.47 | U34: =AVERAGE(U3:U14) -> 260022.74 | V34: =AVERAGE(V3:V14) -> 33513.263 | W34: =AVERAGE(W3:W14) -> 1479550.5 | X34: =W312/P312 -> #DIV/0! | Y34: =(P312-R312)/P312 -> #DIV/0! | Z34: =AVERAGE(Z3:Z14) -> 2091423.5 | AA34: =AVERAGE(AA3:AA14) -> 203236.73 | AB34: =AVERAGE(AB3:AB14) -> 203236.73 | AC34: =AVERAGE(AC3:AC14) -> 0 | AD34: =AVERAGE(AD3:AD14) -> 1276313.8 | AE34: =AD312/P312 -> #DIV/0! | AF34: =AVERAGE(AF3:AF14) -> 244816.64 | AG34: =AVERAGE(AG3:AG14) -> 227781.78 | AH34: =AVERAGE(AH3:AH14) -> 17034.866 | AI34: =AVERAGE(AI3:AI14) -> 133159.55 | AJ34: =AVERAGE(AJ3:AJ14) -> 0 | AK34: =AVERAGE(AK3:AK14) -> 0 | AL34: =AVERAGE(AL3:AL14) -> 0 | AM34: =AVERAGE(AM3:AM14) -> 898337.61 | AN34: =AM312/P312 -> #DIV/0! | AO34: =AVERAGE(AO3:AO14) -> 14005.55 | AP34: =AVERAGE(AP3:AP14) -> -26856.257 | AQ34: =AVERAGE(AQ3:AQ14) -> 898337.61 | AR34: =AVERAGE(AR3:AR14) -> 0
A35: 汇总 | B35: =SUM(B3:B33) -> 1.1696893e+08 | C35: =SUM(C3:C33) -> 1030153.9 | D35: =SUM(D3:D33) -> 102208925 | E35: =SUM(E3:E33) -> 14760009 | F35: =SUM(F3:F33) -> 17754606 | G35: =SUM(G3:G33) -> 15315766 | H35: =SUM(H3:H33) -> 10780051 | I35: =SUM(I3:I33) -> 413831 | ... R35: =SUM(R3:R33) -> 7.6180257e+08 | S35: =T35/Q35 -> 0.010556402 | T35: =SUM(T3:T33) -> 7743785.6 | U35: =SUM(U3:U33) -> 3120272.9 | V35: =SUM(V3:V33) -> 402159.16 | W35: =SUM(W3:W33) -> 17754606 | X35: =W35/P35 -> 0.022551232 | Y35: =(P35-R35)/P35 -> 0.032387096 | Z35: =SUM(Z3:Z33) -> 25097081 | AA35: =SUM(AA3:AA33) -> 2438840.7 | AB35: =SUM(AB3:AB33) -> 2438840.7 | AC35: =SUM(AC3:AC33) -> 0 | AD35: =SUM(AD3:AD33) -> 15315766 | AE35: =AD35/P35 -> 0.019453508 | AF35: =SUM(AF3:AF33) -> 2937799.7 | AG35: =SUM(AG3:AG33) -> 2733381.3 | AH35: =SUM(AH3:AH33) -> 204418.39 | AI35: =SUM(AI3:AI33) -> 1597914.6 | AJ35: =SUM(AJ3:AJ33) -> 0 | AK35: =SUM(AK3:AK33) -> 0 | AL35: =SUM(AL3:AL33) -> 0 | AM35: =SUM(AM3:AM33) -> 10780051 | AN35: =AM35/P35 -> 0.013692415 | AO35: =SUM(AO3:AO33) -> 168066.6 | AP35: =SUM(AP3:AP33) -> -322275.09 | AQ35: =SUM(AQ3:AQ33) -> 10780051 | AR35: =SUM(AR3:AR33) -> 0
A36: 核对 | B36: =WP!L40+GJP!L40+SBET!L40+Sugarplay!L40 -> 1.1696893e+08 | C36: =WP!K40+GJP!K40+SBET!K40+Sugarplay!K40 -> 1030153.9 | D36: =WP!M40+GJP!M40+SBET!M40+Sugarplay!N40 -> 102208925 | E36: =E35 -> 14760009 | F36: =F35 -> 17754606 | G36: =G35 -> 15315766 | H36: =H35 -> 10780051 | I36: =WP!D40+GJP!D40+SBET!D40+Sugarplay!D40 -> 413831 | J36: =WP!J40+GJP!J40+SBET!J40+Sugarplay!J40 -> 290144 | K36: =WP!B40+GJP!B40+SBET!B40+Sugarplay!B40 -> 14713 | L36: =WP!C40+GJP!C40+SBET!C40+Sugarplay!C40 -> 4871 | M36: =WP!E40+GJP!E40+SBET!E40+Sugarplay!E40 -> 10272 | N36: =WP!F40+GJP!F40+SBET!F40+Sugarplay!F40 -> 61637 | O36: =WP!G40+GJP!G40+SBET!G40+Sugarplay!G40 -> 137802 | P36: =WP!O40+GJP!O40+SBET!O40+Sugarplay!P40 -> 7.8730096e+08 | Q36: =WP!P40+GJP!P40+SBET!P40+Sugarplay!Q40 -> 7.3356295e+08 | R36: =WP!R40+GJP!R40+SBET!R40+Sugarplay!S40 -> 7.6180257e+08 | S36: =T36/Q36 -> 0.010556402 | T36: =WP!S40+GJP!S40+SBET!S40+Sugarplay!T40 -> 7743785.6 | U36: =WP!T40+GJP!T40+SBET!T40+Sugarplay!U40 -> 3120272.9 | V36: =WP!U40+GJP!U40+SBET!U40+Sugarplay!V40 -> 402159.16 | W36: =W35 -> 17754606 | X36: =W36/P36 -> 0.022551232 | Y36: =(P36-R36)/P36 -> 0.032387096 | Z36: =WP!AE40+GJP!AE40+SBET!AF40+Sugarplay!AG40 -> 25097081 | AA36: =AA35 -> 2438840.7 | AB36: =WP!AA40+GJP!AA40+SBET!AB40+Sugarplay!AC40 -> 2438840.7 | AC36: =WP!AB40+GJP!AB40+SBET!AC40+Sugarplay!AD40 -> 0 | AD36: =AD35 -> 15315766 | AE36: =AD36/P36 -> 0.019453508 | AF36: =AF35 -> 2937799.7 | AG36: =WP!W40+GJP!W40+SBET!W40+Sugarplay!X40 -> 2733381.3 | AH36: =WP!X40+GJP!X40+SBET!X40+Sugarplay!Y40 -> 204418.39 | AI36: =AI35 -> 1597914.6 | AM36: =AM35 -> 10780051 | AN36: =AM36/P36 -> 0.013692415 | AO36: =WP!AC40+GJP!AC40+SBET!AD40+Sugarplay!AE40 -> 168066.6 | AP36: =WP!AD40+GJP!AD40+SBET!AE40+Sugarplay!AF40 -> -322275.09 | AQ36: =AQ35 -> 10780051
A37: 差额 | B37: =B35-B36 -> 0 | D37: =D35-D36 -> 0 | E37: =E35-E36 -> 0 | F37: =F35-F36 -> 0 | G37: =G35-G36 -> 0 | H37: =H35-H36 -> 0 | I37: =I35-I36 -> 0 | J37: =J35-J36 -> 0 | K37: =K35-K36 -> 0 | ... AR37: =AR35-AR36 -> 0

Sheet 2025全年数据走势图
A1: 日期（2026） | B1: 充值 | C1: 提款 | D1: 充提差 | E1: GP1 | F1: GP2 | G1: GP3 | H1: 登录人数 | I1: 投注人数 | J1: 注册人数 | K1: 首充人数 | L1: 续存人数 | M1: 存款人数 | N1: 存款次数
A2: 1月 | B2: 2.7291086e+08 | C2: 236484767 | D2: 36426090 | E2: 41032556 | F2: 35740695 | G2: 25206321 | H2: 1086977 | I2: 726629 | J2: 43787 | K2: 12835 | L2: 28958 | M2: 179147 | N2: 383067
A3: 2月 | B3: 2.2760305e+08 | C3: 199641810 | D3: 27961236 | E3: 36628676 | F3: 29814588 | G3: 20795632 | H3: 819553 | I3: 576036 | J3: 25813 | K3: 8691 | L3: 21438 | M3: 133324 | N3: 291800
A4: 3月 | B4: =全平台汇总!$B$35 -> 1.1696893e+08 | C4: =全平台汇总!$D$35 -> 102208925 | D4: =全平台汇总!$E$35 -> 14760009 | E4: =全平台汇总!$F$35 -> 17754606 | F4: =全平台汇总!$G$35 -> 15315766 | G4: =全平台汇总!$H$35 -> 10780051 | H4: =全平台汇总!$I$35 -> 413831 | I4: =全平台汇总!$J$35 -> 290144 | J4: =全平台汇总!$K$35 -> 14713 | K4: =全平台汇总!$L$35 -> 4871 | L4: =全平台汇总!$M$35 -> 10272 | M4: =全平台汇总!$N$35 -> 61637 | N4: =全平台汇总!$O$35 -> 137802
A5: 5月
A6: 5月
A7: 6月
A8: 7月
A9: 8月
A10: 9月
A11: 10月
A12: 11月
A13: 12月
A14: 月均 | B14: =AVERAGE(B2:B13) -> 2.0582761e+08 | C14: =AVERAGE(C2:C13) -> 1.7944517e+08 | D14: =AVERAGE(D2:D13) -> 26382445 | E14: =AVERAGE(E2:E13) -> 31805280 | F14: =AVERAGE(F2:F13) -> 26957016 | G14: =AVERAGE(G2:G13) -> 18927335 | H14: =AVERAGE(H2:H13) -> 773453.67 | I14: =AVERAGE(I2:I13) -> 530936.33 | ... N14: =AVERAGE(N2:N13) -> 270889.67
A15: 求和 | B15: =SUM(B2:B13) -> 6.1748284e+08 | C15: =SUM(C2:C13) -> 538335502 | D15: =SUM(D2:D13) -> 79147334 | E15: =SUM(E2:E13) -> 95415839 | F15: =SUM(F2:F13) -> 80871048 | G15: =SUM(G2:G13) -> 56782005 | H15: =SUM(H2:H13) -> 2320361 | I15: =SUM(I2:I13) -> 1592809 | ... N15: =SUM(N2:N13) -> 812669

Sheet 天成系统
A1: =全平台汇总!A1 -> 46093 | F1: Winplus / Go Jackpot / SBET / Sugarplay 平台关键数据报表 | P1: 平台详细数据填制区
A2: 日期 | B2: 充值 | C2: 首存金额 | D2: 提款 | E2: 充提差 | F2: GP1 | G2: GP2 | H2: GP3 | I2: 登录人数 | J2: 投注人数 | K2: 注册人数 | L2: 首充人数 | M2: 续存人数 | N2: 存款人数 | O2: 存款次数 | P2: 投注 | Q2: 有效投注 | R2: 派彩 | S2: 综合优惠比 | T2: 活动红利 | U2: 返点 | V2: 邀请返佣 | W2: GP1 | X2: GP1杀率 | Y2: 游戏杀率 | Z2: 平台余额 | AA2: 周结&月结佣金 | AB2: 周结代理佣金 | AC2: 月结代理佣金 | AD2: GP2 | AE2: GP2杀率 | AF2: 存提手续费 | AG2: 存款手续费 | AH2: 提款手续费 | AI2: 平台费 | AJ2: 包网费(U） | AK2: 汇率 | AL2: 换算P | AM2: GP3 | AN2: GP3杀率 | AO2: 开分 | AP2: 洗分 | AQ2: 核对 | AR2: 差额
A3: =全平台汇总!A3 -> 46082 | B3: =WP!L9+GJP!L9+SBET!L9+Sugarplay!L9 -> 10012561 | C3: =WP!K9+GJP!K9+SBET!K9+Sugarplay!K9 -> 101494 | D3: =WP!M9+GJP!M9+SBET!M9+Sugarplay!N9 -> 9438631 | E3: =B3-D3 -> 573929.6 | F3: =W3 -> 1023619.1 | G3: =AD3 -> 1023619.1 | H3: =AM3 -> 677871.75 | I3: =WP!D9+GJP!D9+SBET!D9+Sugarplay!D9 -> 37276 | J3: =WP!J9+GJP!J9+SBET!J9+Sugarplay!J9 -> 23624 | K3: =WP!B9+GJP!B9+SBET!B9+Sugarplay!B9 -> 1333 | L3: =WP!C9+GJP!C9+SBET!C9+Sugarplay!C9 -> 410 | M3: =WP!E9+GJP!E9+SBET!E9+Sugarplay!E9 -> 992 | N3: =WP!F9+GJP!F9+SBET!F9+Sugarplay!F9 -> 5857 | O3: =WP!G9+GJP!G9+SBET!G9+Sugarplay!G9 -> 12355 | P3: =WP!O9+GJP!O9+SBET!O9+Sugarplay!P9 -> 67076153 | Q3: =WP!P9+GJP!P9+SBET!P9+Sugarplay!Q9 -> 62681990 | R3: =WP!R9+GJP!R9+SBET!R9+Sugarplay!S9 -> 65320984 | S3: =T3/Q3 -> 0.011670818 | T3: =WP!S9+GJP!S9+SBET!S9+Sugarplay!T9 -> 731550.07 | U3: =WP!T9+GJP!T9+SBET!T9+Sugarplay!U9 -> 284236.48 | V3: =WP!U9+GJP!U9+SBET!U9+Sugarplay!V9 -> 29250.28 | W3: =P3-R3-T3 -> 1023619.1 | X3: =W3/P3 -> 0.015260552 | Y3: =(P3-R3)/P3 -> 0.026166814 | Z3: =WP!AE9+GJP!AE9+SBET!AF9+Sugarplay!AG9 -> 1965001.1 | AA3: =AB3+AC3 -> 0 | AB3: =WP!AA9+GJP!AA9+SBET!AB9+Sugarplay!AC9 -> 0 | AC3: =WP!AB9+GJP!AB9+SBET!AC9+Sugarplay!AD9 -> 0 | AD3: =W3-AB3-AC3 -> 1023619.1 | AE3: =AD3/P3 -> 0.015260552 | AF3: =AG3+AH3 -> 253621.64 | AG3: =WP!W9+GJP!W9+SBET!W9+Sugarplay!X9 -> 234744.3 | AH3: =WP!X9+GJP!X9+SBET!X9+Sugarplay!Y9 -> 18877.34 | AI3: =W3*0.09 -> 92125.72 | AJ3: 0 | AK3: 0 | AL3: 0 | AM3: =W3-AB3-AC3-AG3-AH3-AI3 -> 677871.75 | AN3: =AM3/P3 -> 0.010106002 | AO3: =WP!AC9+GJP!AC9+SBET!AD9+Sugarplay!AE9 -> 100 | AP3: =WP!AD9+GJP!AD9+SBET!AE9+Sugarplay!AF9 -> -2554.33 | AQ3: =AD3-AG3-AH3-AI3 -> 677871.75 | AR3: =AM3-AQ3 -> 0
A4: =全平台汇总!A4 -> 46083 | B4: =WP!L10+GJP!L10+SBET!L10+Sugarplay!L10 -> 8816812.6 | C4: =WP!K10+GJP!K10+SBET!K10+Sugarplay!K10 -> 88437 | D4: =WP!M10+GJP!M10+SBET!M10+Sugarplay!N10 -> 8989445 | E4: =B4-D4 -> -172632.43 | F4: =W4 -> 817069.84 | G4: =AD4 -> -209948.92 | H4: =AM4 -> -508126 | I4: =WP!D10+GJP!D10+SBET!D10+Sugarplay!D10 -> 30062 | J4: =WP!J10+GJP!J10+SBET!J10+Sugarplay!J10 -> 19932 | K4: =WP!B10+GJP!B10+SBET!B10+Sugarplay!B10 -> 1326 | L4: =WP!C10+GJP!C10+SBET!C10+Sugarplay!C10 -> 384 | M4: =WP!E10+GJP!E10+SBET!E10+Sugarplay!E10 -> 903 | N4: =WP!F10+GJP!F10+SBET!F10+Sugarplay!F10 -> 4985 | O4: =WP!G10+GJP!G10+SBET!G10+Sugarplay!G10 -> 10948 | P4: =WP!O10+GJP!O10+SBET!O10+Sugarplay!P10 -> 57155008 | Q4: =WP!P10+GJP!P10+SBET!P10+Sugarplay!Q10 -> 53233162 | R4: =WP!R10+GJP!R10+SBET!R10+Sugarplay!S10 -> 55716597 | S4: =T4/Q4 -> 0.011672072 | T4: =WP!S10+GJP!S10+SBET!S10+Sugarplay!T10 -> 621341.32 | U4: =WP!T10+GJP!T10+SBET!T10+Sugarplay!U10 -> 249517.97 | V4: =WP!U10+GJP!U10+SBET!U10+Sugarplay!V10 -> 40804.38 | W4: =P4-R4-T4 -> 817069.84 | X4: =W4/P4 -> 0.014295682 | Y4: =(P4-R4)/P4 -> 0.025166844 | Z4: =WP!AE10+GJP!AE10+SBET!AF10+Sugarplay!AG10 -> 1882353.4 | AA4: =AB4+AC4 -> 1027018.8 | AB4: =WP!AA10+GJP!AA10+SBET!AB10+Sugarplay!AC10 -> 1027018.8 | AC4: =WP!AB10+GJP!AB10+SBET!AC10+Sugarplay!AD10 -> 0 | AD4: =W4-AB4-AC4 -> -209948.92 | AE4: =AD4/P4 -> -0.003673325 | AF4: =AG4+AH4 -> 224640.79 | AG4: =WP!W10+GJP!W10+SBET!W10+Sugarplay!X10 -> 206662.07 | AH4: =WP!X10+GJP!X10+SBET!X10+Sugarplay!Y10 -> 17978.72 | AI4: =W4*0.09 -> 73536.286 | AM4: =W4-AB4-AC4-AG4-AH4-AI4 -> -508126 | AN4: =AM4/P4 -> -0.0088903145 | AO4: =WP!AC10+GJP!AC10+SBET!AD10+Sugarplay!AE10 -> 24934.69 | AP4: =WP!AD10+GJP!AD10+SBET!AE10+Sugarplay!AF10 -> -5158.46 | AQ4: =AD4-AG4-AH4-AI4 -> -508126 | AR4: =AM4-AQ4 -> 0
A5: =全平台汇总!A5 -> 46084 | B5: =WP!L11+GJP!L11+SBET!L11+Sugarplay!L11 -> 9493443 | C5: =WP!K11+GJP!K11+SBET!K11+Sugarplay!K11 -> 81720 | D5: =WP!M11+GJP!M11+SBET!M11+Sugarplay!N11 -> 7971259 | E5: =B5-D5 -> 1522184 | F5: =W5 -> 1120695 | G5: =AD5 -> 1116040 | H5: =AM5 -> 777674.26 | I5: =WP!D11+GJP!D11+SBET!D11+Sugarplay!D11 -> 32603 | J5: =WP!J11+GJP!J11+SBET!J11+Sugarplay!J11 -> 20872 | K5: =WP!B11+GJP!B11+SBET!B11+Sugarplay!B11 -> 1273 | L5: =WP!C11+GJP!C11+SBET!C11+Sugarplay!C11 -> 385 | M5: =WP!E11+GJP!E11+SBET!E11+Sugarplay!E11 -> 840 | N5: =WP!F11+GJP!F11+SBET!F11+Sugarplay!F11 -> 4859 | O5: =WP!G11+GJP!G11+SBET!G11+Sugarplay!G11 -> 10981 | P5: =WP!O11+GJP!O11+SBET!O11+Sugarplay!P11 -> 68808339 | Q5: =WP!P11+GJP!P11+SBET!P11+Sugarplay!Q11 -> 64088379 | R5: =WP!R11+GJP!R11+SBET!R11+Sugarplay!S11 -> 67156074 | S5: =T5/Q5 -> 0.00829434 | T5: =WP!S11+GJP!S11+SBET!S11+Sugarplay!T11 -> 531570.81 | U5: =WP!T11+GJP!T11+SBET!T11+Sugarplay!U11 -> 220355.21 | V5: =WP!U11+GJP!U11+SBET!U11+Sugarplay!V11 -> 31186.92 | W5: =P5-R5-T5 -> 1120695 | X5: =W5/P5 -> 0.016287197 | Y5: =(P5-R5)/P5 -> 0.024012581 | Z5: =WP!AE11+GJP!AE11+SBET!AF11+Sugarplay!AG11 -> 1834307.9 | AA5: =AB5+AC5 -> 4655 | AB5: =WP!AA11+GJP!AA11+SBET!AB11+Sugarplay!AC11 -> 4655 | AC5: =WP!AB11+GJP!AB11+SBET!AC11+Sugarplay!AD11 -> 0 | AD5: =W5-AB5-AC5 -> 1116040 | AE5: =AD5/P5 -> 0.016219545 | AF5: =AG5+AH5 -> 237503.17 | AG5: =WP!W11+GJP!W11+SBET!W11+Sugarplay!X11 -> 221560.78 | AH5: =WP!X11+GJP!X11+SBET!X11+Sugarplay!Y11 -> 15942.39 | AI5: =W5*0.09 -> 100862.55 | AM5: =W5-AB5-AC5-AG5-AH5-AI5 -> 777674.26 | AN5: =AM5/P5 -> 0.011302035 | AO5: =WP!AC11+GJP!AC11+SBET!AD11+Sugarplay!AE11 -> 14094.8 | AP5: =WP!AD11+GJP!AD11+SBET!AE11+Sugarplay!AF11 -> -56452.86 | AQ5: =AD5-AG5-AH5-AI5 -> 777674.26 | AR5: =AM5-AQ5 -> 0
A6: =全平台汇总!A6 -> 46085 | B6: =WP!L12+GJP!L12+SBET!L12+Sugarplay!L12 -> 11799989 | C6: =WP!K12+GJP!K12+SBET!K12+Sugarplay!K12 -> 108144 | D6: =WP!M12+GJP!M12+SBET!M12+Sugarplay!N12 -> 9658460 | E6: =B6-D6 -> 2141529.1 | F6: =W6 -> 1836446 | G6: =AD6 -> 1836288 | H6: =AM6 -> 1375940.2 | I6: =WP!D12+GJP!D12+SBET!D12+Sugarplay!D12 -> 36056 | J6: =WP!J12+GJP!J12+SBET!J12+Sugarplay!J12 -> 22720 | K6: =WP!B12+GJP!B12+SBET!B12+Sugarplay!B12 -> 1133 | L6: =WP!C12+GJP!C12+SBET!C12+Sugarplay!C12 -> 456 | M6: =WP!E12+GJP!E12+SBET!E12+Sugarplay!E12 -> 857 | N6: =WP!F12+GJP!F12+SBET!F12+Sugarplay!F12 -> 5303 | O6: =WP!G12+GJP!G12+SBET!G12+Sugarplay!G12 -> 11724 | P6: =WP!O12+GJP!O12+SBET!O12+Sugarplay!P12 -> 81349421 | Q6: =WP!P12+GJP!P12+SBET!P12+Sugarplay!Q12 -> 75596780 | R6: =WP!R12+GJP!R12+SBET!R12+Sugarplay!S12 -> 78804731 | S6: =T6/Q6 -> 0.0093686982 | T6: =WP!S12+GJP!S12+SBET!S12+Sugarplay!T12 -> 708243.42 | U6: =WP!T12+GJP!T12+SBET!T12+Sugarplay!U12 -> 318389.11 | V6: =WP!U12+GJP!U12+SBET!U12+Sugarplay!V12 -> 39667.62 | W6: =P6-R6-T6 -> 1836446 | X6: =W6/P6 -> 0.022574789 | Y6: =(P6-R6)/P6 -> 0.031280978 | Z6: =WP!AE12+GJP!AE12+SBET!AF12+Sugarplay!AG12 -> 2275472.5 | AA6: =AB6+AC6 -> 158 | AB6: =WP!AA12+GJP!AA12+SBET!AB12+Sugarplay!AC12 -> 158 | AC6: =WP!AB12+GJP!AB12+SBET!AC12+Sugarplay!AD12 -> 0 | AD6: =W6-AB6-AC6 -> 1836288 | AE6: =AD6/P6 -> 0.022572847 | AF6: =AG6+AH6 -> 295067.71 | AG6: =WP!W12+GJP!W12+SBET!W12+Sugarplay!X12 -> 275750.39 | AH6: =WP!X12+GJP!X12+SBET!X12+Sugarplay!Y12 -> 19317.32 | AI6: =W6*0.09 -> 165280.14 | AM6: =W6-AB6-AC6-AG6-AH6-AI6 -> 1375940.2 | AN6: =AM6/P6 -> 0.016913952 | AO6: =WP!AC12+GJP!AC12+SBET!AD12+Sugarplay!AE12 -> 0 | AP6: =WP!AD12+GJP!AD12+SBET!AE12+Sugarplay!AF12 -> -693.1 | AQ6: =AD6-AG6-AH6-AI6 -> 1375940.2 | AR6: =AM6-AQ6 -> 0
A7: =全平台汇总!A7 -> 46086 | B7: =WP!L13+GJP!L13+SBET!L13+Sugarplay!L13 -> 11070696 | C7: =WP!K13+GJP!K13+SBET!K13+Sugarplay!K13 -> 104683 | D7: =WP!M13+GJP!M13+SBET!M13+Sugarplay!N13 -> 9393354 | E7: =B7-D7 -> 1677341.8 | F7: =W7 -> 1716183.1 | G7: =AD7 -> 1715683.1 | H7: =AM7 -> 1283730.2 | I7: =WP!D13+GJP!D13+SBET!D13+Sugarplay!D13 -> 30390 | J7: =WP!J13+GJP!J13+SBET!J13+Sugarplay!J13 -> 20570 | K7: =WP!B13+GJP!B13+SBET!B13+Sugarplay!B13 -> 1126 | L7: =WP!C13+GJP!C13+SBET!C13+Sugarplay!C13 -> 373 | M7: =WP!E13+GJP!E13+SBET!E13+Sugarplay!E13 -> 843 | N7: =WP!F13+GJP!F13+SBET!F13+Sugarplay!F13 -> 4861 | O7: =WP!G13+GJP!G13+SBET!G13+Sugarplay!G13 -> 11389 | P7: =WP!O13+GJP!O13+SBET!O13+Sugarplay!P13 -> 74995038 | Q7: =WP!P13+GJP!P13+SBET!P13+Sugarplay!Q13 -> 70418491 | R7: =WP!R13+GJP!R13+SBET!R13+Sugarplay!S13 -> 72621807 | S7: =T7/Q7 -> 0.0093306258 | T7: =WP!S13+GJP!S13+SBET!S13+Sugarplay!T13 -> 657048.59 | U7: =WP!T13+GJP!T13+SBET!T13+Sugarplay!U13 -> 279745.75 | V7: =WP!U13+GJP!U13+SBET!U13+Sugarplay!V13 -> 36585.53 | W7: =P7-R7-T7 -> 1716183.1 | X7: =W7/P7 -> 0.022883956 | Y7: =(P7-R7)/P7 -> 0.031645183 | Z7: =WP!AE13+GJP!AE13+SBET!AF13+Sugarplay!AG13 -> 2290627.3 | AA7: =AB7+AC7 -> 500 | AB7: =WP!AA13+GJP!AA13+SBET!AB13+Sugarplay!AC13 -> 500 | AC7: =WP!AB13+GJP!AB13+SBET!AC13+Sugarplay!AD13 -> 0 | AD7: =W7-AB7-AC7 -> 1715683.1 | AE7: =AD7/P7 -> 0.022877288 | AF7: =AG7+AH7 -> 277496.43 | AG7: =WP!W13+GJP!W13+SBET!W13+Sugarplay!X13 -> 258709.75 | AH7: =WP!X13+GJP!X13+SBET!X13+Sugarplay!Y13 -> 18786.68 | AI7: =W7*0.09 -> 154456.48 | AM7: =W7-AB7-AC7-AG7-AH7-AI7 -> 1283730.2 | AN7: =AM7/P7 -> 0.017117535 | AO7: =WP!AC13+GJP!AC13+SBET!AD13+Sugarplay!AE13 -> 0 | AP7: =WP!AD13+GJP!AD13+SBET!AE13+Sugarplay!AF13 -> -15883.11 | AQ7: =AD7-AG7-AH7-AI7 -> 1283730.2 | AR7: =AM7-AQ7 -> 0
A8: =全平台汇总!A8 -> 46087 | B8: =WP!L14+GJP!L14+SBET!L14+Sugarplay!L14 -> 11336766 | C8: =WP!K14+GJP!K14+SBET!K14+Sugarplay!K14 -> 102748 | D8: =WP!M14+GJP!M14+SBET!M14+Sugarplay!N14 -> 9913747 | E8: =B8-D8 -> 1423019 | F8: =W8 -> 2163495.7 | G8: =AD8 -> 2162895.7 | H8: =AM8 -> 1684159.8 | I8: =WP!D14+GJP!D14+SBET!D14+Sugarplay!D14 -> 34834 | J8: =WP!J14+GJP!J14+SBET!J14+Sugarplay!J14 -> 25291 | K8: =WP!B14+GJP!B14+SBET!B14+Sugarplay!B14 -> 1211 | L8: =WP!C14+GJP!C14+SBET!C14+Sugarplay!C14 -> 418 | M8: =WP!E14+GJP!E14+SBET!E14+Sugarplay!E14 -> 855 | N8: =WP!F14+GJP!F14+SBET!F14+Sugarplay!F14 -> 5432 | O8: =WP!G14+GJP!G14+SBET!G14+Sugarplay!G14 -> 12047 | P8: =WP!O14+GJP!O14+SBET!O14+Sugarplay!P14 -> 76693220 | Q8: =WP!P14+GJP!P14+SBET!P14+Sugarplay!Q14 -> 71420335 | R8: =WP!R14+GJP!R14+SBET!R14+Sugarplay!S14 -> 73651319 | S8: =T8/Q8 -> 0.012299094 | T8: =WP!S14+GJP!S14+SBET!S14+Sugarplay!T14 -> 878405.45 | U8: =WP!T14+GJP!T14+SBET!T14+Sugarplay!U14 -> 355546.15 | V8: =WP!U14+GJP!U14+SBET!U14+Sugarplay!V14 -> 27739.37 | W8: =P8-R8-T8 -> 2163495.7 | X8: =W8/P8 -> 0.028209739 | Y8: =(P8-R8)/P8 -> 0.039663234 | Z8: =WP!AE14+GJP!AE14+SBET!AF14+Sugarplay!AG14 -> 1772925.9 | AA8: =AB8+AC8 -> 600 | AB8: =WP!AA14+GJP!AA14+SBET!AB14+Sugarplay!AC14 -> 600 | AC8: =WP!AB14+GJP!AB14+SBET!AC14+Sugarplay!AD14 -> 0 | AD8: =W8-AB8-AC8 -> 2162895.7 | AE8: =AD8/P8 -> 0.028201915 | AF8: =AG8+AH8 -> 284021.27 | AG8: =WP!W14+GJP!W14+SBET!W14+Sugarplay!X14 -> 264193.49 | AH8: =WP!X14+GJP!X14+SBET!X14+Sugarplay!Y14 -> 19827.78 | AI8: =W8*0.09 -> 194714.61 | AM8: =W8-AB8-AC8-AG8-AH8-AI8 -> 1684159.8 | AN8: =AM8/P8 -> 0.021959696 | AO8: =WP!AC14+GJP!AC14+SBET!AD14+Sugarplay!AE14 -> 0 | AP8: =WP!AD14+GJP!AD14+SBET!AE14+Sugarplay!AF14 -> -22828.95 | AQ8: =AD8-AG8-AH8-AI8 -> 1684159.8 | AR8: =AM8-AQ8 -> 0
A9: =全平台汇总!A9 -> 46088 | B9: =WP!L15+GJP!L15+SBET!L15+Sugarplay!L15 -> 9146001.2 | C9: =WP!K15+GJP!K15+SBET!K15+Sugarplay!K15 -> 80548 | D9: =WP!M15+GJP!M15+SBET!M15+Sugarplay!N15 -> 7388477 | E9: =B9-D9 -> 1757524.2 | F9: =W9 -> 2096383 | G9: =AD9 -> 2092285 | H9: =AM9 -> 1674812.2 | I9: =WP!D15+GJP!D15+SBET!D15+Sugarplay!D15 -> 31535 | J9: =WP!J15+GJP!J15+SBET!J15+Sugarplay!J15 -> 22766 | K9: =WP!B15+GJP!B15+SBET!B15+Sugarplay!B15 -> 1187 | L9: =WP!C15+GJP!C15+SBET!C15+Sugarplay!C15 -> 429 | M9: =WP!E15+GJP!E15+SBET!E15+Sugarplay!E15 -> 890 | N9: =WP!F15+GJP!F15+SBET!F15+Sugarplay!F15 -> 5370 | O9: =WP!G15+GJP!G15+SBET!G15+Sugarplay!G15 -> 12128 | P9: =WP!O15+GJP!O15+SBET!O15+Sugarplay!P15 -> 61440169 | Q9: =WP!P15+GJP!P15+SBET!P15+Sugarplay!Q15 -> 57446216 | R9: =WP!R15+GJP!R15+SBET!R15+Sugarplay!S15 -> 58710718 | S9: =T9/Q9 -> 0.011020182 | T9: =WP!S15+GJP!S15+SBET!S15+Sugarplay!T15 -> 633067.76 | U9: =WP!T15+GJP!T15+SBET!T15+Sugarplay!U15 -> 238979.64 | V9: =WP!U15+GJP!U15+SBET!U15+Sugarplay!V15 -> 44748.36 | W9: =P9-R9-T9 -> 2096383 | X9: =W9/P9 -> 0.034120723 | Y9: =(P9-R9)/P9 -> 0.044424531 | Z9: =WP!AE15+GJP!AE15+SBET!AF15+Sugarplay!AG15 -> 1822697.1 | AA9: =AB9+AC9 -> 4098 | AB9: =WP!AA15+GJP!AA15+SBET!AB15+Sugarplay!AC15 -> 4098 | AC9: =WP!AB15+GJP!AB15+SBET!AC15+Sugarplay!AD15 -> 0 | AD9: =W9-AB9-AC9 -> 2092285 | AE9: =AD9/P9 -> 0.034054023 | AF9: =AG9+AH9 -> 228798.32 | AG9: =WP!W15+GJP!W15+SBET!W15+Sugarplay!X15 -> 214021.57 | AH9: =WP!X15+GJP!X15+SBET!X15+Sugarplay!Y15 -> 14776.75 | AI9: =W9*0.09 -> 188674.47 | AM9: =W9-AB9-AC9-AG9-AH9-AI9 -> 1674812.2 | AN9: =AM9/P9 -> 0.027259238 | AO9: =WP!AC15+GJP!AC15+SBET!AD15+Sugarplay!AE15 -> 0 | AP9: =WP!AD15+GJP!AD15+SBET!AE15+Sugarplay!AF15 -> -6039.02 | AQ9: =AD9-AG9-AH9-AI9 -> 1674812.2 | AR9: =AM9-AQ9 -> 0
A10: =全平台汇总!A10 -> 46089 | B10: =WP!L16+GJP!L16+SBET!L16+Sugarplay!L16 -> 8743030.4 | C10: =WP!K16+GJP!K16+SBET!K16+Sugarplay!K16 -> 89151 | D10: =WP!M16+GJP!M16+SBET!M16+Sugarplay!N16 -> 7021701 | E10: =B10-D10 -> 1721329.4 | F10: =W10 -> 1430284.9 | G10: =AD10 -> 1430284.9 | H10: =AM10 -> 1083093 | I10: =WP!D16+GJP!D16+SBET!D16+Sugarplay!D16 -> 44452 | J10: =WP!J16+GJP!J16+SBET!J16+Sugarplay!J16 -> 35587 | K10: =WP!B16+GJP!B16+SBET!B16+Sugarplay!B16 -> 1495 | L10: =WP!C16+GJP!C16+SBET!C16+Sugarplay!C16 -> 475 | M10: =WP!E16+GJP!E16+SBET!E16+Sugarplay!E16 -> 861 | N10: =WP!F16+GJP!F16+SBET!F16+Sugarplay!F16 -> 5524 | O10: =WP!G16+GJP!G16+SBET!G16+Sugarplay!G16 -> 11873 | P10: =WP!O16+GJP!O16+SBET!O16+Sugarplay!P16 -> 59518719 | Q10: =WP!P16+GJP!P16+SBET!P16+Sugarplay!Q16 -> 55414312 | R10: =WP!R16+GJP!R16+SBET!R16+Sugarplay!S16 -> 57454100 | S10: =T10/Q10 -> 0.011447123 | T10: =WP!S16+GJP!S16+SBET!S16+Sugarplay!T16 -> 634334.47 | U10: =WP!T16+GJP!T16+SBET!T16+Sugarplay!U16 -> 219316.17 | V10: =WP!U16+GJP!U16+SBET!U16+Sugarplay!V16 -> 35016.34 | W10: =P10-R10-T10 -> 1430284.9 | X10: =W10/P10 -> 0.024030841 | Y10: =(P10-R10)/P10 -> 0.034688571 | Z10: =WP!AE16+GJP!AE16+SBET!AF16+Sugarplay!AG16 -> 1959603.2 | AA10: =AB10+AC10 -> 0 | AB10: =WP!AA16+GJP!AA16+SBET!AB16+Sugarplay!AC16 -> 0 | AC10: =WP!AB16+GJP!AB16+SBET!AC16+Sugarplay!AD16 -> 0 | AD10: =W10-AB10-AC10 -> 1430284.9 | AE10: =AD10/P10 -> 0.024030841 | AF10: =AG10+AH10 -> 218466.26 | AG10: =WP!W16+GJP!W16+SBET!W16+Sugarplay!X16 -> 204422.46 | AH10: =WP!X16+GJP!X16+SBET!X16+Sugarplay!Y16 -> 14043.8 | AI10: =W10*0.09 -> 128725.64 | AM10: =W10-AB10-AC10-AG10-AH10-AI10 -> 1083093 | AN10: =AM10/P10 -> 0.018197518 | AO10: =WP!AC16+GJP!AC16+SBET!AD16+Sugarplay!AE16 -> 0 | AP10: =WP!AD16+GJP!AD16+SBET!AE16+Sugarplay!AF16 -> -32070.54 | AQ10: =AD10-AG10-AH10-AI10 -> 1083093 | AR10: =AM10-AQ10 -> 0
A11: =全平台汇总!A11 -> 46090 | B11: =WP!L17+GJP!L17+SBET!L17+Sugarplay!L17 -> 8998021.2 | C11: =WP!K17+GJP!K17+SBET!K17+Sugarplay!K17 -> 84741 | D11: =WP!M17+GJP!M17+SBET!M17+Sugarplay!N17 -> 9075963 | E11: =B11-D11 -> -77941.79 | F11: =W11 -> 1168422.1 | G11: =AD11 -> -189137.81 | H11: =AM11 -> -522932.01 | I11: =WP!D17+GJP!D17+SBET!D17+Sugarplay!D17 -> 35036 | J11: =WP!J17+GJP!J17+SBET!J17+Sugarplay!J17 -> 26675 | K11: =WP!B17+GJP!B17+SBET!B17+Sugarplay!B17 -> 1324 | L11: =WP!C17+GJP!C17+SBET!C17+Sugarplay!C17 -> 465 | M11: =WP!E17+GJP!E17+SBET!E17+Sugarplay!E17 -> 812 | N11: =WP!F17+GJP!F17+SBET!F17+Sugarplay!F17 -> 4866 | O11: =WP!G17+GJP!G17+SBET!G17+Sugarplay!G17 -> 11121 | P11: =WP!O17+GJP!O17+SBET!O17+Sugarplay!P17 -> 62418180 | Q11: =WP!P17+GJP!P17+SBET!P17+Sugarplay!Q17 -> 57490214 | R11: =WP!R17+GJP!R17+SBET!R17+Sugarplay!S17 -> 60604634 | S11: =T11/Q11 -> 0.011221456 | T11: =WP!S17+GJP!S17+SBET!S17+Sugarplay!T17 -> 645123.92 | U11: =WP!T17+GJP!T17+SBET!T17+Sugarplay!U17 -> 251060.31 | V11: =WP!U17+GJP!U17+SBET!U17+Sugarplay!V17 -> 32777.63 | W11: =P11-R11-T11 -> 1168422.1 | X11: =W11/P11 -> 0.01871926 | Y11: =(P11-R11)/P11 -> 0.029054773 | Z11: =WP!AE17+GJP!AE17+SBET!AF17+Sugarplay!AG17 -> 2770004.3 | AA11: =AB11+AC11 -> 1357560 | AB11: =WP!AA17+GJP!AA17+SBET!AB17+Sugarplay!AC17 -> 1357560 | AC11: =WP!AB17+GJP!AB17+SBET!AC17+Sugarplay!AD17 -> 0 | AD11: =W11-AB11-AC11 -> -189137.81 | AE11: =AD11/P11 -> -0.0030301718 | AF11: =AG11+AH11 -> 228636.21 | AG11: =WP!W17+GJP!W17+SBET!W17+Sugarplay!X17 -> 210483.81 | AH11: =WP!X17+GJP!X17+SBET!X17+Sugarplay!Y17 -> 18152.4 | AI11: =W11*0.09 -> 105157.99 | AM11: =W11-AB11-AC11-AG11-AH11-AI11 -> -522932.01 | AN11: =AM11/P11 -> -0.0083778798 | AO11: =WP!AC17+GJP!AC17+SBET!AD17+Sugarplay!AE17 -> 123737.11 | AP11: =WP!AD17+GJP!AD17+SBET!AE17+Sugarplay!AF17 -> -147358.45 | AQ11: =AD11-AG11-AH11-AI11 -> -522932.01 | AR11: =AM11-AQ11 -> 0
A12: =全平台汇总!A12 -> 46091 | B12: =WP!L18+GJP!L18+SBET!L18+Sugarplay!L18 -> 8656049.1 | C12: =WP!K18+GJP!K18+SBET!K18+Sugarplay!K18 -> 65052 | D12: =WP!M18+GJP!M18+SBET!M18+Sugarplay!N18 -> 7894537 | E12: =B12-D12 -> 761512.14 | F12: =W12 -> 1049437.1 | G12: =AD12 -> 1005714.1 | H12: =AM12 -> 693346.95 | I12: =WP!D18+GJP!D18+SBET!D18+Sugarplay!D18 -> 33657 | J12: =WP!J18+GJP!J18+SBET!J18+Sugarplay!J18 -> 24070 | K12: =WP!B18+GJP!B18+SBET!B18+Sugarplay!B18 -> 1282 | L12: =WP!C18+GJP!C18+SBET!C18+Sugarplay!C18 -> 394 | M12: =WP!E18+GJP!E18+SBET!E18+Sugarplay!E18 -> 850 | N12: =WP!F18+GJP!F18+SBET!F18+Sugarplay!F18 -> 4877 | O12: =WP!G18+GJP!G18+SBET!G18+Sugarplay!G18 -> 10991 | P12: =WP!O18+GJP!O18+SBET!O18+Sugarplay!P18 -> 60320102 | Q12: =WP!P18+GJP!P18+SBET!P18+Sugarplay!Q18 -> 56307616 | R12: =WP!R18+GJP!R18+SBET!R18+Sugarplay!S18 -> 58750252 | S12: =T12/Q12 -> 0.0092423188 | T12: =WP!S18+GJP!S18+SBET!S18+Sugarplay!T18 -> 520412.94 | U12: =WP!T18+GJP!T18+SBET!T18+Sugarplay!U18 -> 217343.52 | V12: =WP!U18+GJP!U18+SBET!U18+Sugarplay!V18 -> 29775.73 | W12: =P12-R12-T12 -> 1049437.1 | X12: =W12/P12 -> 0.0173978 | Y12: =(P12-R12)/P12 -> 0.02602532 | Z12: =WP!AE18+GJP!AE18+SBET!AF18+Sugarplay!AG18 -> 1998999.8 | AA12: =AB12+AC12 -> 43723 | AB12: =WP!AA18+GJP!AA18+SBET!AB18+Sugarplay!AC18 -> 43723 | AC12: =WP!AB18+GJP!AB18+SBET!AC18+Sugarplay!AD18 -> 0 | AD12: =W12-AB12-AC12 -> 1005714.1 | AE12: =AD12/P12 -> 0.01667295 | AF12: =AG12+AH12 -> 217917.77 | AG12: =WP!W18+GJP!W18+SBET!W18+Sugarplay!X18 -> 202128.61 | AH12: =WP!X18+GJP!X18+SBET!X18+Sugarplay!Y18 -> 15789.16 | AI12: =W12*0.09 -> 94449.335 | AM12: =W12-AB12-AC12-AG12-AH12-AI12 -> 693346.95 | AN12: =AM12/P12 -> 0.011494459 | AO12: =WP!AC18+GJP!AC18+SBET!AD18+Sugarplay!AE18 -> 3100 | AP12: =WP!AD18+GJP!AD18+SBET!AE18+Sugarplay!AF18 -> -11420.41 | AQ12: =AD12-AG12-AH12-AI12 -> 693346.95 | AR12: =AM12-AQ12 -> 0
A13: =全平台汇总!A13 -> 46092 | B13: =WP!L19+GJP!L19+SBET!L19+Sugarplay!L19 -> 9771389.9 | C13: =WP!K19+GJP!K19+SBET!K19+Sugarplay!K19 -> 62776.89 | D13: =WP!M19+GJP!M19+SBET!M19+Sugarplay!N19 -> 7339569 | E13: =B13-D13 -> 2431820.9 | F13: =W13 -> 1578360.4 | G13: =AD13 -> 1578024.4 | H13: =AM13 -> 1193323.2 | I13: =WP!D19+GJP!D19+SBET!D19+Sugarplay!D19 -> 35220 | J13: =WP!J19+GJP!J19+SBET!J19+Sugarplay!J19 -> 25573 | K13: =WP!B19+GJP!B19+SBET!B19+Sugarplay!B19 -> 1043 | L13: =WP!C19+GJP!C19+SBET!C19+Sugarplay!C19 -> 340 | M13: =WP!E19+GJP!E19+SBET!E19+Sugarplay!E19 -> 793 | N13: =WP!F19+GJP!F19+SBET!F19+Sugarplay!F19 -> 4878 | O13: =WP!G19+GJP!G19+SBET!G19+Sugarplay!G19 -> 11239 | P13: =WP!O19+GJP!O19+SBET!O19+Sugarplay!P19 -> 57537374 | Q13: =WP!P19+GJP!P19+SBET!P19+Sugarplay!Q19 -> 53706677 | R13: =WP!R19+GJP!R19+SBET!R19+Sugarplay!S19 -> 55368621 | S13: =T13/Q13 -> 0.010992913 | T13: =WP!S19+GJP!S19+SBET!S19+Sugarplay!T19 -> 590392.81 | U13: =WP!T19+GJP!T19+SBET!T19+Sugarplay!U19 -> 242227.65 | V13: =WP!U19+GJP!U19+SBET!U19+Sugarplay!V19 -> 27742.02 | W13: =P13-R13-T13 -> 1578360.4 | X13: =W13/P13 -> 0.027431916 | Y13: =(P13-R13)/P13 -> 0.037692947 | Z13: =WP!AE19+GJP!AE19+SBET!AF19+Sugarplay!AG19 -> 2716736.4 | AA13: =AB13+AC13 -> 336 | AB13: =WP!AA19+GJP!AA19+SBET!AB19+Sugarplay!AC19 -> 336 | AC13: =WP!AB19+GJP!AB19+SBET!AC19+Sugarplay!AD19 -> 0 | AD13: =W13-AB13-AC13 -> 1578024.4 | AE13: =AD13/P13 -> 0.027426076 | AF13: =AG13+AH13 -> 242648.76 | AG13: =WP!W19+GJP!W19+SBET!W19+Sugarplay!X19 -> 227970.11 | AH13: =WP!X19+GJP!X19+SBET!X19+Sugarplay!Y19 -> 14678.65 | AI13: =W13*0.09 -> 142052.44 | AM13: =W13-AB13-AC13-AG13-AH13-AI13 -> 1193323.2 | AN13: =AM13/P13 -> 0.020739966 | AO13: =WP!AC19+GJP!AC19+SBET!AD19+Sugarplay!AE19 -> 0 | AP13: =WP!AD19+GJP!AD19+SBET!AE19+Sugarplay!AF19 -> -4601.87 | AQ13: =AD13-AG13-AH13-AI13 -> 1193323.2 | AR13: =AM13-AQ13 -> 0
A14: =全平台汇总!A14 -> 46093 | B14: =WP!L20+GJP!L20+SBET!L20+Sugarplay!L20 -> 9124174.9 | C14: =WP!K20+GJP!K20+SBET!K20+Sugarplay!K20 -> 60659 | D14: =WP!M20+GJP!M20+SBET!M20+Sugarplay!N20 -> 8123782 | E14: =B14-D14 -> 1000392.9 | F14: =W14 -> 1754210.2 | G14: =AD14 -> 1754018.2 | H14: =AM14 -> 1367157.9 | I14: =WP!D20+GJP!D20+SBET!D20+Sugarplay!D20 -> 32710 | J14: =WP!J20+GJP!J20+SBET!J20+Sugarplay!J20 -> 22464 | K14: =WP!B20+GJP!B20+SBET!B20+Sugarplay!B20 -> 980 | L14: =WP!C20+GJP!C20+SBET!C20+Sugarplay!C20 -> 342 | M14: =WP!E20+GJP!E20+SBET!E20+Sugarplay!E20 -> 776 | N14: =WP!F20+GJP!F20+SBET!F20+Sugarplay!F20 -> 4825 | O14: =WP!G20+GJP!G20+SBET!G20+Sugarplay!G20 -> 11006 | P14: =WP!O20+GJP!O20+SBET!O20+Sugarplay!P20 -> 59989236 | Q14: =WP!P20+GJP!P20+SBET!P20+Sugarplay!Q20 -> 55758780 | R14: =WP!R20+GJP!R20+SBET!R20+Sugarplay!S20 -> 57642732 | S14: =T14/Q14 -> 0.010622436 | T14: =WP!S20+GJP!S20+SBET!S20+Sugarplay!T20 -> 592294.08 | U14: =WP!T20+GJP!T20+SBET!T20+Sugarplay!U20 -> 243554.97 | V14: =WP!U20+GJP!U20+SBET!U20+Sugarplay!V20 -> 26864.98 | W14: =P14-R14-T14 -> 1754210.2 | X14: =W14/P14 -> 0.029242082 | Y14: =(P14-R14)/P14 -> 0.039115421 | Z14: =WP!AE20+GJP!AE20+SBET!AF20+Sugarplay!AG20 -> 1808352.5 | AA14: =AB14+AC14 -> 192 | AB14: =WP!AA20+GJP!AA20+SBET!AB20+Sugarplay!AC20 -> 192 | AC14: =WP!AB20+GJP!AB20+SBET!AC20+Sugarplay!AD20 -> 0 | AD14: =W14-AB14-AC14 -> 1754018.2 | AE14: =AD14/P14 -> 0.029238881 | AF14: =AG14+AH14 -> 228981.39 | AG14: =WP!W20+GJP!W20+SBET!W20+Sugarplay!X20 -> 212733.99 | AH14: =WP!X20+GJP!X20+SBET!X20+Sugarplay!Y20 -> 16247.4 | AI14: =W14*0.09 -> 157878.91 | AM14: =W14-AB14-AC14-AG14-AH14-AI14 -> 1367157.9 | AN14: =AM14/P14 -> 0.022790053 | AO14: =WP!AC20+GJP!AC20+SBET!AD20+Sugarplay!AE20 -> 2100 | AP14: =WP!AD20+GJP!AD20+SBET!AE20+Sugarplay!AF20 -> -17213.99 | AQ14: =AD14-AG14-AH14-AI14 -> 1367157.9 | AR14: =AM14-AQ14 -> 0
A15: =全平台汇总!A15 -> 46094 | B15: =WP!L21+GJP!L21+SBET!L21+Sugarplay!L21 -> 0 | C15: =WP!K21+GJP!K21+SBET!K21+Sugarplay!K21 -> 0 | D15: =WP!M21+GJP!M21+SBET!M21+Sugarplay!N21 -> 0 | E15: =B15-D15 -> 0 | F15: =W15 -> 0 | G15: =AD15 -> 0 | H15: =AM15 -> 0 | I15: =WP!D21+GJP!D21+SBET!D21+Sugarplay!D21 -> 0 | J15: =WP!J21+GJP!J21+SBET!J21+Sugarplay!J21 -> 0 | K15: =WP!B21+GJP!B21+SBET!B21+Sugarplay!B21 -> 0 | L15: =WP!C21+GJP!C21+SBET!C21+Sugarplay!C21 -> 0 | M15: =WP!E21+GJP!E21+SBET!E21+Sugarplay!E21 -> 0 | N15: =WP!F21+GJP!F21+SBET!F21+Sugarplay!F21 -> 0 | O15: =WP!G21+GJP!G21+SBET!G21+Sugarplay!G21 -> 0 | P15: =WP!O21+GJP!O21+SBET!O21+Sugarplay!P21 -> 0 | Q15: =WP!P21+GJP!P21+SBET!P21+Sugarplay!Q21 -> 0 | R15: =WP!R21+GJP!R21+SBET!R21+Sugarplay!S21 -> 0 | S15: =T15/Q15 -> #DIV/0! | T15: =WP!S21+GJP!S21+SBET!S21+Sugarplay!T21 -> 0 | U15: =WP!T21+GJP!T21+SBET!T21+Sugarplay!U21 -> 0 | V15: =WP!U21+GJP!U21+SBET!U21+Sugarplay!V21 -> 0 | W15: =P15-R15-T15 -> 0 | X15: =W15/P15 -> #DIV/0! | Y15: =(P15-R15)/P15 -> #DIV/0! | Z15: =WP!AE21+GJP!AE21+SBET!AF21+Sugarplay!AG21 -> 0 | AA15: =AB15+AC15 -> 0 | AB15: =WP!AA21+GJP!AA21+SBET!AB21+Sugarplay!AC21 -> 0 | AC15: =WP!AB21+GJP!AB21+SBET!AC21+Sugarplay!AD21 -> 0 | AD15: =W15-AB15-AC15 -> 0 | AE15: =AD15/P15 -> #DIV/0! | AF15: =AG15+AH15 -> 0 | AG15: =WP!W21+GJP!W21+SBET!W21+Sugarplay!X21 -> 0 | AH15: =WP!X21+GJP!X21+SBET!X21+Sugarplay!Y21 -> 0 | AI15: =W15*0.09 -> 0 | AM15: =W15-AB15-AC15-AG15-AH15-AI15 -> 0 | AN15: =AM15/P15 -> #DIV/0! | AO15: =WP!AC21+GJP!AC21+SBET!AD21+Sugarplay!AE21 -> 0 | AP15: =WP!AD21+GJP!AD21+SBET!AE21+Sugarplay!AF21 -> 0 | AQ15: =AD15-AG15-AH15-AI15 -> 0 | AR15: =AM15-AQ15 -> 0
... A33: =全平台汇总!A33 -> 46112 | B33: =WP!L39+GJP!L39+SBET!L39+Sugarplay!L39 -> 0 | C33: =WP!K39+GJP!K39+SBET!K39+Sugarplay!K39 -> 0 | D33: =WP!M39+GJP!M39+SBET!M39+Sugarplay!N39 -> 0 | E33: =B33-D33 -> 0 | F33: =W33 -> 0 | G33: =AD33 -> 0 | H33: =AM33 -> 0 | I33: =WP!D39+GJP!D39+SBET!D39+Sugarplay!D39 -> 0 | J33: =WP!J39+GJP!J39+SBET!J39+Sugarplay!J39 -> 0 | K33: =WP!B39+GJP!B39+SBET!B39+Sugarplay!B39 -> 0 | L33: =WP!C39+GJP!C39+SBET!C39+Sugarplay!C39 -> 0 | M33: =WP!E39+GJP!E39+SBET!E39+Sugarplay!E39 -> 0 | N33: =WP!F39+GJP!F39+SBET!F39+Sugarplay!F39 -> 0 | O33: =WP!G39+GJP!G39+SBET!G39+Sugarplay!G39 -> 0 | P33: =WP!O39+GJP!O39+SBET!O39+Sugarplay!P39 -> 0 | Q33: =WP!P39+GJP!P39+SBET!P39+Sugarplay!Q39 -> 0 | R33: =WP!R39+GJP!R39+SBET!R39+Sugarplay!S39 -> 0 | S33: =T33/Q33 -> #DIV/0! | T33: =WP!S39+GJP!S39+SBET!S39+Sugarplay!T39 -> 0 | U33: =WP!T39+GJP!T39+SBET!T39+Sugarplay!U39 -> 0 | V33: =WP!U39+GJP!U39+SBET!U39+Sugarplay!V39 -> 0 | W33: =P33-R33-T33 -> 0 | X33: =W33/P33 -> #DIV/0! | Y33: =(P33-R33)/P33 -> #DIV/0! | Z33: =WP!AE39+GJP!AE39+SBET!AF39+Sugarplay!AG39 -> 0 | AA33: =AB33+AC33 -> 0 | AB33: =WP!AA39+GJP!AA39+SBET!AB39+Sugarplay!AC39 -> 0 | AC33: =WP!AB39+GJP!AB39+SBET!AC39+Sugarplay!AD39 -> 0 | AD33: =W33-AB33-AC33 -> 0 | AE33: =AD33/P33 -> #DIV/0! | AF33: =AG33+AH33 -> 0 | AG33: =WP!W39+GJP!W39+SBET!W39+Sugarplay!X39 -> 0 | AH33: =WP!X39+GJP!X39+SBET!X39+Sugarplay!Y39 -> 0 | AI33: =W33*0.09 -> 0 | AM33: =W33-AB33-AC33-AG33-AH33-AI33 -> 0 | AN33: =AM33/P33 -> #DIV/0! | AO33: =WP!AC39+GJP!AC39+SBET!AD39+Sugarplay!AE39 -> 0 | AP33: =WP!AD39+GJP!AD39+SBET!AE39+Sugarplay!AF39 -> 0 | AQ33: =AD33-AG33-AH33-AI33 -> 0 | AR33: =AM33-AQ33 -> 0
A34: 日均 | B34: =AVERAGE(B3:B14) -> 9747411.2 | C34: =AVERAGE(C3:C14) -> 85846.158 | D34: =AVERAGE(D3:D14) -> 8517410.4 | E34: =AVERAGE(E3:E14) -> 1230000.7 | F34: =AVERAGE(F3:F14) -> 1479550.5 | G34: =AVERAGE(G3:G14) -> 1276313.8 | H34: =AVERAGE(H3:H14) -> 898337.61 | I34: =AVERAGE(I3:I14) -> 34485.917 | ... R34: =AVERAGE(R3:R14) -> 63483547 | S34: =T312/Q312 -> #DIV/0! | T34: =AVERAGE(T3:T14) -> 645315.47 | U34: =AVERAGE(U3:U14) -> 260022.74 | V34: =AVERAGE(V3:V14) -> 33513.263 | W34: =AVERAGE(W3:W14) -> 1479550.5 | X34: =W312/P312 -> #DIV/0! | Y34: =(P312-R312)/P312 -> #DIV/0! | Z34: =AVERAGE(Z3:Z14) -> 2091423.5 | AA34: =AVERAGE(AA3:AA14) -> 203236.73 | AB34: =AVERAGE(AB3:AB14) -> 203236.73 | AC34: =AVERAGE(AC3:AC14) -> 0 | AD34: =AVERAGE(AD3:AD14) -> 1276313.8 | AE34: =AVERAGE(AE3:AE14) -> 0.019154285 | AF34: =AVERAGE(AF3:AF14) -> 244816.64 | AG34: =AVERAGE(AG3:AG14) -> 227781.78 | ... AM34: =AVERAGE(AM3:AM14) -> 898337.61 | AN34: =AM312/P312 -> #DIV/0! | AO34: =AVERAGE(AO3:AO14) -> 14005.55 | AP34: =AVERAGE(AP3:AP14) -> -26856.257 | AQ34: =AVERAGE(AQ3:AQ14) -> 898337.61 | AR34: =AVERAGE(AR3:AR14) -> 0
